[INFO] Cloning dataset to Dataset(/scratch1/03201/jbwexler/work_dir/fmriprep/ds000117_sub-03/fmriprep_wf/single_subject_03_wf/func_preproc_ses_mri_task_facerecognition_run_01_wf/unwarp_wf/resample/sourcedata/templateflow) 
[INFO] Cloning dataset to Dataset(/scratch1/03201/jbwexler/work_dir/fmriprep/ds000117_sub-03/fmriprep_wf/single_subject_03_wf/func_preproc_ses_mri_task_facerecognition_run_01_wf/unwarp_wf/resample/sourcedata/templateflow) 
[INFO] Attempting to clone from https://github.com/templateflow/templateflow.git to /scratch1/03201/jbwexler/work_dir/fmriprep/ds000117_sub-03/fmriprep_wf/single_subject_03_wf/func_preproc_ses_mri_task_facerecognition_run_01_wf/unwarp_wf/resample/sourcedata/templateflow 
[INFO] Attempting to clone from https://github.com/templateflow/templateflow.git to /scratch1/03201/jbwexler/work_dir/fmriprep/ds000117_sub-03/fmriprep_wf/single_subject_03_wf/func_preproc_ses_mri_task_facerecognition_run_01_wf/unwarp_wf/resample/sourcedata/templateflow 
[INFO] Cloning dataset to Dataset(/scratch1/03201/jbwexler/work_dir/fmriprep/ds000117_sub-03/fmriprep_wf/single_subject_03_wf/func_preproc_ses_mri_task_facerecognition_run_01_wf/unwarp_wf/resample/sourcedata/templateflow) 
[INFO] Attempting to clone from https://github.com/templateflow/templateflow.git to /scratch1/03201/jbwexler/work_dir/fmriprep/ds000117_sub-03/fmriprep_wf/single_subject_03_wf/func_preproc_ses_mri_task_facerecognition_run_01_wf/unwarp_wf/resample/sourcedata/templateflow 
[INFO] Cloning dataset to Dataset(/scratch1/03201/jbwexler/work_dir/fmriprep/ds000117_sub-03/fmriprep_wf/single_subject_03_wf/func_preproc_ses_mri_task_facerecognition_run_01_wf/unwarp_wf/resample/sourcedata/templateflow) 
[INFO] Attempting to clone from https://github.com/templateflow/templateflow.git to /scratch1/03201/jbwexler/work_dir/fmriprep/ds000117_sub-03/fmriprep_wf/single_subject_03_wf/func_preproc_ses_mri_task_facerecognition_run_01_wf/unwarp_wf/resample/sourcedata/templateflow 
[INFO] Cloning dataset to Dataset(/scratch1/03201/jbwexler/work_dir/fmriprep/ds000117_sub-03/fmriprep_wf/single_subject_03_wf/func_preproc_ses_mri_task_facerecognition_run_01_wf/unwarp_wf/resample/sourcedata/templateflow) 
[INFO] Attempting to clone from https://github.com/templateflow/templateflow.git to /scratch1/03201/jbwexler/work_dir/fmriprep/ds000117_sub-03/fmriprep_wf/single_subject_03_wf/func_preproc_ses_mri_task_facerecognition_run_01_wf/unwarp_wf/resample/sourcedata/templateflow 
[INFO] Cloning dataset to Dataset(/scratch1/03201/jbwexler/work_dir/fmriprep/ds000117_sub-03/fmriprep_wf/single_subject_03_wf/func_preproc_ses_mri_task_facerecognition_run_01_wf/unwarp_wf/resample/sourcedata/templateflow) 
[INFO] Cloning dataset to Dataset(/scratch1/03201/jbwexler/work_dir/fmriprep/ds000117_sub-03/fmriprep_wf/single_subject_03_wf/func_preproc_ses_mri_task_facerecognition_run_01_wf/unwarp_wf/resample/sourcedata/templateflow) 
[INFO] Attempting to clone from https://github.com/templateflow/templateflow.git to /scratch1/03201/jbwexler/work_dir/fmriprep/ds000117_sub-03/fmriprep_wf/single_subject_03_wf/func_preproc_ses_mri_task_facerecognition_run_01_wf/unwarp_wf/resample/sourcedata/templateflow 
[INFO] Attempting to clone from https://github.com/templateflow/templateflow.git to /scratch1/03201/jbwexler/work_dir/fmriprep/ds000117_sub-03/fmriprep_wf/single_subject_03_wf/func_preproc_ses_mri_task_facerecognition_run_01_wf/unwarp_wf/resample/sourcedata/templateflow 
[INFO] Attempting to clone from https://github.com/templateflow/templateflow.git/.git to /scratch1/03201/jbwexler/work_dir/fmriprep/ds000117_sub-03/fmriprep_wf/single_subject_03_wf/func_preproc_ses_mri_task_facerecognition_run_01_wf/unwarp_wf/resample/sourcedata/templateflow 
[INFO] Attempting to clone from https://github.com/templateflow/templateflow.git/.git to /scratch1/03201/jbwexler/work_dir/fmriprep/ds000117_sub-03/fmriprep_wf/single_subject_03_wf/func_preproc_ses_mri_task_facerecognition_run_01_wf/unwarp_wf/resample/sourcedata/templateflow 
[INFO] Attempting to clone from https://github.com/templateflow/templateflow.git/.git to /scratch1/03201/jbwexler/work_dir/fmriprep/ds000117_sub-03/fmriprep_wf/single_subject_03_wf/func_preproc_ses_mri_task_facerecognition_run_01_wf/unwarp_wf/resample/sourcedata/templateflow 
[INFO] Attempting to clone from https://github.com/templateflow/templateflow.git/.git to /scratch1/03201/jbwexler/work_dir/fmriprep/ds000117_sub-03/fmriprep_wf/single_subject_03_wf/func_preproc_ses_mri_task_facerecognition_run_01_wf/unwarp_wf/resample/sourcedata/templateflow 
[INFO] Attempting to clone from https://github.com/templateflow/templateflow.git/.git to /scratch1/03201/jbwexler/work_dir/fmriprep/ds000117_sub-03/fmriprep_wf/single_subject_03_wf/func_preproc_ses_mri_task_facerecognition_run_01_wf/unwarp_wf/resample/sourcedata/templateflow 
[INFO] Attempting to clone from https://github.com/templateflow/templateflow.git/.git to /scratch1/03201/jbwexler/work_dir/fmriprep/ds000117_sub-03/fmriprep_wf/single_subject_03_wf/func_preproc_ses_mri_task_facerecognition_run_01_wf/unwarp_wf/resample/sourcedata/templateflow 
[INFO] Attempting to clone from https://github.com/templateflow/templateflow.git/.git to /scratch1/03201/jbwexler/work_dir/fmriprep/ds000117_sub-03/fmriprep_wf/single_subject_03_wf/func_preproc_ses_mri_task_facerecognition_run_01_wf/unwarp_wf/resample/sourcedata/templateflow 
[INFO] Completed clone attempts for Dataset(/scratch1/03201/jbwexler/work_dir/fmriprep/ds000117_sub-03/fmriprep_wf/single_subject_03_wf/func_preproc_ses_mri_task_facerecognition_run_01_wf/unwarp_wf/resample/sourcedata/templateflow) 
Traceback (most recent call last):
  File "/opt/conda/lib/python3.8/multiprocessing/forkserver.py", line 280, in main
    code = _serve_one(child_r, fds,
  File "/opt/conda/lib/python3.8/multiprocessing/forkserver.py", line 319, in _serve_one
    code = spawn._main(child_r, parent_sentinel)
  File "/opt/conda/lib/python3.8/multiprocessing/spawn.py", line 125, in _main
[INFO] Completed clone attempts for Dataset(/scratch1/03201/jbwexler/work_dir/fmriprep/ds000117_sub-03/fmriprep_wf/single_subject_03_wf/func_preproc_ses_mri_task_facerecognition_run_01_wf/unwarp_wf/resample/sourcedata/templateflow) 
Traceback (most recent call last):
  File "/opt/conda/lib/python3.8/multiprocessing/forkserver.py", line 280, in main
    code = _serve_one(child_r, fds,
  File "/opt/conda/lib/python3.8/multiprocessing/forkserver.py", line 319, in _serve_one
    code = spawn._main(child_r, parent_sentinel)
  File "/opt/conda/lib/python3.8/multiprocessing/spawn.py", line 125, in _main
    prepare(preparation_data)
      File "/opt/conda/lib/python3.8/multiprocessing/spawn.py", line 236, in prepare
prepare(preparation_data)
  File "/opt/conda/lib/python3.8/multiprocessing/spawn.py", line 236, in prepare
    _fixup_main_from_path(data['init_main_from_path'])
  File "/opt/conda/lib/python3.8/multiprocessing/spawn.py", line 287, in _fixup_main_from_path
    _fixup_main_from_path(data['init_main_from_path'])
  File "/opt/conda/lib/python3.8/multiprocessing/spawn.py", line 287, in _fixup_main_from_path
    main_content = runpy.run_path(main_path,
  File "/opt/conda/lib/python3.8/runpy.py", line 265, in run_path
    main_content = runpy.run_path(main_path,
  File "/opt/conda/lib/python3.8/runpy.py", line 265, in run_path
    return _run_module_code(code, init_globals, run_name,    
return _run_module_code(code, init_globals, run_name,  File "/opt/conda/lib/python3.8/runpy.py", line 97, in _run_module_code

  File "/opt/conda/lib/python3.8/runpy.py", line 97, in _run_module_code
    _run_code(code, mod_globals, init_globals,
      File "/opt/conda/lib/python3.8/runpy.py", line 87, in _run_code
_run_code(code, mod_globals, init_globals,
  File "/opt/conda/lib/python3.8/runpy.py", line 87, in _run_code
    exec(code, run_globals)
  File "/opt/conda/bin/fmriprep", line 5, in <module>
    exec(code, run_globals)
  File "/opt/conda/bin/fmriprep", line 5, in <module>
    from fmriprep.cli.run import main
      File "/opt/conda/lib/python3.8/site-packages/fmriprep/cli/run.py", line 25, in <module>
from fmriprep.cli.run import main
  File "/opt/conda/lib/python3.8/site-packages/fmriprep/cli/run.py", line 25, in <module>
        from .. import config
from .. import config
  File "/opt/conda/lib/python3.8/site-packages/fmriprep/config.py", line 116, in <module>
  File "/opt/conda/lib/python3.8/site-packages/fmriprep/config.py", line 116, in <module>
        from templateflow import __version__ as _tf_ver
from templateflow import __version__ as _tf_ver
  File "/opt/conda/lib/python3.8/site-packages/templateflow/__init__.py", line 19, in <module>
  File "/opt/conda/lib/python3.8/site-packages/templateflow/__init__.py", line 19, in <module>
        from . import apifrom . import api

  File "/opt/conda/lib/python3.8/site-packages/templateflow/api.py", line 7, in <module>
  File "/opt/conda/lib/python3.8/site-packages/templateflow/api.py", line 7, in <module>
        from .conf import TF_LAYOUT, TF_S3_ROOT, TF_USE_DATALAD, requires_layoutfrom .conf import TF_LAYOUT, TF_S3_ROOT, TF_USE_DATALAD, requires_layout

  File "/opt/conda/lib/python3.8/site-packages/templateflow/conf/__init__.py", line 53, in <module>
  File "/opt/conda/lib/python3.8/site-packages/templateflow/conf/__init__.py", line 53, in <module>
        install(path=str(TF_HOME), source=TF_GITHUB_SOURCE, recursive=True)install(path=str(TF_HOME), source=TF_GITHUB_SOURCE, recursive=True)

  File "/opt/conda/lib/python3.8/site-packages/datalad/interface/utils.py", line 484, in eval_func
  File "/opt/conda/lib/python3.8/site-packages/datalad/interface/utils.py", line 484, in eval_func
    return return_func(generator_func)(*args, **kwargs)
  File "/opt/conda/lib/python3.8/site-packages/datalad/interface/utils.py", line 476, in return_func
    return return_func(generator_func)(*args, **kwargs)
  File "/opt/conda/lib/python3.8/site-packages/datalad/interface/utils.py", line 476, in return_func
    results = list(results)
  File "/opt/conda/lib/python3.8/site-packages/datalad/interface/utils.py", line 396, in generator_func
    results = list(results)
  File "/opt/conda/lib/python3.8/site-packages/datalad/interface/utils.py", line 396, in generator_func
    for r in _process_results(
  File "/opt/conda/lib/python3.8/site-packages/datalad/interface/utils.py", line 579, in _process_results
    for r in _process_results(
  File "/opt/conda/lib/python3.8/site-packages/datalad/interface/utils.py", line 579, in _process_results
    for res in results:
  File "/opt/conda/lib/python3.8/site-packages/datalad/distribution/install.py", line 381, in __call__
    for res in results:
  File "/opt/conda/lib/python3.8/site-packages/datalad/distribution/install.py", line 381, in __call__
    for r in destination_dataset.get(
      File "/opt/conda/lib/python3.8/site-packages/datalad/interface/utils.py", line 396, in generator_func
for r in destination_dataset.get(
  File "/opt/conda/lib/python3.8/site-packages/datalad/interface/utils.py", line 396, in generator_func
    for r in _process_results(
  File "/opt/conda/lib/python3.8/site-packages/datalad/interface/utils.py", line 579, in _process_results
    for r in _process_results(
  File "/opt/conda/lib/python3.8/site-packages/datalad/interface/utils.py", line 579, in _process_results
    for res in results:
  File "/opt/conda/lib/python3.8/site-packages/datalad/distribution/get.py", line 849, in __call__
    for res in results:
  File "/opt/conda/lib/python3.8/site-packages/datalad/distribution/get.py", line 849, in __call__
    refds = require_dataset(
  File "/opt/conda/lib/python3.8/site-packages/datalad/distribution/dataset.py", line 567, in require_dataset
    refds = require_dataset(
  File "/opt/conda/lib/python3.8/site-packages/datalad/distribution/dataset.py", line 567, in require_dataset
    raise ValueError(u"No installed dataset found at "
    raise ValueError(u"No installed dataset found at "
ValueError: ValueErrorNo installed dataset found at /scratch1/03201/jbwexler/work_dir/fmriprep/ds000117_sub-03/fmriprep_wf/single_subject_03_wf/func_preproc_ses_mri_task_facerecognition_run_01_wf/unwarp_wf/resample/sourcedata/templateflow.: 
No installed dataset found at /scratch1/03201/jbwexler/work_dir/fmriprep/ds000117_sub-03/fmriprep_wf/single_subject_03_wf/func_preproc_ses_mri_task_facerecognition_run_01_wf/unwarp_wf/resample/sourcedata/templateflow.
[INFO] Cloning dataset to Dataset(/scratch1/03201/jbwexler/work_dir/fmriprep/ds000117_sub-03/fmriprep_wf/single_subject_03_wf/func_preproc_ses_mri_task_facerecognition_run_02_wf/unwarp_wf/resample/sourcedata/templateflow) 
[INFO] Cloning dataset to Dataset(/scratch1/03201/jbwexler/work_dir/fmriprep/ds000117_sub-03/fmriprep_wf/single_subject_03_wf/func_preproc_ses_mri_task_facerecognition_run_02_wf/unwarp_wf/resample/sourcedata/templateflow) 
[INFO] Attempting to clone from https://github.com/templateflow/templateflow.git to /scratch1/03201/jbwexler/work_dir/fmriprep/ds000117_sub-03/fmriprep_wf/single_subject_03_wf/func_preproc_ses_mri_task_facerecognition_run_02_wf/unwarp_wf/resample/sourcedata/templateflow 
[INFO] Attempting to clone from https://github.com/templateflow/templateflow.git to /scratch1/03201/jbwexler/work_dir/fmriprep/ds000117_sub-03/fmriprep_wf/single_subject_03_wf/func_preproc_ses_mri_task_facerecognition_run_02_wf/unwarp_wf/resample/sourcedata/templateflow 
Traceback (most recent call last):
  File "/opt/conda/lib/python3.8/multiprocessing/forkserver.py", line 280, in main
    code = _serve_one(child_r, fds,
  File "/opt/conda/lib/python3.8/multiprocessing/forkserver.py", line 319, in _serve_one
    code = spawn._main(child_r, parent_sentinel)
  File "/opt/conda/lib/python3.8/multiprocessing/spawn.py", line 125, in _main
    prepare(preparation_data)
  File "/opt/conda/lib/python3.8/multiprocessing/spawn.py", line 236, in prepare
    _fixup_main_from_path(data['init_main_from_path'])
  File "/opt/conda/lib/python3.8/multiprocessing/spawn.py", line 287, in _fixup_main_from_path
    main_content = runpy.run_path(main_path,
  File "/opt/conda/lib/python3.8/runpy.py", line 265, in run_path
Traceback (most recent call last):
Traceback (most recent call last):
Traceback (most recent call last):
  File "/opt/conda/lib/python3.8/multiprocessing/forkserver.py", line 280, in main
  File "/opt/conda/lib/python3.8/multiprocessing/forkserver.py", line 280, in main
  File "/opt/conda/lib/python3.8/multiprocessing/forkserver.py", line 280, in main
    return _run_module_code(code, init_globals, run_name,
  File "/opt/conda/lib/python3.8/runpy.py", line 97, in _run_module_code
    _run_code(code, mod_globals, init_globals,
  File "/opt/conda/lib/python3.8/runpy.py", line 87, in _run_code
Traceback (most recent call last):
    exec(code, run_globals)
          File "/opt/conda/bin/fmriprep", line 5, in <module>
code = _serve_one(child_r, fds,  File "/opt/conda/lib/python3.8/multiprocessing/forkserver.py", line 280, in main
code = _serve_one(child_r, fds,    

code = _serve_one(child_r, fds,  File "/opt/conda/lib/python3.8/multiprocessing/forkserver.py", line 319, in _serve_one

  File "/opt/conda/lib/python3.8/multiprocessing/forkserver.py", line 319, in _serve_one
    from fmriprep.cli.run import main  File "/opt/conda/lib/python3.8/multiprocessing/forkserver.py", line 319, in _serve_one

  File "/opt/conda/lib/python3.8/site-packages/fmriprep/cli/run.py", line 25, in <module>
    from .. import config
        code = spawn._main(child_r, parent_sentinel)  File "/opt/conda/lib/python3.8/site-packages/fmriprep/config.py", line 116, in <module>
code = spawn._main(child_r, parent_sentinel)    

code = spawn._main(child_r, parent_sentinel)  File "/opt/conda/lib/python3.8/multiprocessing/spawn.py", line 125, in _main

  File "/opt/conda/lib/python3.8/multiprocessing/spawn.py", line 125, in _main
  File "/opt/conda/lib/python3.8/multiprocessing/spawn.py", line 125, in _main
                code = _serve_one(child_r, fds,prepare(preparation_data)prepare(preparation_data)    
from templateflow import __version__ as _tf_ver

prepare(preparation_data)
  File "/opt/conda/lib/python3.8/multiprocessing/spawn.py", line 236, in prepare

  File "/opt/conda/lib/python3.8/multiprocessing/spawn.py", line 236, in prepare
  File "/opt/conda/lib/python3.8/multiprocessing/forkserver.py", line 319, in _serve_one
  File "/opt/conda/lib/python3.8/site-packages/templateflow/__init__.py", line 19, in <module>
  File "/opt/conda/lib/python3.8/multiprocessing/spawn.py", line 236, in prepare
        _fixup_main_from_path(data['init_main_from_path'])_fixup_main_from_path(data['init_main_from_path'])

  File "/opt/conda/lib/python3.8/multiprocessing/spawn.py", line 287, in _fixup_main_from_path
  File "/opt/conda/lib/python3.8/multiprocessing/spawn.py", line 287, in _fixup_main_from_path
    from . import api
  File "/opt/conda/lib/python3.8/site-packages/templateflow/api.py", line 7, in <module>
    _fixup_main_from_path(data['init_main_from_path'])
  File "/opt/conda/lib/python3.8/multiprocessing/spawn.py", line 287, in _fixup_main_from_path
        from .conf import TF_LAYOUT, TF_S3_ROOT, TF_USE_DATALAD, requires_layout    
code = spawn._main(child_r, parent_sentinel)    main_content = runpy.run_path(main_path,

  File "/opt/conda/lib/python3.8/site-packages/templateflow/conf/__init__.py", line 53, in <module>
main_content = runpy.run_path(main_path,
  File "/opt/conda/lib/python3.8/multiprocessing/spawn.py", line 125, in _main
  File "/opt/conda/lib/python3.8/runpy.py", line 265, in run_path
  File "/opt/conda/lib/python3.8/runpy.py", line 265, in run_path
    main_content = runpy.run_path(main_path,    
install(path=str(TF_HOME), source=TF_GITHUB_SOURCE, recursive=True)  File "/opt/conda/lib/python3.8/runpy.py", line 265, in run_path

  File "/opt/conda/lib/python3.8/site-packages/datalad/interface/utils.py", line 484, in eval_func
    prepare(preparation_data)
      File "/opt/conda/lib/python3.8/multiprocessing/spawn.py", line 236, in prepare
    return _run_module_code(code, init_globals, run_name,
return _run_module_code(code, init_globals, run_name,
  File "/opt/conda/lib/python3.8/runpy.py", line 97, in _run_module_code
  File "/opt/conda/lib/python3.8/runpy.py", line 97, in _run_module_code
    return _run_module_code(code, init_globals, run_name,
  File "/opt/conda/lib/python3.8/runpy.py", line 97, in _run_module_code
            _fixup_main_from_path(data['init_main_from_path'])_run_code(code, mod_globals, init_globals,_run_code(code, mod_globals, init_globals,

    
  File "/opt/conda/lib/python3.8/multiprocessing/spawn.py", line 287, in _fixup_main_from_path
      File "/opt/conda/lib/python3.8/runpy.py", line 87, in _run_code
return return_func(generator_func)(*args, **kwargs)  File "/opt/conda/lib/python3.8/runpy.py", line 87, in _run_code
_run_code(code, mod_globals, init_globals,

  File "/opt/conda/lib/python3.8/site-packages/datalad/interface/utils.py", line 476, in return_func
  File "/opt/conda/lib/python3.8/runpy.py", line 87, in _run_code
        exec(code, run_globals)exec(code, run_globals)

      File "/opt/conda/bin/fmriprep", line 5, in <module>
  File "/opt/conda/bin/fmriprep", line 5, in <module>
    exec(code, run_globals)main_content = runpy.run_path(main_path,

  File "/opt/conda/bin/fmriprep", line 5, in <module>
  File "/opt/conda/lib/python3.8/runpy.py", line 265, in run_path
        from fmriprep.cli.run import mainfrom fmriprep.cli.run import main

      File "/opt/conda/lib/python3.8/site-packages/fmriprep/cli/run.py", line 25, in <module>
  File "/opt/conda/lib/python3.8/site-packages/fmriprep/cli/run.py", line 25, in <module>
    results = list(results)
from fmriprep.cli.run import main
  File "/opt/conda/lib/python3.8/site-packages/datalad/interface/utils.py", line 396, in generator_func
  File "/opt/conda/lib/python3.8/site-packages/fmriprep/cli/run.py", line 25, in <module>
        from .. import configfrom .. import config    

return _run_module_code(code, init_globals, run_name,      File "/opt/conda/lib/python3.8/site-packages/fmriprep/config.py", line 116, in <module>

  File "/opt/conda/lib/python3.8/site-packages/fmriprep/config.py", line 116, in <module>
from .. import config
  File "/opt/conda/lib/python3.8/runpy.py", line 97, in _run_module_code
  File "/opt/conda/lib/python3.8/site-packages/fmriprep/config.py", line 116, in <module>
                for r in _process_results(_run_code(code, mod_globals, init_globals,from templateflow import __version__ as _tf_ver    from templateflow import __version__ as _tf_ver



from templateflow import __version__ as _tf_ver  File "/opt/conda/lib/python3.8/site-packages/datalad/interface/utils.py", line 579, in _process_results
  File "/opt/conda/lib/python3.8/runpy.py", line 87, in _run_code

  File "/opt/conda/lib/python3.8/site-packages/templateflow/__init__.py", line 19, in <module>
  File "/opt/conda/lib/python3.8/site-packages/templateflow/__init__.py", line 19, in <module>
  File "/opt/conda/lib/python3.8/site-packages/templateflow/__init__.py", line 19, in <module>
            from . import api    from . import apiexec(code, run_globals)
from . import api


  File "/opt/conda/lib/python3.8/site-packages/templateflow/api.py", line 7, in <module>
  File "/opt/conda/lib/python3.8/site-packages/templateflow/api.py", line 7, in <module>
  File "/opt/conda/bin/fmriprep", line 5, in <module>
  File "/opt/conda/lib/python3.8/site-packages/templateflow/api.py", line 7, in <module>
            from .conf import TF_LAYOUT, TF_S3_ROOT, TF_USE_DATALAD, requires_layout        from .conf import TF_LAYOUT, TF_S3_ROOT, TF_USE_DATALAD, requires_layoutfrom fmriprep.cli.run import main
from .conf import TF_LAYOUT, TF_S3_ROOT, TF_USE_DATALAD, requires_layoutfor res in results:



  File "/opt/conda/lib/python3.8/site-packages/templateflow/conf/__init__.py", line 53, in <module>
  File "/opt/conda/lib/python3.8/site-packages/templateflow/conf/__init__.py", line 53, in <module>
  File "/opt/conda/lib/python3.8/site-packages/fmriprep/cli/run.py", line 25, in <module>
  File "/opt/conda/lib/python3.8/site-packages/templateflow/conf/__init__.py", line 53, in <module>
  File "/opt/conda/lib/python3.8/site-packages/datalad/distribution/install.py", line 381, in __call__
            install(path=str(TF_HOME), source=TF_GITHUB_SOURCE, recursive=True)install(path=str(TF_HOME), source=TF_GITHUB_SOURCE, recursive=True)    
install(path=str(TF_HOME), source=TF_GITHUB_SOURCE, recursive=True)
from .. import config
  File "/opt/conda/lib/python3.8/site-packages/datalad/interface/utils.py", line 484, in eval_func

  File "/opt/conda/lib/python3.8/site-packages/datalad/interface/utils.py", line 484, in eval_func
  File "/opt/conda/lib/python3.8/site-packages/datalad/interface/utils.py", line 484, in eval_func
  File "/opt/conda/lib/python3.8/site-packages/fmriprep/config.py", line 116, in <module>
    for r in destination_dataset.get(
  File "/opt/conda/lib/python3.8/site-packages/datalad/interface/utils.py", line 396, in generator_func
    from templateflow import __version__ as _tf_ver
  File "/opt/conda/lib/python3.8/site-packages/templateflow/__init__.py", line 19, in <module>
            return return_func(generator_func)(*args, **kwargs)return return_func(generator_func)(*args, **kwargs)return return_func(generator_func)(*args, **kwargs)


  File "/opt/conda/lib/python3.8/site-packages/datalad/interface/utils.py", line 476, in return_func
  File "/opt/conda/lib/python3.8/site-packages/datalad/interface/utils.py", line 476, in return_func
  File "/opt/conda/lib/python3.8/site-packages/datalad/interface/utils.py", line 476, in return_func
        from . import apifor r in _process_results(

  File "/opt/conda/lib/python3.8/site-packages/templateflow/api.py", line 7, in <module>
  File "/opt/conda/lib/python3.8/site-packages/datalad/interface/utils.py", line 579, in _process_results
    from .conf import TF_LAYOUT, TF_S3_ROOT, TF_USE_DATALAD, requires_layout
  File "/opt/conda/lib/python3.8/site-packages/templateflow/conf/__init__.py", line 53, in <module>
            results = list(results)results = list(results)results = list(results)


  File "/opt/conda/lib/python3.8/site-packages/datalad/interface/utils.py", line 396, in generator_func
  File "/opt/conda/lib/python3.8/site-packages/datalad/interface/utils.py", line 396, in generator_func
  File "/opt/conda/lib/python3.8/site-packages/datalad/interface/utils.py", line 396, in generator_func
        install(path=str(TF_HOME), source=TF_GITHUB_SOURCE, recursive=True)for res in results:

  File "/opt/conda/lib/python3.8/site-packages/datalad/interface/utils.py", line 484, in eval_func
  File "/opt/conda/lib/python3.8/site-packages/datalad/distribution/get.py", line 849, in __call__
        for r in _process_results(for r in _process_results(

  File "/opt/conda/lib/python3.8/site-packages/datalad/interface/utils.py", line 579, in _process_results
  File "/opt/conda/lib/python3.8/site-packages/datalad/interface/utils.py", line 579, in _process_results
    for r in _process_results(
  File "/opt/conda/lib/python3.8/site-packages/datalad/interface/utils.py", line 579, in _process_results
    return return_func(generator_func)(*args, **kwargs)
      File "/opt/conda/lib/python3.8/site-packages/datalad/interface/utils.py", line 476, in return_func
    for res in results:for res in results:

  File "/opt/conda/lib/python3.8/site-packages/datalad/distribution/install.py", line 381, in __call__
  File "/opt/conda/lib/python3.8/site-packages/datalad/distribution/install.py", line 381, in __call__
    refds = require_dataset(
  File "/opt/conda/lib/python3.8/site-packages/datalad/distribution/dataset.py", line 567, in require_dataset
    for res in results:
  File "/opt/conda/lib/python3.8/site-packages/datalad/distribution/install.py", line 381, in __call__
    results = list(results)        
for r in destination_dataset.get(for r in destination_dataset.get(

  File "/opt/conda/lib/python3.8/site-packages/datalad/interface/utils.py", line 396, in generator_func
  File "/opt/conda/lib/python3.8/site-packages/datalad/interface/utils.py", line 396, in generator_func
  File "/opt/conda/lib/python3.8/site-packages/datalad/interface/utils.py", line 396, in generator_func
        for r in destination_dataset.get(raise ValueError(u"No installed dataset found at "

  File "/opt/conda/lib/python3.8/site-packages/datalad/interface/utils.py", line 396, in generator_func
ValueError: No installed dataset found at /scratch1/03201/jbwexler/work_dir/fmriprep/ds000117_sub-03/fmriprep_wf/single_subject_03_wf/func_preproc_ses_mri_task_facerecognition_run_02_wf/unwarp_wf/resample/sourcedata/templateflow.
    for r in _process_results(        
for r in _process_results(for r in _process_results(

  File "/opt/conda/lib/python3.8/site-packages/datalad/interface/utils.py", line 579, in _process_results
  File "/opt/conda/lib/python3.8/site-packages/datalad/interface/utils.py", line 579, in _process_results
  File "/opt/conda/lib/python3.8/site-packages/datalad/interface/utils.py", line 579, in _process_results
    for r in _process_results(
  File "/opt/conda/lib/python3.8/site-packages/datalad/interface/utils.py", line 579, in _process_results
            for res in results:for res in results:for res in results:


  File "/opt/conda/lib/python3.8/site-packages/datalad/distribution/install.py", line 381, in __call__
  File "/opt/conda/lib/python3.8/site-packages/datalad/distribution/get.py", line 849, in __call__
  File "/opt/conda/lib/python3.8/site-packages/datalad/distribution/get.py", line 849, in __call__
    for res in results:
  File "/opt/conda/lib/python3.8/site-packages/datalad/distribution/get.py", line 849, in __call__
    for r in destination_dataset.get(
  File "/opt/conda/lib/python3.8/site-packages/datalad/interface/utils.py", line 396, in generator_func
        refds = require_dataset(refds = require_dataset(

      File "/opt/conda/lib/python3.8/site-packages/datalad/distribution/dataset.py", line 567, in require_dataset
  File "/opt/conda/lib/python3.8/site-packages/datalad/distribution/dataset.py", line 567, in require_dataset
refds = require_dataset(
      File "/opt/conda/lib/python3.8/site-packages/datalad/distribution/dataset.py", line 567, in require_dataset
for r in _process_results(
  File "/opt/conda/lib/python3.8/site-packages/datalad/interface/utils.py", line 579, in _process_results
        raise ValueError(u"No installed dataset found at "raise ValueError(u"No installed dataset found at "

    ValueErrorValueErrorraise ValueError(u"No installed dataset found at ":     
: for res in results:No installed dataset found at /scratch1/03201/jbwexler/work_dir/fmriprep/ds000117_sub-03/fmriprep_wf/single_subject_03_wf/func_preproc_ses_mri_task_facerecognition_run_02_wf/unwarp_wf/resample/sourcedata/templateflow.ValueError

No installed dataset found at /scratch1/03201/jbwexler/work_dir/fmriprep/ds000117_sub-03/fmriprep_wf/single_subject_03_wf/func_preproc_ses_mri_task_facerecognition_run_02_wf/unwarp_wf/resample/sourcedata/templateflow.: 
  File "/opt/conda/lib/python3.8/site-packages/datalad/distribution/get.py", line 849, in __call__
No installed dataset found at /scratch1/03201/jbwexler/work_dir/fmriprep/ds000117_sub-03/fmriprep_wf/single_subject_03_wf/func_preproc_ses_mri_task_facerecognition_run_02_wf/unwarp_wf/resample/sourcedata/templateflow.
    refds = require_dataset(
  File "/opt/conda/lib/python3.8/site-packages/datalad/distribution/dataset.py", line 567, in require_dataset
    raise ValueError(u"No installed dataset found at "
ValueError: No installed dataset found at /scratch1/03201/jbwexler/work_dir/fmriprep/ds000117_sub-03/fmriprep_wf/single_subject_03_wf/func_preproc_ses_mri_task_facerecognition_run_02_wf/unwarp_wf/resample/sourcedata/templateflow.
[INFO] Cloning dataset to Dataset(/scratch1/03201/jbwexler/work_dir/fmriprep/ds000117_sub-03/fmriprep_wf/single_subject_03_wf/func_preproc_ses_mri_task_facerecognition_run_03_wf/unwarp_wf/resample/sourcedata/templateflow) 
[INFO] Cloning dataset to Dataset(/scratch1/03201/jbwexler/work_dir/fmriprep/ds000117_sub-03/fmriprep_wf/single_subject_03_wf/func_preproc_ses_mri_task_facerecognition_run_03_wf/unwarp_wf/resample/sourcedata/templateflow) 
[INFO] Cloning dataset to Dataset(/scratch1/03201/jbwexler/work_dir/fmriprep/ds000117_sub-03/fmriprep_wf/single_subject_03_wf/func_preproc_ses_mri_task_facerecognition_run_03_wf/unwarp_wf/resample/sourcedata/templateflow) 
[INFO] Attempting to clone from https://github.com/templateflow/templateflow.git to /scratch1/03201/jbwexler/work_dir/fmriprep/ds000117_sub-03/fmriprep_wf/single_subject_03_wf/func_preproc_ses_mri_task_facerecognition_run_03_wf/unwarp_wf/resample/sourcedata/templateflow 
[INFO] Attempting to clone from https://github.com/templateflow/templateflow.git to /scratch1/03201/jbwexler/work_dir/fmriprep/ds000117_sub-03/fmriprep_wf/single_subject_03_wf/func_preproc_ses_mri_task_facerecognition_run_03_wf/unwarp_wf/resample/sourcedata/templateflow 
[INFO] Attempting to clone from https://github.com/templateflow/templateflow.git to /scratch1/03201/jbwexler/work_dir/fmriprep/ds000117_sub-03/fmriprep_wf/single_subject_03_wf/func_preproc_ses_mri_task_facerecognition_run_03_wf/unwarp_wf/resample/sourcedata/templateflow 
[INFO] Cloning dataset to Dataset(/scratch1/03201/jbwexler/work_dir/fmriprep/ds000117_sub-03/fmriprep_wf/single_subject_03_wf/func_preproc_ses_mri_task_facerecognition_run_03_wf/unwarp_wf/resample/sourcedata/templateflow) 
[INFO] Attempting to clone from https://github.com/templateflow/templateflow.git to /scratch1/03201/jbwexler/work_dir/fmriprep/ds000117_sub-03/fmriprep_wf/single_subject_03_wf/func_preproc_ses_mri_task_facerecognition_run_03_wf/unwarp_wf/resample/sourcedata/templateflow 
[INFO] Cloning dataset to Dataset(/scratch1/03201/jbwexler/work_dir/fmriprep/ds000117_sub-03/fmriprep_wf/single_subject_03_wf/func_preproc_ses_mri_task_facerecognition_run_03_wf/unwarp_wf/resample/sourcedata/templateflow) 
[INFO] Attempting to clone from https://github.com/templateflow/templateflow.git to /scratch1/03201/jbwexler/work_dir/fmriprep/ds000117_sub-03/fmriprep_wf/single_subject_03_wf/func_preproc_ses_mri_task_facerecognition_run_03_wf/unwarp_wf/resample/sourcedata/templateflow 
[INFO] Cloning dataset to Dataset(/scratch1/03201/jbwexler/work_dir/fmriprep/ds000117_sub-03/fmriprep_wf/single_subject_03_wf/func_preproc_ses_mri_task_facerecognition_run_03_wf/unwarp_wf/resample/sourcedata/templateflow) 
[INFO] Attempting to clone from https://github.com/templateflow/templateflow.git to /scratch1/03201/jbwexler/work_dir/fmriprep/ds000117_sub-03/fmriprep_wf/single_subject_03_wf/func_preproc_ses_mri_task_facerecognition_run_03_wf/unwarp_wf/resample/sourcedata/templateflow 
[INFO] Cloning dataset to Dataset(/scratch1/03201/jbwexler/work_dir/fmriprep/ds000117_sub-03/fmriprep_wf/single_subject_03_wf/func_preproc_ses_mri_task_facerecognition_run_03_wf/unwarp_wf/resample/sourcedata/templateflow) 
[INFO] Attempting to clone from https://github.com/templateflow/templateflow.git to /scratch1/03201/jbwexler/work_dir/fmriprep/ds000117_sub-03/fmriprep_wf/single_subject_03_wf/func_preproc_ses_mri_task_facerecognition_run_03_wf/unwarp_wf/resample/sourcedata/templateflow 
Traceback (most recent call last):
  File "/opt/conda/lib/python3.8/site-packages/datalad/core/distributed/clone.py", line 589, in clone_dataset
    GitRepo.clone(
  File "/opt/conda/lib/python3.8/site-packages/datalad/support/gitrepo.py", line 994, in clone
    res = GitWitlessRunner().run(
  File "/opt/conda/lib/python3.8/site-packages/datalad/runner/runner.py", line 145, in run
    raise CommandError(
datalad.runner.exception.CommandError: CommandError: 'git -c diff.ignoreSubmodules=none clone --progress https://github.com/templateflow/templateflow.git /scratch1/03201/jbwexler/work_dir/fmriprep/ds000117_sub-03/fmriprep_wf/single_subject_03_wf/func_preproc_ses_mri_task_facerecognition_run_03_wf/unwarp_wf/resample/sourcedata/templateflow' failed with exitcode 128 [err: 'Cloning into '/scratch1/03201/jbwexler/work_dir/fmriprep/ds000117_sub-03/fmriprep_wf/single_subject_03_wf/func_preproc_ses_mri_task_facerecognition_run_03_wf/unwarp_wf/resample/sourcedata/templateflow'...
fatal: cannot copy '/opt/conda/share/git-core/templates/hooks/applypatch-msg.sample' to '/scratch1/03201/jbwexler/work_dir/fmriprep/ds000117_sub-03/fmriprep_wf/single_subject_03_wf/func_preproc_ses_mri_task_facerecognition_run_03_wf/unwarp_wf/resample/sourcedata/templateflow/.git/hooks/applypatch-msg.sample': File exists']

During handling of the above exception, another exception occurred:

Traceback (most recent call last):
  File "/opt/conda/lib/python3.8/multiprocessing/forkserver.py", line 280, in main
    code = _serve_one(child_r, fds,
  File "/opt/conda/lib/python3.8/multiprocessing/forkserver.py", line 319, in _serve_one
    code = spawn._main(child_r, parent_sentinel)
  File "/opt/conda/lib/python3.8/multiprocessing/spawn.py", line 125, in _main
    prepare(preparation_data)
  File "/opt/conda/lib/python3.8/multiprocessing/spawn.py", line 236, in prepare
    _fixup_main_from_path(data['init_main_from_path'])
  File "/opt/conda/lib/python3.8/multiprocessing/spawn.py", line 287, in _fixup_main_from_path
    main_content = runpy.run_path(main_path,
  File "/opt/conda/lib/python3.8/runpy.py", line 265, in run_path
    [INFO] Attempting to clone from https://github.com/templateflow/templateflow.git/.git to /scratch1/03201/jbwexler/work_dir/fmriprep/ds000117_sub-03/fmriprep_wf/single_subject_03_wf/func_preproc_ses_mri_task_facerecognition_run_03_wf/unwarp_wf/resample/sourcedata/templateflow 
return _run_module_code(code, init_globals, run_name,
  File "/opt/conda/lib/python3.8/runpy.py", line 97, in _run_module_code
    _run_code(code, mod_globals, init_globals,
  File "/opt/conda/lib/python3.8/runpy.py", line 87, in _run_code
    exec(code, run_globals)
  File "/opt/conda/bin/fmriprep", line 5, in <module>
    from fmriprep.cli.run import main
  File "/opt/conda/lib/python3.8/site-packages/fmriprep/cli/run.py", line 25, in <module>
    from .. import config
  File "/opt/conda/lib/python3.8/site-packages/fmriprep/config.py", line 116, in <module>
    from templateflow import __version__ as _tf_ver
  File "/opt/conda/lib/python3.8/site-packages/templateflow/__init__.py", line 19, in <module>
    from . import api
  File "/opt/conda/lib/python3.8/site-packages/templateflow/api.py", line 7, in <module>
    from .conf import TF_LAYOUT, TF_S3_ROOT, TF_USE_DATALAD, requires_layout
  File "/opt/conda/lib/python3.8/site-packages/templateflow/conf/__init__.py", line 53, in <module>
    install(path=str(TF_HOME), source=TF_GITHUB_SOURCE, recursive=True)
  File "/opt/conda/lib/python3.8/site-packages/datalad/interface/utils.py", line 484, in eval_func
    return return_func(generator_func)(*args, **kwargs)
  File "/opt/conda/lib/python3.8/site-packages/datalad/interface/utils.py", line 476, in return_func
    results = list(results)
  File "/opt/conda/lib/python3.8/site-packages/datalad/interface/utils.py", line 396, in generator_func
[INFO] Attempting to clone from https://github.com/templateflow/templateflow.git/.git to /scratch1/03201/jbwexler/work_dir/fmriprep/ds000117_sub-03/fmriprep_wf/single_subject_03_wf/func_preproc_ses_mri_task_facerecognition_run_03_wf/unwarp_wf/resample/sourcedata/templateflow 
    for r in _process_results(
  File "/opt/conda/lib/python3.8/site-packages/datalad/interface/utils.py", line 579, in _process_results
    for res in results:
  File "/opt/conda/lib/python3.8/site-packages/datalad/distribution/install.py", line 365, in __call__
    for r in res:
  File "/opt/conda/lib/python3.8/site-packages/datalad/interface/utils.py", line 396, in generator_func
    for r in _process_results(
  File "/opt/conda/lib/python3.8/site-packages/datalad/interface/utils.py", line 579, in _process_results
    for res in results:
  File "/opt/conda/lib/python3.8/site-packages/datalad/core/distributed/clone.py", line 320, in __call__
    yield from clone_dataset(
  File "/opt/conda/lib/python3.8/site-packages/datalad/core/distributed/clone.py", line 609, in clone_dataset
    rmtree(str(dest_path), children_only=dest_path_existed)
  File "/opt/conda/lib/python3.8/site-packages/datalad/utils.py", line 471, in rmtree
    rotree(path, ro=False, chmod_files=chmod_files)
  File "/opt/conda/lib/python3.8/site-packages/datalad/utils.py", line 435, in rotree
    chmod(root)
  File "/opt/conda/lib/python3.8/site-packages/datalad/utils.py", line 426, in <lambda>
    chmod = lambda f: os.chmod(f, os.stat(f).st_mode | stat.S_IWRITE | stat.S_IREAD)
FileNotFoundError: [Errno 2] No such file or directory: '/scratch1/03201/jbwexler/work_dir/fmriprep/ds000117_sub-03/fmriprep_wf/single_subject_03_wf/func_preproc_ses_mri_task_facerecognition_run_03_wf/unwarp_wf/resample/sourcedata/templateflow'
[INFO] Cloning dataset to Dataset(/scratch1/03201/jbwexler/work_dir/fmriprep/ds000117_sub-03/fmriprep_wf/single_subject_03_wf/func_preproc_ses_mri_task_facerecognition_run_04_wf/unwarp_wf/resample/sourcedata/templateflow) 
[INFO] Attempting to clone from https://github.com/templateflow/templateflow.git to /scratch1/03201/jbwexler/work_dir/fmriprep/ds000117_sub-03/fmriprep_wf/single_subject_03_wf/func_preproc_ses_mri_task_facerecognition_run_04_wf/unwarp_wf/resample/sourcedata/templateflow 
[INFO] Cloning dataset to Dataset(/scratch1/03201/jbwexler/work_dir/fmriprep/ds000117_sub-03/fmriprep_wf/single_subject_03_wf/func_preproc_ses_mri_task_facerecognition_run_04_wf/unwarp_wf/resample/sourcedata/templateflow) 
[INFO] Attempting to clone from https://github.com/templateflow/templateflow.git to /scratch1/03201/jbwexler/work_dir/fmriprep/ds000117_sub-03/fmriprep_wf/single_subject_03_wf/func_preproc_ses_mri_task_facerecognition_run_04_wf/unwarp_wf/resample/sourcedata/templateflow 
Traceback (most recent call last):
  File "/opt/conda/lib/python3.8/multiprocessing/forkserver.py", line 280, in main
    code = _serve_one(child_r, fds,
  File "/opt/conda/lib/python3.8/multiprocessing/forkserver.py", line 319, in _serve_one
    code = spawn._main(child_r, parent_sentinel)
  File "/opt/conda/lib/python3.8/multiprocessing/spawn.py", line 125, in _main
    prepare(preparation_data)
  File "/opt/conda/lib/python3.8/multiprocessing/spawn.py", line 236, in prepare
    _fixup_main_from_path(data['init_main_from_path'])
  File "/opt/conda/lib/python3.8/multiprocessing/spawn.py", line 287, in _fixup_main_from_path
    main_content = runpy.run_path(main_path,
  File "/opt/conda/lib/python3.8/runpy.py", line 265, in run_path
    return _run_module_code(code, init_globals, run_name,
  File "/opt/conda/lib/python3.8/runpy.py", line 97, in _run_module_code
    _run_code(code, mod_globals, init_globals,
  File "/opt/conda/lib/python3.8/runpy.py", line 87, in _run_code
    exec(code, run_globals)
  File "/opt/conda/bin/fmriprep", line 5, in <module>
    from fmriprep.cli.run import main
  File "/opt/conda/lib/python3.8/site-packages/fmriprep/cli/run.py", line 25, in <module>
    from .. import config
  File "/opt/conda/lib/python3.8/site-packages/fmriprep/config.py", line 116, in <module>
    from templateflow import __version__ as _tf_ver
  File "/opt/conda/lib/python3.8/site-packages/templateflow/__init__.py", line 19, in <module>
    from . import api
  File "/opt/conda/lib/python3.8/site-packages/templateflow/api.py", line 7, in <module>
    from .conf import TF_LAYOUT, TF_S3_ROOT, TF_USE_DATALAD, requires_layout
  File "/opt/conda/lib/python3.8/site-packages/templateflow/conf/__init__.py", line 53, in <module>
    install(path=str(TF_HOME), source=TF_GITHUB_SOURCE, recursive=True)
  File "/opt/conda/lib/python3.8/site-packages/datalad/interface/utils.py", line 484, in eval_func
    return return_func(generator_func)(*args, **kwargs)
  File "/opt/conda/lib/python3.8/site-packages/datalad/interface/utils.py", line 476, in return_func
    results = list(results)
  File "/opt/conda/lib/python3.8/site-packages/datalad/interface/utils.py", line 396, in generator_func
    for r in _process_results(
  File "/opt/conda/lib/python3.8/site-packages/datalad/interface/utils.py", line 579, in _process_results
    for res in results:
  File "/opt/conda/lib/python3.8/site-packages/datalad/distribution/install.py", line 365, in __call__
    for r in res:
  File "/opt/conda/lib/python3.8/site-packages/datalad/interface/utils.py", line 396, in generator_func
    for r in _process_results(
  File "/opt/conda/lib/python3.8/site-packages/datalad/interface/utils.py", line 579, in _process_results
    for res in results:
  File "/opt/conda/lib/python3.8/site-packages/datalad/core/distributed/clone.py", line 320, in __call__
    yield from clone_dataset(
  File "/opt/conda/lib/python3.8/site-packages/datalad/core/distributed/clone.py", line 589, in clone_dataset
    GitRepo.clone(
  File "/opt/conda/lib/python3.8/site-packages/datalad/support/gitrepo.py", line 949, in clone
    raise ValueError(
ValueError: destination path '/scratch1/03201/jbwexler/work_dir/fmriprep/ds000117_sub-03/fmriprep_wf/single_subject_03_wf/func_preproc_ses_mri_task_facerecognition_run_04_wf/unwarp_wf/resample/sourcedata/templateflow' already exists and is not an empty directory.
[INFO] Cloning dataset to Dataset(/scratch1/03201/jbwexler/work_dir/fmriprep/ds000117_sub-03/fmriprep_wf/single_subject_03_wf/func_preproc_ses_mri_task_facerecognition_run_05_wf/unwarp_wf/resample/sourcedata/templateflow) 
[INFO] Attempting to clone from https://github.com/templateflow/templateflow.git to /scratch1/03201/jbwexler/work_dir/fmriprep/ds000117_sub-03/fmriprep_wf/single_subject_03_wf/func_preproc_ses_mri_task_facerecognition_run_05_wf/unwarp_wf/resample/sourcedata/templateflow 
[INFO] Cloning dataset to Dataset(/scratch1/03201/jbwexler/work_dir/fmriprep/ds000117_sub-03/fmriprep_wf/single_subject_03_wf/func_preproc_ses_mri_task_facerecognition_run_05_wf/unwarp_wf/resample/sourcedata/templateflow) 
[INFO] Attempting to clone from https://github.com/templateflow/templateflow.git to /scratch1/03201/jbwexler/work_dir/fmriprep/ds000117_sub-03/fmriprep_wf/single_subject_03_wf/func_preproc_ses_mri_task_facerecognition_run_05_wf/unwarp_wf/resample/sourcedata/templateflow 
[INFO] Cloning dataset to Dataset(/scratch1/03201/jbwexler/work_dir/fmriprep/ds000117_sub-03/fmriprep_wf/single_subject_03_wf/func_preproc_ses_mri_task_facerecognition_run_05_wf/unwarp_wf/resample/sourcedata/templateflow) 
[INFO] Attempting to clone from https://github.com/templateflow/templateflow.git to /scratch1/03201/jbwexler/work_dir/fmriprep/ds000117_sub-03/fmriprep_wf/single_subject_03_wf/func_preproc_ses_mri_task_facerecognition_run_05_wf/unwarp_wf/resample/sourcedata/templateflow 
[INFO] Cloning dataset to Dataset(/scratch1/03201/jbwexler/work_dir/fmriprep/ds000117_sub-03/fmriprep_wf/single_subject_03_wf/func_preproc_ses_mri_task_facerecognition_run_05_wf/unwarp_wf/resample/sourcedata/templateflow) 
[INFO] Cloning dataset to Dataset(/scratch1/03201/jbwexler/work_dir/fmriprep/ds000117_sub-03/fmriprep_wf/single_subject_03_wf/func_preproc_ses_mri_task_facerecognition_run_05_wf/unwarp_wf/resample/sourcedata/templateflow) 
[INFO] Attempting to clone from https://github.com/templateflow/templateflow.git to /scratch1/03201/jbwexler/work_dir/fmriprep/ds000117_sub-03/fmriprep_wf/single_subject_03_wf/func_preproc_ses_mri_task_facerecognition_run_05_wf/unwarp_wf/resample/sourcedata/templateflow 
[INFO] Attempting to clone from https://github.com/templateflow/templateflow.git to /scratch1/03201/jbwexler/work_dir/fmriprep/ds000117_sub-03/fmriprep_wf/single_subject_03_wf/func_preproc_ses_mri_task_facerecognition_run_05_wf/unwarp_wf/resample/sourcedata/templateflow 
[INFO] Cloning dataset to Dataset(/scratch1/03201/jbwexler/work_dir/fmriprep/ds000117_sub-03/fmriprep_wf/single_subject_03_wf/func_preproc_ses_mri_task_facerecognition_run_05_wf/unwarp_wf/resample/sourcedata/templateflow) 
[INFO] Attempting to clone from https://github.com/templateflow/templateflow.git to /scratch1/03201/jbwexler/work_dir/fmriprep/ds000117_sub-03/fmriprep_wf/single_subject_03_wf/func_preproc_ses_mri_task_facerecognition_run_05_wf/unwarp_wf/resample/sourcedata/templateflow 
[INFO] Cloning dataset to Dataset(/scratch1/03201/jbwexler/work_dir/fmriprep/ds000117_sub-03/fmriprep_wf/single_subject_03_wf/func_preproc_ses_mri_task_facerecognition_run_05_wf/unwarp_wf/resample/sourcedata/templateflow) 
[INFO] Attempting to clone from https://github.com/templateflow/templateflow.git to /scratch1/03201/jbwexler/work_dir/fmriprep/ds000117_sub-03/fmriprep_wf/single_subject_03_wf/func_preproc_ses_mri_task_facerecognition_run_05_wf/unwarp_wf/resample/sourcedata/templateflow 
[INFO] Attempting to clone from https://github.com/templateflow/templateflow.git/.git to /scratch1/03201/jbwexler/work_dir/fmriprep/ds000117_sub-03/fmriprep_wf/single_subject_03_wf/func_preproc_ses_mri_task_facerecognition_run_05_wf/unwarp_wf/resample/sourcedata/templateflow 
[INFO] Attempting to clone from https://github.com/templateflow/templateflow.git/.git to /scratch1/03201/jbwexler/work_dir/fmriprep/ds000117_sub-03/fmriprep_wf/single_subject_03_wf/func_preproc_ses_mri_task_facerecognition_run_05_wf/unwarp_wf/resample/sourcedata/templateflow 
[INFO] Completed clone attempts for Dataset(/scratch1/03201/jbwexler/work_dir/fmriprep/ds000117_sub-03/fmriprep_wf/single_subject_03_wf/func_preproc_ses_mri_task_facerecognition_run_05_wf/unwarp_wf/resample/sourcedata/templateflow) 
Traceback (most recent call last):
  File "/opt/conda/lib/python3.8/multiprocessing/forkserver.py", line 280, in main
    code = _serve_one(child_r, fds,
  File "/opt/conda/lib/python3.8/multiprocessing/forkserver.py", line 319, in _serve_one
    code = spawn._main(child_r, parent_sentinel)
  File "/opt/conda/lib/python3.8/multiprocessing/spawn.py", line 125, in _main
    prepare(preparation_data)
  File "/opt/conda/lib/python3.8/multiprocessing/spawn.py", line 236, in prepare
    _fixup_main_from_path(data['init_main_from_path'])
  File "/opt/conda/lib/python3.8/multiprocessing/spawn.py", line 287, in _fixup_main_from_path
    main_content = runpy.run_path(main_path,
  File "/opt/conda/lib/python3.8/runpy.py", line 265, in run_path
    return _run_module_code(code, init_globals, run_name,
  File "/opt/conda/lib/python3.8/runpy.py", line 97, in _run_module_code
    _run_code(code, mod_globals, init_globals,
  File "/opt/conda/lib/python3.8/runpy.py", line 87, in _run_code
    exec(code, run_globals)
  File "/opt/conda/bin/fmriprep", line 5, in <module>
    from fmriprep.cli.run import main
  File "/opt/conda/lib/python3.8/site-packages/fmriprep/cli/run.py", line 25, in <module>
    from .. import config
  File "/opt/conda/lib/python3.8/site-packages/fmriprep/config.py", line 116, in <module>
    from templateflow import __version__ as _tf_ver
  File "/opt/conda/lib/python3.8/site-packages/templateflow/__init__.py", line 19, in <module>
    from . import api
  File "/opt/conda/lib/python3.8/site-packages/templateflow/api.py", line 7, in <module>
    from .conf import TF_LAYOUT, TF_S3_ROOT, TF_USE_DATALAD, requires_layout
  File "/opt/conda/lib/python3.8/site-packages/templateflow/conf/__init__.py", line 53, in <module>
    install(path=str(TF_HOME), source=TF_GITHUB_SOURCE, recursive=True)
  File "/opt/conda/lib/python3.8/site-packages/datalad/interface/utils.py", line 484, in eval_func
    return return_func(generator_func)(*args, **kwargs)
  File "/opt/conda/lib/python3.8/site-packages/datalad/interface/utils.py", line 476, in return_func
    results = list(results)
  File "/opt/conda/lib/python3.8/site-packages/datalad/interface/utils.py", line 396, in generator_func
    for r in _process_results(
  File "/opt/conda/lib/python3.8/site-packages/datalad/interface/utils.py", line 579, in _process_results
    for res in results:
  File "/opt/conda/lib/python3.8/site-packages/datalad/distribution/install.py", line 381, in __call__
    for r in destination_dataset.get(
  File "/opt/conda/lib/python3.8/site-packages/datalad/interface/utils.py", line 396, in generator_func
    for r in _process_results(
  File "/opt/conda/lib/python3.8/site-packages/datalad/interface/utils.py", line 579, in _process_results
    for res in results:
  File "/opt/conda/lib/python3.8/site-packages/datalad/distribution/get.py", line 849, in __call__
    refds = require_dataset(
  File "/opt/conda/lib/python3.8/site-packages/datalad/distribution/dataset.py", line 567, in require_dataset
    raise ValueError(u"No installed dataset found at "
ValueError: No installed dataset found at /scratch1/03201/jbwexler/work_dir/fmriprep/ds000117_sub-03/fmriprep_wf/single_subject_03_wf/func_preproc_ses_mri_task_facerecognition_run_05_wf/unwarp_wf/resample/sourcedata/templateflow.
[INFO] Cloning dataset to Dataset(/scratch1/03201/jbwexler/work_dir/fmriprep/ds000117_sub-03/fmriprep_wf/single_subject_03_wf/func_preproc_ses_mri_task_facerecognition_run_06_wf/unwarp_wf/resample/sourcedata/templateflow) 
[INFO] Cloning dataset to Dataset(/scratch1/03201/jbwexler/work_dir/fmriprep/ds000117_sub-03/fmriprep_wf/single_subject_03_wf/func_preproc_ses_mri_task_facerecognition_run_06_wf/unwarp_wf/resample/sourcedata/templateflow) 
[INFO] Attempting to clone from https://github.com/templateflow/templateflow.git to /scratch1/03201/jbwexler/work_dir/fmriprep/ds000117_sub-03/fmriprep_wf/single_subject_03_wf/func_preproc_ses_mri_task_facerecognition_run_06_wf/unwarp_wf/resample/sourcedata/templateflow 
[INFO] Attempting to clone from https://github.com/templateflow/templateflow.git to /scratch1/03201/jbwexler/work_dir/fmriprep/ds000117_sub-03/fmriprep_wf/single_subject_03_wf/func_preproc_ses_mri_task_facerecognition_run_06_wf/unwarp_wf/resample/sourcedata/templateflow 
[INFO] Cloning dataset to Dataset(/scratch1/03201/jbwexler/work_dir/fmriprep/ds000117_sub-03/fmriprep_wf/single_subject_03_wf/func_preproc_ses_mri_task_facerecognition_run_06_wf/unwarp_wf/resample/sourcedata/templateflow) 
[INFO] Attempting to clone from https://github.com/templateflow/templateflow.git to /scratch1/03201/jbwexler/work_dir/fmriprep/ds000117_sub-03/fmriprep_wf/single_subject_03_wf/func_preproc_ses_mri_task_facerecognition_run_06_wf/unwarp_wf/resample/sourcedata/templateflow 
[INFO] Cloning dataset to Dataset(/scratch1/03201/jbwexler/work_dir/fmriprep/ds000117_sub-03/fmriprep_wf/single_subject_03_wf/func_preproc_ses_mri_task_facerecognition_run_06_wf/unwarp_wf/resample/sourcedata/templateflow) 
[INFO] Cloning dataset to Dataset(/scratch1/03201/jbwexler/work_dir/fmriprep/ds000117_sub-03/fmriprep_wf/single_subject_03_wf/func_preproc_ses_mri_task_facerecognition_run_06_wf/unwarp_wf/resample/sourcedata/templateflow) 
[INFO] Attempting to clone from https://github.com/templateflow/templateflow.git to /scratch1/03201/jbwexler/work_dir/fmriprep/ds000117_sub-03/fmriprep_wf/single_subject_03_wf/func_preproc_ses_mri_task_facerecognition_run_06_wf/unwarp_wf/resample/sourcedata/templateflow 
[INFO] Attempting to clone from https://github.com/templateflow/templateflow.git to /scratch1/03201/jbwexler/work_dir/fmriprep/ds000117_sub-03/fmriprep_wf/single_subject_03_wf/func_preproc_ses_mri_task_facerecognition_run_06_wf/unwarp_wf/resample/sourcedata/templateflow 
[INFO] Cloning dataset to Dataset(/scratch1/03201/jbwexler/work_dir/fmriprep/ds000117_sub-03/fmriprep_wf/single_subject_03_wf/func_preproc_ses_mri_task_facerecognition_run_06_wf/unwarp_wf/resample/sourcedata/templateflow) 
[INFO] Cloning dataset to Dataset(/scratch1/03201/jbwexler/work_dir/fmriprep/ds000117_sub-03/fmriprep_wf/single_subject_03_wf/func_preproc_ses_mri_task_facerecognition_run_06_wf/unwarp_wf/resample/sourcedata/templateflow) 
[INFO] Attempting to clone from https://github.com/templateflow/templateflow.git to /scratch1/03201/jbwexler/work_dir/fmriprep/ds000117_sub-03/fmriprep_wf/single_subject_03_wf/func_preproc_ses_mri_task_facerecognition_run_06_wf/unwarp_wf/resample/sourcedata/templateflow 
[INFO] Attempting to clone from https://github.com/templateflow/templateflow.git to /scratch1/03201/jbwexler/work_dir/fmriprep/ds000117_sub-03/fmriprep_wf/single_subject_03_wf/func_preproc_ses_mri_task_facerecognition_run_06_wf/unwarp_wf/resample/sourcedata/templateflow 
Traceback (most recent call last):
  File "/opt/conda/lib/python3.8/site-packages/datalad/core/distributed/clone.py", line 589, in clone_dataset
    GitRepo.clone(
  File "/opt/conda/lib/python3.8/site-packages/datalad/support/gitrepo.py", line 994, in clone
    res = GitWitlessRunner().run(
  File "/opt/conda/lib/python3.8/site-packages/datalad/runner/runner.py", line 145, in run
    raise CommandError(
datalad.runner.exception.CommandError: CommandError: 'git -c diff.ignoreSubmodules=none clone --progress https://github.com/templateflow/templateflow.git /scratch1/03201/jbwexler/work_dir/fmriprep/ds000117_sub-03/fmriprep_wf/single_subject_03_wf/func_preproc_ses_mri_task_facerecognition_run_06_wf/unwarp_wf/resample/sourcedata/templateflow' failed with exitcode 128 [err: 'fatal: destination path '/scratch1/03201/jbwexler/work_dir/fmriprep/ds000117_sub-03/fmriprep_wf/single_subject_03_wf/func_preproc_ses_mri_task_facerecognition_run_06_wf/unwarp_wf/resample/sourcedata/templateflow' already exists and is not an empty directory.']

During handling of the above exception, another exception occurred:

Traceback (most recent call last):
  File "/opt/conda/lib/python3.8/multiprocessing/forkserver.py", line 280, in main
    code = _serve_one(child_r, fds,
  File "/opt/conda/lib/python3.8/multiprocessing/forkserver.py", line 319, in _serve_one
    code = spawn._main(child_r, parent_sentinel)
  File "/opt/conda/lib/python3.8/multiprocessing/spawn.py", line 125, in _main
    prepare(preparation_data)
  File "/opt/conda/lib/python3.8/multiprocessing/spawn.py", line 236, in prepare
    _fixup_main_from_path(data['init_main_from_path'])
  File "/opt/conda/lib/python3.8/multiprocessing/spawn.py", line 287, in _fixup_main_from_path
    main_content = runpy.run_path(main_path,
  File "/opt/conda/lib/python3.8/runpy.py", line 265, in run_path
    return _run_module_code(code, init_globals, run_name,
  File "/opt/conda/lib/python3.8/runpy.py", line 97, in _run_module_code
    _run_code(code, mod_globals, init_globals,
  File "/opt/conda/lib/python3.8/runpy.py", line 87, in _run_code
    exec(code, run_globals)
  File "/opt/conda/bin/fmriprep", line 5, in <module>
    from fmriprep.cli.run import main
  File "/opt/conda/lib/python3.8/site-packages/fmriprep/cli/run.py", line 25, in <module>
    from .. import config
  File "/opt/conda/lib/python3.8/site-packages/fmriprep/config.py", line 116, in <module>
    from templateflow import __version__ as _tf_ver
  File "/opt/conda/lib/python3.8/site-packages/templateflow/__init__.py", line 19, in <module>
    from . import api
  File "/opt/conda/lib/python3.8/site-packages/templateflow/api.py", line 7, in <module>
    from .conf import TF_LAYOUT, TF_S3_ROOT, TF_USE_DATALAD, requires_layout
  File "/opt/conda/lib/python3.8/site-packages/templateflow/conf/__init__.py", line 53, in <module>
    install(path=str(TF_HOME), source=TF_GITHUB_SOURCE, recursive=True)
  File "/opt/conda/lib/python3.8/site-packages/datalad/interface/utils.py", line 484, in eval_func
    return return_func(generator_func)(*args, **kwargs)
  File "/opt/conda/lib/python3.8/site-packages/datalad/interface/utils.py", line 476, in return_func
    results = list(results)
  File "/opt/conda/lib/python3.8/site-packages/datalad/interface/utils.py", line 396, in generator_func
    for r in _process_results(
  File "/opt/conda/lib/python3.8/site-packages/datalad/interface/utils.py", line 579, in _process_results
    for res in results:
  File "/opt/conda/lib/python3.8/site-packages/datalad/distribution/install.py", line 365, in __call__
    for r in res:
  File "/opt/conda/lib/python3.8/site-packages/datalad/interface/utils.py", line 396, in generator_func
    for r in _process_results(
  File "/opt/conda/lib/python3.8/site-packages/datalad/interface/utils.py", line 579, in _process_results
    for res in results:
  File "/opt/conda/lib/python3.8/site-packages/datalad/core/distributed/clone.py", line 320, in __call__
    yield from clone_dataset(
  File "/opt/conda/lib/python3.8/site-packages/datalad/core/distributed/clone.py", line 609, in clone_dataset
    rmtree(str(dest_path), children_only=dest_path_existed)
  File "/opt/conda/lib/python3.8/site-packages/datalad/utils.py", line 471, in rmtree
[INFO] Attempting to clone from https://github.com/templateflow/templateflow.git/.git to /scratch1/03201/jbwexler/work_dir/fmriprep/ds000117_sub-03/fmriprep_wf/single_subject_03_wf/func_preproc_ses_mri_task_facerecognition_run_06_wf/unwarp_wf/resample/sourcedata/templateflow 
    rotree(path, ro=False, chmod_files=chmod_files)
  File "/opt/conda/lib/python3.8/site-packages/datalad/utils.py", line 435, in rotree
    chmod(root)
  File "/opt/conda/lib/python3.8/site-packages/datalad/utils.py", line 426, in <lambda>
[INFO] Attempting to clone from https://github.com/templateflow/templateflow.git/.git to /scratch1/03201/jbwexler/work_dir/fmriprep/ds000117_sub-03/fmriprep_wf/single_subject_03_wf/func_preproc_ses_mri_task_facerecognition_run_06_wf/unwarp_wf/resample/sourcedata/templateflow 
    chmod = lambda f: os.chmod(f, os.stat(f).st_mode | stat.S_IWRITE | stat.S_IREAD)
FileNotFoundError: [Errno 2] No such file or directory: '/scratch1/03201/jbwexler/work_dir/fmriprep/ds000117_sub-03/fmriprep_wf/single_subject_03_wf/func_preproc_ses_mri_task_facerecognition_run_06_wf/unwarp_wf/resample/sourcedata/templateflow/.git/hooks'
[INFO] Attempting to clone from https://github.com/templateflow/templateflow.git/.git to /scratch1/03201/jbwexler/work_dir/fmriprep/ds000117_sub-03/fmriprep_wf/single_subject_03_wf/func_preproc_ses_mri_task_facerecognition_run_06_wf/unwarp_wf/resample/sourcedata/templateflow 
[INFO] Attempting to clone from https://github.com/templateflow/templateflow.git/.git to /scratch1/03201/jbwexler/work_dir/fmriprep/ds000117_sub-03/fmriprep_wf/single_subject_03_wf/func_preproc_ses_mri_task_facerecognition_run_06_wf/unwarp_wf/resample/sourcedata/templateflow 
[INFO] Cloning dataset to Dataset(/scratch1/03201/jbwexler/work_dir/fmriprep/ds000117_sub-03/fmriprep_wf/single_subject_03_wf/func_preproc_ses_mri_task_facerecognition_run_07_wf/unwarp_wf/resample/sourcedata/templateflow) 
[INFO] Attempting to clone from https://github.com/templateflow/templateflow.git to /scratch1/03201/jbwexler/work_dir/fmriprep/ds000117_sub-03/fmriprep_wf/single_subject_03_wf/func_preproc_ses_mri_task_facerecognition_run_07_wf/unwarp_wf/resample/sourcedata/templateflow 
Traceback (most recent call last):
Traceback (most recent call last):
  File "/opt/conda/lib/python3.8/multiprocessing/forkserver.py", line 280, in main
  File "/opt/conda/lib/python3.8/multiprocessing/forkserver.py", line 280, in main
Traceback (most recent call last):
Traceback (most recent call last):
  File "/opt/conda/lib/python3.8/multiprocessing/forkserver.py", line 280, in main
  File "/opt/conda/lib/python3.8/multiprocessing/forkserver.py", line 280, in main
        code = _serve_one(child_r, fds,code = _serve_one(child_r, fds,
        
  File "/opt/conda/lib/python3.8/multiprocessing/forkserver.py", line 319, in _serve_one
code = _serve_one(child_r, fds,code = _serve_one(child_r, fds,  File "/opt/conda/lib/python3.8/multiprocessing/forkserver.py", line 319, in _serve_one


  File "/opt/conda/lib/python3.8/multiprocessing/forkserver.py", line 319, in _serve_one
  File "/opt/conda/lib/python3.8/multiprocessing/forkserver.py", line 319, in _serve_one
    code = spawn._main(child_r, parent_sentinel)
      File "/opt/conda/lib/python3.8/multiprocessing/spawn.py", line 125, in _main
    code = spawn._main(child_r, parent_sentinel)    code = spawn._main(child_r, parent_sentinel)
code = spawn._main(child_r, parent_sentinel)

  File "/opt/conda/lib/python3.8/multiprocessing/spawn.py", line 125, in _main
  File "/opt/conda/lib/python3.8/multiprocessing/spawn.py", line 125, in _main
  File "/opt/conda/lib/python3.8/multiprocessing/spawn.py", line 125, in _main
    prepare(preparation_data)
  File "/opt/conda/lib/python3.8/multiprocessing/spawn.py", line 236, in prepare
        prepare(preparation_data)    prepare(preparation_data)
prepare(preparation_data)

  File "/opt/conda/lib/python3.8/multiprocessing/spawn.py", line 236, in prepare
  File "/opt/conda/lib/python3.8/multiprocessing/spawn.py", line 236, in prepare
  File "/opt/conda/lib/python3.8/multiprocessing/spawn.py", line 236, in prepare
    _fixup_main_from_path(data['init_main_from_path'])
  File "/opt/conda/lib/python3.8/multiprocessing/spawn.py", line 287, in _fixup_main_from_path
            _fixup_main_from_path(data['init_main_from_path'])_fixup_main_from_path(data['init_main_from_path'])

_fixup_main_from_path(data['init_main_from_path'])
  File "/opt/conda/lib/python3.8/multiprocessing/spawn.py", line 287, in _fixup_main_from_path
  File "/opt/conda/lib/python3.8/multiprocessing/spawn.py", line 287, in _fixup_main_from_path
  File "/opt/conda/lib/python3.8/multiprocessing/spawn.py", line 287, in _fixup_main_from_path
    main_content = runpy.run_path(main_path,
  File "/opt/conda/lib/python3.8/runpy.py", line 265, in run_path
            main_content = runpy.run_path(main_path,main_content = runpy.run_path(main_path,main_content = runpy.run_path(main_path,


  File "/opt/conda/lib/python3.8/runpy.py", line 265, in run_path
  File "/opt/conda/lib/python3.8/runpy.py", line 265, in run_path
  File "/opt/conda/lib/python3.8/runpy.py", line 265, in run_path
    return _run_module_code(code, init_globals, run_name,
  File "/opt/conda/lib/python3.8/runpy.py", line 97, in _run_module_code
            return _run_module_code(code, init_globals, run_name,    return _run_module_code(code, init_globals, run_name,return _run_module_code(code, init_globals, run_name,
_run_code(code, mod_globals, init_globals,


  File "/opt/conda/lib/python3.8/runpy.py", line 97, in _run_module_code
  File "/opt/conda/lib/python3.8/runpy.py", line 97, in _run_module_code
  File "/opt/conda/lib/python3.8/runpy.py", line 97, in _run_module_code
  File "/opt/conda/lib/python3.8/runpy.py", line 87, in _run_code
                _run_code(code, mod_globals, init_globals,_run_code(code, mod_globals, init_globals,
exec(code, run_globals)_run_code(code, mod_globals, init_globals,

  File "/opt/conda/lib/python3.8/runpy.py", line 87, in _run_code

  File "/opt/conda/lib/python3.8/runpy.py", line 87, in _run_code
  File "/opt/conda/bin/fmriprep", line 5, in <module>
  File "/opt/conda/lib/python3.8/runpy.py", line 87, in _run_code
        from fmriprep.cli.run import main    exec(code, run_globals)
exec(code, run_globals)    
  File "/opt/conda/lib/python3.8/site-packages/fmriprep/cli/run.py", line 25, in <module>
exec(code, run_globals)  File "/opt/conda/bin/fmriprep", line 5, in <module>


  File "/opt/conda/bin/fmriprep", line 5, in <module>
  File "/opt/conda/bin/fmriprep", line 5, in <module>
    from fmriprep.cli.run import main    
    from .. import config      File "/opt/conda/lib/python3.8/site-packages/fmriprep/cli/run.py", line 25, in <module>
from fmriprep.cli.run import main
from fmriprep.cli.run import main
  File "/opt/conda/lib/python3.8/site-packages/fmriprep/config.py", line 116, in <module>
    
  File "/opt/conda/lib/python3.8/site-packages/fmriprep/cli/run.py", line 25, in <module>
from .. import config
  File "/opt/conda/lib/python3.8/site-packages/fmriprep/cli/run.py", line 25, in <module>
  File "/opt/conda/lib/python3.8/site-packages/fmriprep/config.py", line 116, in <module>
    from .. import config
        from .. import config  File "/opt/conda/lib/python3.8/site-packages/fmriprep/config.py", line 116, in <module>
from templateflow import __version__ as _tf_ver

  File "/opt/conda/lib/python3.8/site-packages/fmriprep/config.py", line 116, in <module>
  File "/opt/conda/lib/python3.8/site-packages/templateflow/__init__.py", line 19, in <module>
    from templateflow import __version__ as _tf_ver
  File "/opt/conda/lib/python3.8/site-packages/templateflow/__init__.py", line 19, in <module>
    from . import api
  File "/opt/conda/lib/python3.8/site-packages/templateflow/api.py", line 7, in <module>
        from . import apifrom templateflow import __version__ as _tf_ver

      File "/opt/conda/lib/python3.8/site-packages/templateflow/api.py", line 7, in <module>
from templateflow import __version__ as _tf_ver      File "/opt/conda/lib/python3.8/site-packages/templateflow/__init__.py", line 19, in <module>

from .conf import TF_LAYOUT, TF_S3_ROOT, TF_USE_DATALAD, requires_layout
  File "/opt/conda/lib/python3.8/site-packages/templateflow/__init__.py", line 19, in <module>
  File "/opt/conda/lib/python3.8/site-packages/templateflow/conf/__init__.py", line 53, in <module>
    from .conf import TF_LAYOUT, TF_S3_ROOT, TF_USE_DATALAD, requires_layout
    from . import api  File "/opt/conda/lib/python3.8/site-packages/templateflow/conf/__init__.py", line 53, in <module>
    
from . import api
  File "/opt/conda/lib/python3.8/site-packages/templateflow/api.py", line 7, in <module>
      File "/opt/conda/lib/python3.8/site-packages/templateflow/api.py", line 7, in <module>
install(path=str(TF_HOME), source=TF_GITHUB_SOURCE, recursive=True)
      File "/opt/conda/lib/python3.8/site-packages/datalad/interface/utils.py", line 484, in eval_func
install(path=str(TF_HOME), source=TF_GITHUB_SOURCE, recursive=True)    
    from .conf import TF_LAYOUT, TF_S3_ROOT, TF_USE_DATALAD, requires_layout  File "/opt/conda/lib/python3.8/site-packages/datalad/interface/utils.py", line 484, in eval_func

from .conf import TF_LAYOUT, TF_S3_ROOT, TF_USE_DATALAD, requires_layout
  File "/opt/conda/lib/python3.8/site-packages/templateflow/conf/__init__.py", line 53, in <module>
  File "/opt/conda/lib/python3.8/site-packages/templateflow/conf/__init__.py", line 53, in <module>
        install(path=str(TF_HOME), source=TF_GITHUB_SOURCE, recursive=True)install(path=str(TF_HOME), source=TF_GITHUB_SOURCE, recursive=True)

  File "/opt/conda/lib/python3.8/site-packages/datalad/interface/utils.py", line 484, in eval_func
  File "/opt/conda/lib/python3.8/site-packages/datalad/interface/utils.py", line 484, in eval_func
    return return_func(generator_func)(*args, **kwargs)
  File "/opt/conda/lib/python3.8/site-packages/datalad/interface/utils.py", line 476, in return_func
    return return_func(generator_func)(*args, **kwargs)
  File "/opt/conda/lib/python3.8/site-packages/datalad/interface/utils.py", line 476, in return_func
        return return_func(generator_func)(*args, **kwargs)return return_func(generator_func)(*args, **kwargs)

      File "/opt/conda/lib/python3.8/site-packages/datalad/interface/utils.py", line 476, in return_func
  File "/opt/conda/lib/python3.8/site-packages/datalad/interface/utils.py", line 476, in return_func
results = list(results)
      File "/opt/conda/lib/python3.8/site-packages/datalad/interface/utils.py", line 396, in generator_func
results = list(results)
  File "/opt/conda/lib/python3.8/site-packages/datalad/interface/utils.py", line 396, in generator_func
            results = list(results)results = list(results)for r in _process_results(
    

for r in _process_results(  File "/opt/conda/lib/python3.8/site-packages/datalad/interface/utils.py", line 396, in generator_func

  File "/opt/conda/lib/python3.8/site-packages/datalad/interface/utils.py", line 396, in generator_func
  File "/opt/conda/lib/python3.8/site-packages/datalad/interface/utils.py", line 579, in _process_results
  File "/opt/conda/lib/python3.8/site-packages/datalad/interface/utils.py", line 579, in _process_results
        for r in _process_results(for r in _process_results(

  File "/opt/conda/lib/python3.8/site-packages/datalad/interface/utils.py", line 579, in _process_results
  File "/opt/conda/lib/python3.8/site-packages/datalad/interface/utils.py", line 579, in _process_results
    for res in results:
  File "/opt/conda/lib/python3.8/site-packages/datalad/distribution/install.py", line 365, in __call__
    for res in results:
  File "/opt/conda/lib/python3.8/site-packages/datalad/distribution/install.py", line 381, in __call__
            for res in results:for r in res:for res in results:


  File "/opt/conda/lib/python3.8/site-packages/datalad/distribution/install.py", line 381, in __call__
  File "/opt/conda/lib/python3.8/site-packages/datalad/interface/utils.py", line 396, in generator_func
  File "/opt/conda/lib/python3.8/site-packages/datalad/distribution/install.py", line 381, in __call__
    for r in destination_dataset.get(
  File "/opt/conda/lib/python3.8/site-packages/datalad/distribution/dataset.py", line 484, in apply_func
    for r in _process_results(    
    for r in destination_dataset.get(
for r in destination_dataset.get(  File "/opt/conda/lib/python3.8/site-packages/datalad/interface/utils.py", line 579, in _process_results

  File "/opt/conda/lib/python3.8/site-packages/datalad/distribution/dataset.py", line 484, in apply_func
  File "/opt/conda/lib/python3.8/site-packages/datalad/distribution/dataset.py", line 484, in apply_func
    return f(**kwargs)
  File "/opt/conda/lib/python3.8/site-packages/datalad/interface/utils.py", line 375, in eval_func
    for res in results:        
return f(**kwargs)return f(**kwargs)    
  File "/opt/conda/lib/python3.8/site-packages/datalad/core/distributed/clone.py", line 320, in __call__

hooks = get_jsonhooks_from_config(ds.config if ds else dlcfg)  File "/opt/conda/lib/python3.8/site-packages/datalad/interface/utils.py", line 375, in eval_func

  File "/opt/conda/lib/python3.8/site-packages/datalad/interface/utils.py", line 375, in eval_func
  File "/opt/conda/lib/python3.8/site-packages/datalad/distribution/dataset.py", line 325, in config
    yield from clone_dataset(    
        hooks = get_jsonhooks_from_config(ds.config if ds else dlcfg)hooks = get_jsonhooks_from_config(ds.config if ds else dlcfg)repo = self.repo


  File "/opt/conda/lib/python3.8/site-packages/datalad/distribution/dataset.py", line 271, in repo
  File "/opt/conda/lib/python3.8/site-packages/datalad/distribution/dataset.py", line 325, in config
  File "/opt/conda/lib/python3.8/site-packages/datalad/distribution/dataset.py", line 325, in config
  File "/opt/conda/lib/python3.8/site-packages/datalad/core/distributed/clone.py", line 527, in clone_dataset
    self._repo = repo_from_path(self._path)
        repo = self.repo  File "/opt/conda/lib/python3.8/site-packages/datalad/core/local/repo.py", line 56, in repo_from_path
repo = self.repo

  File "/opt/conda/lib/python3.8/site-packages/datalad/distribution/dataset.py", line 271, in repo
  File "/opt/conda/lib/python3.8/site-packages/datalad/distribution/dataset.py", line 271, in repo
    if destds.is_installed():
  File "/opt/conda/lib/python3.8/site-packages/datalad/distribution/dataset.py", line 366, in is_installed
        self._repo = repo_from_path(self._path)self._repo = repo_from_path(self._path)

  File "/opt/conda/lib/python3.8/site-packages/datalad/core/local/repo.py", line 56, in repo_from_path
  File "/opt/conda/lib/python3.8/site-packages/datalad/core/local/repo.py", line 56, in repo_from_path
    self.repo is not None
  File "/opt/conda/lib/python3.8/site-packages/datalad/distribution/dataset.py", line 271, in repo
    self._repo = repo_from_path(self._path)
  File "/opt/conda/lib/python3.8/site-packages/datalad/core/local/repo.py", line 56, in repo_from_path
        if not cls.is_valid_repo(path, **ckw):    if not cls.is_valid_repo(path, **ckw):
    if not cls.is_valid_repo(path, **ckw):
  File "/opt/conda/lib/python3.8/site-packages/datalad/support/annexrepo.py", line 670, in is_valid_repo
if not cls.is_valid_repo(path, **ckw):
  File "/opt/conda/lib/python3.8/site-packages/datalad/support/annexrepo.py", line 670, in is_valid_repo

  File "/opt/conda/lib/python3.8/site-packages/datalad/support/annexrepo.py", line 670, in is_valid_repo
  File "/opt/conda/lib/python3.8/site-packages/datalad/support/annexrepo.py", line 670, in is_valid_repo
    return initialized_annex or GitRepo(path, create=False, init=False).is_with_annex()
      File "/opt/conda/lib/python3.8/site-packages/datalad/support/gitrepo.py", line 1120, in is_with_annex
    return initialized_annex or GitRepo(path, create=False, init=False).is_with_annex()
return initialized_annex or GitRepo(path, create=False, init=False).is_with_annex()
  File "/opt/conda/lib/python3.8/site-packages/datalad/support/gitrepo.py", line 1120, in is_with_annex
  File "/opt/conda/lib/python3.8/site-packages/datalad/support/gitrepo.py", line 1120, in is_with_annex
    return initialized_annex or GitRepo(path, create=False, init=False).is_with_annex()
  File "/opt/conda/lib/python3.8/site-packages/datalad/support/gitrepo.py", line 1120, in is_with_annex
    return any(
  File "/opt/conda/lib/python3.8/site-packages/datalad/support/gitrepo.py", line 1120, in <genexpr>
    return any(    
return any(
  File "/opt/conda/lib/python3.8/site-packages/datalad/support/gitrepo.py", line 1120, in <genexpr>
  File "/opt/conda/lib/python3.8/site-packages/datalad/support/gitrepo.py", line 1120, in <genexpr>
    return any(
  File "/opt/conda/lib/python3.8/site-packages/datalad/support/gitrepo.py", line 1120, in <genexpr>
    return any(
  File "/opt/conda/lib/python3.8/site-packages/datalad/dataset/gitrepo.py", line 503, in for_each_ref_
        return any(return any(

  File "/opt/conda/lib/python3.8/site-packages/datalad/dataset/gitrepo.py", line 503, in for_each_ref_
  File "/opt/conda/lib/python3.8/site-packages/datalad/dataset/gitrepo.py", line 503, in for_each_ref_
    return any(
  File "/opt/conda/lib/python3.8/site-packages/datalad/dataset/gitrepo.py", line 503, in for_each_ref_
        for line in self.call_git_items_(cmd, read_only=True):for line in self.call_git_items_(cmd, read_only=True):    

    for line in self.call_git_items_(cmd, read_only=True):  File "/opt/conda/lib/python3.8/site-packages/datalad/dataset/gitrepo.py", line 343, in call_git_items_
  File "/opt/conda/lib/python3.8/site-packages/datalad/dataset/gitrepo.py", line 343, in call_git_items_

for line in self.call_git_items_(cmd, read_only=True):
  File "/opt/conda/lib/python3.8/site-packages/datalad/dataset/gitrepo.py", line 343, in call_git_items_
  File "/opt/conda/lib/python3.8/site-packages/datalad/dataset/gitrepo.py", line 343, in call_git_items_
        out, _ = self._call_git(args, files, expect_stderr=expect_stderr,out, _ = self._call_git(args, files, expect_stderr=expect_stderr,

      File "/opt/conda/lib/python3.8/site-packages/datalad/dataset/gitrepo.py", line 259, in _call_git
  File "/opt/conda/lib/python3.8/site-packages/datalad/dataset/gitrepo.py", line 259, in _call_git
out, _ = self._call_git(args, files, expect_stderr=expect_stderr,    
out, _ = self._call_git(args, files, expect_stderr=expect_stderr,
  File "/opt/conda/lib/python3.8/site-packages/datalad/dataset/gitrepo.py", line 259, in _call_git
  File "/opt/conda/lib/python3.8/site-packages/datalad/dataset/gitrepo.py", line 259, in _call_git
        res = runner.run(res = runner.run(

      File "/opt/conda/lib/python3.8/site-packages/datalad/runner/runner.py", line 145, in run
  File "/opt/conda/lib/python3.8/site-packages/datalad/runner/runner.py", line 145, in run
res = runner.run(    
res = runner.run(
  File "/opt/conda/lib/python3.8/site-packages/datalad/runner/runner.py", line 145, in run
  File "/opt/conda/lib/python3.8/site-packages/datalad/runner/runner.py", line 145, in run
        raise CommandError(raise CommandError(

datalad.runner.exceptiondatalad.runner.exception..CommandErrorCommandError        raise CommandError(raise CommandError(

: datalad.runner.exceptiondatalad.runner.exception: ..CommandErrorCommandError: 'git -c diff.ignoreSubmodules=none for-each-ref '--format=%(refname:strip=2)' refs/heads refs/remotes' failed with exitcode 128 under /scratch1/03201/jbwexler/work_dir/fmriprep/ds000117_sub-03/fmriprep_wf/single_subject_03_wf/func_preproc_ses_mri_task_facerecognition_run_07_wf/unwarp_wf/resample/sourcedata/templateflow [err: 'fatal: not a git repository (or any parent up to mount point /)
Stopping at filesystem boundary (GIT_DISCOVERY_ACROSS_FILESYSTEM not set).']CommandError
CommandError: 'git -c diff.ignoreSubmodules=none for-each-ref '--format=%(refname:strip=2)' refs/heads refs/remotes' failed with exitcode 128 under /scratch1/03201/jbwexler/work_dir/fmriprep/ds000117_sub-03/fmriprep_wf/single_subject_03_wf/func_preproc_ses_mri_task_facerecognition_run_07_wf/unwarp_wf/resample/sourcedata/templateflow [err: 'fatal: not a git repository (or any parent up to mount point /)
Stopping at filesystem boundary (GIT_DISCOVERY_ACROSS_FILESYSTEM not set).']
: : CommandError: 'git -c diff.ignoreSubmodules=none for-each-ref '--format=%(refname:strip=2)' refs/heads refs/remotes' failed with exitcode 128 under /scratch1/03201/jbwexler/work_dir/fmriprep/ds000117_sub-03/fmriprep_wf/single_subject_03_wf/func_preproc_ses_mri_task_facerecognition_run_07_wf/unwarp_wf/resample/sourcedata/templateflow [err: 'fatal: not a git repository (or any parent up to mount point /)
Stopping at filesystem boundary (GIT_DISCOVERY_ACROSS_FILESYSTEM not set).']
CommandError: 'git -c diff.ignoreSubmodules=none for-each-ref '--format=%(refname:strip=2)' refs/heads refs/remotes' failed with exitcode 128 under /scratch1/03201/jbwexler/work_dir/fmriprep/ds000117_sub-03/fmriprep_wf/single_subject_03_wf/func_preproc_ses_mri_task_facerecognition_run_07_wf/unwarp_wf/resample/sourcedata/templateflow [err: 'fatal: not a git repository (or any parent up to mount point /)
Stopping at filesystem boundary (GIT_DISCOVERY_ACROSS_FILESYSTEM not set).']
[INFO] Cloning dataset to Dataset(/scratch1/03201/jbwexler/work_dir/fmriprep/ds000117_sub-03/fmriprep_wf/single_subject_03_wf/func_preproc_ses_mri_task_facerecognition_run_08_wf/unwarp_wf/resample/sourcedata/templateflow) 
[INFO] Cloning dataset to Dataset(/scratch1/03201/jbwexler/work_dir/fmriprep/ds000117_sub-03/fmriprep_wf/single_subject_03_wf/func_preproc_ses_mri_task_facerecognition_run_08_wf/unwarp_wf/resample/sourcedata/templateflow) 
[INFO] Cloning dataset to Dataset(/scratch1/03201/jbwexler/work_dir/fmriprep/ds000117_sub-03/fmriprep_wf/single_subject_03_wf/func_preproc_ses_mri_task_facerecognition_run_08_wf/unwarp_wf/resample/sourcedata/templateflow) 
[INFO] Attempting to clone from https://github.com/templateflow/templateflow.git to /scratch1/03201/jbwexler/work_dir/fmriprep/ds000117_sub-03/fmriprep_wf/single_subject_03_wf/func_preproc_ses_mri_task_facerecognition_run_08_wf/unwarp_wf/resample/sourcedata/templateflow 
[INFO] Attempting to clone from https://github.com/templateflow/templateflow.git to /scratch1/03201/jbwexler/work_dir/fmriprep/ds000117_sub-03/fmriprep_wf/single_subject_03_wf/func_preproc_ses_mri_task_facerecognition_run_08_wf/unwarp_wf/resample/sourcedata/templateflow 
[INFO] Attempting to clone from https://github.com/templateflow/templateflow.git to /scratch1/03201/jbwexler/work_dir/fmriprep/ds000117_sub-03/fmriprep_wf/single_subject_03_wf/func_preproc_ses_mri_task_facerecognition_run_08_wf/unwarp_wf/resample/sourcedata/templateflow 
[INFO] Cloning dataset to Dataset(/scratch1/03201/jbwexler/work_dir/fmriprep/ds000117_sub-03/fmriprep_wf/single_subject_03_wf/func_preproc_ses_mri_task_facerecognition_run_08_wf/unwarp_wf/resample/sourcedata/templateflow) 
[INFO] Attempting to clone from https://github.com/templateflow/templateflow.git to /scratch1/03201/jbwexler/work_dir/fmriprep/ds000117_sub-03/fmriprep_wf/single_subject_03_wf/func_preproc_ses_mri_task_facerecognition_run_08_wf/unwarp_wf/resample/sourcedata/templateflow 
[INFO] Cloning dataset to Dataset(/scratch1/03201/jbwexler/work_dir/fmriprep/ds000117_sub-03/fmriprep_wf/single_subject_03_wf/func_preproc_ses_mri_task_facerecognition_run_08_wf/unwarp_wf/resample/sourcedata/templateflow) 
[INFO] Cloning dataset to Dataset(/scratch1/03201/jbwexler/work_dir/fmriprep/ds000117_sub-03/fmriprep_wf/single_subject_03_wf/func_preproc_ses_mri_task_facerecognition_run_08_wf/unwarp_wf/resample/sourcedata/templateflow) 
[INFO] Attempting to clone from https://github.com/templateflow/templateflow.git to /scratch1/03201/jbwexler/work_dir/fmriprep/ds000117_sub-03/fmriprep_wf/single_subject_03_wf/func_preproc_ses_mri_task_facerecognition_run_08_wf/unwarp_wf/resample/sourcedata/templateflow 
[INFO] Attempting to clone from https://github.com/templateflow/templateflow.git to /scratch1/03201/jbwexler/work_dir/fmriprep/ds000117_sub-03/fmriprep_wf/single_subject_03_wf/func_preproc_ses_mri_task_facerecognition_run_08_wf/unwarp_wf/resample/sourcedata/templateflow 
[INFO] Cloning dataset to Dataset(/scratch1/03201/jbwexler/work_dir/fmriprep/ds000117_sub-03/fmriprep_wf/single_subject_03_wf/func_preproc_ses_mri_task_facerecognition_run_08_wf/unwarp_wf/resample/sourcedata/templateflow) 
[INFO] Attempting to clone from https://github.com/templateflow/templateflow.git to /scratch1/03201/jbwexler/work_dir/fmriprep/ds000117_sub-03/fmriprep_wf/single_subject_03_wf/func_preproc_ses_mri_task_facerecognition_run_08_wf/unwarp_wf/resample/sourcedata/templateflow 
Traceback (most recent call last):
  File "/opt/conda/lib/python3.8/site-packages/datalad/core/distributed/clone.py", line 589, in clone_dataset
Traceback (most recent call last):
  File "/opt/conda/lib/python3.8/site-packages/datalad/core/distributed/clone.py", line 589, in clone_dataset
        GitRepo.clone(GitRepo.clone(

  File "/opt/conda/lib/python3.8/site-packages/datalad/support/gitrepo.py", line 994, in clone
  File "/opt/conda/lib/python3.8/site-packages/datalad/support/gitrepo.py", line 994, in clone
        res = GitWitlessRunner().run(res = GitWitlessRunner().run(

  File "/opt/conda/lib/python3.8/site-packages/datalad/runner/runner.py", line 145, in run
  File "/opt/conda/lib/python3.8/site-packages/datalad/runner/runner.py", line 145, in run
        raise CommandError(raise CommandError(

datalad.runner.exceptiondatalad.runner.exception..CommandErrorCommandError: : CommandError: 'git -c diff.ignoreSubmodules=none clone --progress https://github.com/templateflow/templateflow.git /scratch1/03201/jbwexler/work_dir/fmriprep/ds000117_sub-03/fmriprep_wf/single_subject_03_wf/func_preproc_ses_mri_task_facerecognition_run_08_wf/unwarp_wf/resample/sourcedata/templateflow' failed with exitcode 128 [err: 'Cloning into '/scratch1/03201/jbwexler/work_dir/fmriprep/ds000117_sub-03/fmriprep_wf/single_subject_03_wf/func_preproc_ses_mri_task_facerecognition_run_08_wf/unwarp_wf/resample/sourcedata/templateflow'...
fatal: cannot copy '/opt/conda/share/git-core/templates/hooks/applypatch-msg.sample' to '/scratch1/03201/jbwexler/work_dir/fmriprep/ds000117_sub-03/fmriprep_wf/single_subject_03_wf/func_preproc_ses_mri_task_facerecognition_run_08_wf/unwarp_wf/resample/sourcedata/templateflow/.git/hooks/applypatch-msg.sample': File exists']

During handling of the above exception, another exception occurred:

Traceback (most recent call last):
CommandError: 'git -c diff.ignoreSubmodules=none clone --progress https://github.com/templateflow/templateflow.git /scratch1/03201/jbwexler/work_dir/fmriprep/ds000117_sub-03/fmriprep_wf/single_subject_03_wf/func_preproc_ses_mri_task_facerecognition_run_08_wf/unwarp_wf/resample/sourcedata/templateflow' failed with exitcode 128 [err: 'Cloning into '/scratch1/03201/jbwexler/work_dir/fmriprep/ds000117_sub-03/fmriprep_wf/single_subject_03_wf/func_preproc_ses_mri_task_facerecognition_run_08_wf/unwarp_wf/resample/sourcedata/templateflow'...
fatal: cannot copy '/opt/conda/share/git-core/templates/hooks/commit-msg.sample' to '/scratch1/03201/jbwexler/work_dir/fmriprep/ds000117_sub-03/fmriprep_wf/single_subject_03_wf/func_preproc_ses_mri_task_facerecognition_run_08_wf/unwarp_wf/resample/sourcedata/templateflow/.git/hooks/commit-msg.sample': File exists']  File "/opt/conda/lib/python3.8/multiprocessing/forkserver.py", line 280, in main


During handling of the above exception, another exception occurred:

Traceback (most recent call last):
  File "/opt/conda/lib/python3.8/multiprocessing/forkserver.py", line 280, in main
    code = _serve_one(child_r, fds,
  File "/opt/conda/lib/python3.8/multiprocessing/forkserver.py", line 319, in _serve_one
    code = _serve_one(child_r, fds,
  File "/opt/conda/lib/python3.8/multiprocessing/forkserver.py", line 319, in _serve_one
    code = spawn._main(child_r, parent_sentinel)
  File "/opt/conda/lib/python3.8/multiprocessing/spawn.py", line 125, in _main
    Traceback (most recent call last):
code = spawn._main(child_r, parent_sentinel)
  File "/opt/conda/lib/python3.8/multiprocessing/spawn.py", line 125, in _main
  File "/opt/conda/lib/python3.8/site-packages/datalad/core/distributed/clone.py", line 589, in clone_dataset
    prepare(preparation_data)
  File "/opt/conda/lib/python3.8/multiprocessing/spawn.py", line 236, in prepare
    prepare(preparation_data)
  File "/opt/conda/lib/python3.8/multiprocessing/spawn.py", line 236, in prepare
    _fixup_main_from_path(data['init_main_from_path'])
  File "/opt/conda/lib/python3.8/multiprocessing/spawn.py", line 287, in _fixup_main_from_path
    _fixup_main_from_path(data['init_main_from_path'])
  File "/opt/conda/lib/python3.8/multiprocessing/spawn.py", line 287, in _fixup_main_from_path
    main_content = runpy.run_path(main_path,
      File "/opt/conda/lib/python3.8/runpy.py", line 265, in run_path
GitRepo.clone(
  File "/opt/conda/lib/python3.8/site-packages/datalad/support/gitrepo.py", line 994, in clone
    main_content = runpy.run_path(main_path,
  File "/opt/conda/lib/python3.8/runpy.py", line 265, in run_path
    return _run_module_code(code, init_globals, run_name,
  File "/opt/conda/lib/python3.8/runpy.py", line 97, in _run_module_code
    return _run_module_code(code, init_globals, run_name,
      File "/opt/conda/lib/python3.8/runpy.py", line 97, in _run_module_code
_run_code(code, mod_globals, init_globals,
  File "/opt/conda/lib/python3.8/runpy.py", line 87, in _run_code
    _run_code(code, mod_globals, init_globals,
      File "/opt/conda/lib/python3.8/runpy.py", line 87, in _run_code
    exec(code, run_globals)res = GitWitlessRunner().run(

  File "/opt/conda/bin/fmriprep", line 5, in <module>
  File "/opt/conda/lib/python3.8/site-packages/datalad/runner/runner.py", line 145, in run
    exec(code, run_globals)
      File "/opt/conda/bin/fmriprep", line 5, in <module>
from fmriprep.cli.run import main
  File "/opt/conda/lib/python3.8/site-packages/fmriprep/cli/run.py", line 25, in <module>
    raise CommandError(    
from fmriprep.cli.run import main
datalad.runner.exception.  File "/opt/conda/lib/python3.8/site-packages/fmriprep/cli/run.py", line 25, in <module>
CommandError    from .. import config
  File "/opt/conda/lib/python3.8/site-packages/fmriprep/config.py", line 116, in <module>
    : from .. import config
  File "/opt/conda/lib/python3.8/site-packages/fmriprep/config.py", line 116, in <module>
CommandError: 'git -c diff.ignoreSubmodules=none clone --progress https://github.com/templateflow/templateflow.git /scratch1/03201/jbwexler/work_dir/fmriprep/ds000117_sub-03/fmriprep_wf/single_subject_03_wf/func_preproc_ses_mri_task_facerecognition_run_08_wf/unwarp_wf/resample/sourcedata/templateflow' failed with exitcode 128 [err: 'Cloning into '/scratch1/03201/jbwexler/work_dir/fmriprep/ds000117_sub-03/fmriprep_wf/single_subject_03_wf/func_preproc_ses_mri_task_facerecognition_run_08_wf/unwarp_wf/resample/sourcedata/templateflow'...
fatal: cannot copy '/opt/conda/share/git-core/templates/hooks/applypatch-msg.sample' to '/scratch1/03201/jbwexler/work_dir/fmriprep/ds000117_sub-03/fmriprep_wf/single_subject_03_wf/func_preproc_ses_mri_task_facerecognition_run_08_wf/unwarp_wf/resample/sourcedata/templateflow/.git/hooks/applypatch-msg.sample': File exists']    
from templateflow import __version__ as _tf_ver
During handling of the above exception, another exception occurred:


    Traceback (most recent call last):
  File "/opt/conda/lib/python3.8/site-packages/templateflow/__init__.py", line 19, in <module>
from templateflow import __version__ as _tf_ver  File "/opt/conda/lib/python3.8/multiprocessing/forkserver.py", line 280, in main

  File "/opt/conda/lib/python3.8/site-packages/templateflow/__init__.py", line 19, in <module>
    from . import api
      File "/opt/conda/lib/python3.8/site-packages/templateflow/api.py", line 7, in <module>
from . import api
  File "/opt/conda/lib/python3.8/site-packages/templateflow/api.py", line 7, in <module>
        from .conf import TF_LAYOUT, TF_S3_ROOT, TF_USE_DATALAD, requires_layoutcode = _serve_one(child_r, fds,    

from .conf import TF_LAYOUT, TF_S3_ROOT, TF_USE_DATALAD, requires_layout
  File "/opt/conda/lib/python3.8/site-packages/templateflow/conf/__init__.py", line 53, in <module>
  File "/opt/conda/lib/python3.8/multiprocessing/forkserver.py", line 319, in _serve_one
  File "/opt/conda/lib/python3.8/site-packages/templateflow/conf/__init__.py", line 53, in <module>
        install(path=str(TF_HOME), source=TF_GITHUB_SOURCE, recursive=True)install(path=str(TF_HOME), source=TF_GITHUB_SOURCE, recursive=True)

  File "/opt/conda/lib/python3.8/site-packages/datalad/interface/utils.py", line 484, in eval_func
  File "/opt/conda/lib/python3.8/site-packages/datalad/interface/utils.py", line 484, in eval_func
    code = spawn._main(child_r, parent_sentinel)
  File "/opt/conda/lib/python3.8/multiprocessing/spawn.py", line 125, in _main
    prepare(preparation_data)
  File "/opt/conda/lib/python3.8/multiprocessing/spawn.py", line 236, in prepare
        return return_func(generator_func)(*args, **kwargs)return return_func(generator_func)(*args, **kwargs)

  File "/opt/conda/lib/python3.8/site-packages/datalad/interface/utils.py", line 476, in return_func
  File "/opt/conda/lib/python3.8/site-packages/datalad/interface/utils.py", line 476, in return_func
    _fixup_main_from_path(data['init_main_from_path'])
  File "/opt/conda/lib/python3.8/multiprocessing/spawn.py", line 287, in _fixup_main_from_path
    main_content = runpy.run_path(main_path,
          File "/opt/conda/lib/python3.8/runpy.py", line 265, in run_path
results = list(results)results = list(results)

  File "/opt/conda/lib/python3.8/site-packages/datalad/interface/utils.py", line 396, in generator_func
  File "/opt/conda/lib/python3.8/site-packages/datalad/interface/utils.py", line 396, in generator_func
    return _run_module_code(code, init_globals, run_name,
  File "/opt/conda/lib/python3.8/runpy.py", line 97, in _run_module_code
        for r in _process_results(for r in _process_results(

  File "/opt/conda/lib/python3.8/site-packages/datalad/interface/utils.py", line 579, in _process_results
      File "/opt/conda/lib/python3.8/site-packages/datalad/interface/utils.py", line 579, in _process_results
_run_code(code, mod_globals, init_globals,
  File "/opt/conda/lib/python3.8/runpy.py", line 87, in _run_code
    exec(code, run_globals)
  File "/opt/conda/bin/fmriprep", line 5, in <module>
        from fmriprep.cli.run import main    for res in results:
for res in results:

  File "/opt/conda/lib/python3.8/site-packages/fmriprep/cli/run.py", line 25, in <module>
  File "/opt/conda/lib/python3.8/site-packages/datalad/distribution/install.py", line 365, in __call__
  File "/opt/conda/lib/python3.8/site-packages/datalad/distribution/install.py", line 365, in __call__
    from .. import config
  File "/opt/conda/lib/python3.8/site-packages/fmriprep/config.py", line 116, in <module>
        for r in res:for r in res:

  File "/opt/conda/lib/python3.8/site-packages/datalad/interface/utils.py", line 396, in generator_func
  File "/opt/conda/lib/python3.8/site-packages/datalad/interface/utils.py", line 396, in generator_func
    from templateflow import __version__ as _tf_ver
  File "/opt/conda/lib/python3.8/site-packages/templateflow/__init__.py", line 19, in <module>
        from . import apifor r in _process_results(

  File "/opt/conda/lib/python3.8/site-packages/templateflow/api.py", line 7, in <module>
  File "/opt/conda/lib/python3.8/site-packages/datalad/interface/utils.py", line 579, in _process_results
    for r in _process_results(
      File "/opt/conda/lib/python3.8/site-packages/datalad/interface/utils.py", line 579, in _process_results
from .conf import TF_LAYOUT, TF_S3_ROOT, TF_USE_DATALAD, requires_layout
  File "/opt/conda/lib/python3.8/site-packages/templateflow/conf/__init__.py", line 53, in <module>
    install(path=str(TF_HOME), source=TF_GITHUB_SOURCE, recursive=True)
  File "/opt/conda/lib/python3.8/site-packages/datalad/interface/utils.py", line 484, in eval_func
    for res in results:
  File "/opt/conda/lib/python3.8/site-packages/datalad/core/distributed/clone.py", line 320, in __call__
    for res in results:
  File "/opt/conda/lib/python3.8/site-packages/datalad/core/distributed/clone.py", line 320, in __call__
        yield from clone_dataset(return return_func(generator_func)(*args, **kwargs)

  File "/opt/conda/lib/python3.8/site-packages/datalad/core/distributed/clone.py", line 609, in clone_dataset
  File "/opt/conda/lib/python3.8/site-packages/datalad/interface/utils.py", line 476, in return_func
    yield from clone_dataset(
  File "/opt/conda/lib/python3.8/site-packages/datalad/core/distributed/clone.py", line 609, in clone_dataset
    results = list(results)
  File "/opt/conda/lib/python3.8/site-packages/datalad/interface/utils.py", line 396, in generator_func
    rmtree(str(dest_path), children_only=dest_path_existed)
  File "/opt/conda/lib/python3.8/site-packages/datalad/utils.py", line 471, in rmtree
    rmtree(str(dest_path), children_only=dest_path_existed)
  File "/opt/conda/lib/python3.8/site-packages/datalad/utils.py", line 471, in rmtree
    for r in _process_results(
  File "/opt/conda/lib/python3.8/site-packages/datalad/interface/utils.py", line 579, in _process_results
    rotree(path, ro=False, chmod_files=chmod_files)
  File "/opt/conda/lib/python3.8/site-packages/datalad/utils.py", line 435, in rotree
    rotree(path, ro=False, chmod_files=chmod_files)
  File "/opt/conda/lib/python3.8/site-packages/datalad/utils.py", line 435, in rotree
    for res in results:
  File "/opt/conda/lib/python3.8/site-packages/datalad/distribution/install.py", line 365, in __call__
    chmod(root)
  File "/opt/conda/lib/python3.8/site-packages/datalad/utils.py", line 426, in <lambda>
    chmod(root)
  File "/opt/conda/lib/python3.8/site-packages/datalad/utils.py", line 426, in <lambda>
    for r in res:
  File "/opt/conda/lib/python3.8/site-packages/datalad/interface/utils.py", line 396, in generator_func
    chmod = lambda f: os.chmod(f, os.stat(f).st_mode | stat.S_IWRITE | stat.S_IREAD)
FileNotFoundError    : chmod = lambda f: os.chmod(f, os.stat(f).st_mode | stat.S_IWRITE | stat.S_IREAD)
[Errno 2] No such file or directory: '/scratch1/03201/jbwexler/work_dir/fmriprep/ds000117_sub-03/fmriprep_wf/single_subject_03_wf/func_preproc_ses_mri_task_facerecognition_run_08_wf/unwarp_wf/resample/sourcedata/templateflow/.git/refs/tags'FileNotFoundError
:     [Errno 2] No such file or directory: '/scratch1/03201/jbwexler/work_dir/fmriprep/ds000117_sub-03/fmriprep_wf/single_subject_03_wf/func_preproc_ses_mri_task_facerecognition_run_08_wf/unwarp_wf/resample/sourcedata/templateflow/.git/refs/tags'for r in _process_results(

  File "/opt/conda/lib/python3.8/site-packages/datalad/interface/utils.py", line 579, in _process_results
    for res in results:
  File "/opt/conda/lib/python3.8/site-packages/datalad/core/distributed/clone.py", line 320, in __call__
    yield from clone_dataset(
  File "/opt/conda/lib/python3.8/site-packages/datalad/core/distributed/clone.py", line 609, in clone_dataset
    rmtree(str(dest_path), children_only=dest_path_existed)
  File "/opt/conda/lib/python3.8/site-packages/datalad/utils.py", line 471, in rmtree
    rotree(path, ro=False, chmod_files=chmod_files)
  File "/opt/conda/lib/python3.8/site-packages/datalad/utils.py", line 435, in rotree
    chmod(root)
  File "/opt/conda/lib/python3.8/site-packages/datalad/utils.py", line 426, in <lambda>
    chmod = lambda f: os.chmod(f, os.stat(f).st_mode | stat.S_IWRITE | stat.S_IREAD)
FileNotFoundError: [Errno 2] No such file or directory: '/scratch1/03201/jbwexler/work_dir/fmriprep/ds000117_sub-03/fmriprep_wf/single_subject_03_wf/func_preproc_ses_mri_task_facerecognition_run_08_wf/unwarp_wf/resample/sourcedata/templateflow/.git/refs/heads'
[INFO] Cloning dataset to Dataset(/scratch1/03201/jbwexler/work_dir/fmriprep/ds000117_sub-03/fmriprep_wf/single_subject_03_wf/func_preproc_ses_mri_task_facerecognition_run_09_wf/unwarp_wf/resample/sourcedata/templateflow) 
[INFO] Attempting to clone from https://github.com/templateflow/templateflow.git to /scratch1/03201/jbwexler/work_dir/fmriprep/ds000117_sub-03/fmriprep_wf/single_subject_03_wf/func_preproc_ses_mri_task_facerecognition_run_09_wf/unwarp_wf/resample/sourcedata/templateflow 
[INFO] Cloning dataset to Dataset(/scratch1/03201/jbwexler/work_dir/fmriprep/ds000117_sub-03/fmriprep_wf/single_subject_03_wf/func_preproc_ses_mri_task_facerecognition_run_09_wf/unwarp_wf/resample/sourcedata/templateflow) 
[INFO] Cloning dataset to Dataset(/scratch1/03201/jbwexler/work_dir/fmriprep/ds000117_sub-03/fmriprep_wf/single_subject_03_wf/func_preproc_ses_mri_task_facerecognition_run_09_wf/unwarp_wf/resample/sourcedata/templateflow) 
[INFO] Cloning dataset to Dataset(/scratch1/03201/jbwexler/work_dir/fmriprep/ds000117_sub-03/fmriprep_wf/single_subject_03_wf/func_preproc_ses_mri_task_facerecognition_run_09_wf/unwarp_wf/resample/sourcedata/templateflow) 
[INFO] Attempting to clone from https://github.com/templateflow/templateflow.git to /scratch1/03201/jbwexler/work_dir/fmriprep/ds000117_sub-03/fmriprep_wf/single_subject_03_wf/func_preproc_ses_mri_task_facerecognition_run_09_wf/unwarp_wf/resample/sourcedata/templateflow 
[INFO] Attempting to clone from https://github.com/templateflow/templateflow.git to /scratch1/03201/jbwexler/work_dir/fmriprep/ds000117_sub-03/fmriprep_wf/single_subject_03_wf/func_preproc_ses_mri_task_facerecognition_run_09_wf/unwarp_wf/resample/sourcedata/templateflow 
[INFO] Attempting to clone from https://github.com/templateflow/templateflow.git to /scratch1/03201/jbwexler/work_dir/fmriprep/ds000117_sub-03/fmriprep_wf/single_subject_03_wf/func_preproc_ses_mri_task_facerecognition_run_09_wf/unwarp_wf/resample/sourcedata/templateflow 
[INFO] Cloning dataset to Dataset(/scratch1/03201/jbwexler/work_dir/fmriprep/ds000117_sub-03/fmriprep_wf/single_subject_03_wf/func_preproc_ses_mri_task_facerecognition_run_09_wf/unwarp_wf/resample/sourcedata/templateflow) 
[INFO] Attempting to clone from https://github.com/templateflow/templateflow.git to /scratch1/03201/jbwexler/work_dir/fmriprep/ds000117_sub-03/fmriprep_wf/single_subject_03_wf/func_preproc_ses_mri_task_facerecognition_run_09_wf/unwarp_wf/resample/sourcedata/templateflow 
[INFO] Cloning dataset to Dataset(/scratch1/03201/jbwexler/work_dir/fmriprep/ds000117_sub-03/fmriprep_wf/single_subject_03_wf/func_preproc_ses_mri_task_facerecognition_run_09_wf/unwarp_wf/resample/sourcedata/templateflow) 
[INFO] Attempting to clone from https://github.com/templateflow/templateflow.git to /scratch1/03201/jbwexler/work_dir/fmriprep/ds000117_sub-03/fmriprep_wf/single_subject_03_wf/func_preproc_ses_mri_task_facerecognition_run_09_wf/unwarp_wf/resample/sourcedata/templateflow 
[INFO] Cloning dataset to Dataset(/scratch1/03201/jbwexler/work_dir/fmriprep/ds000117_sub-03/fmriprep_wf/single_subject_03_wf/func_preproc_ses_mri_task_facerecognition_run_09_wf/unwarp_wf/resample/sourcedata/templateflow) 
[INFO] Attempting to clone from https://github.com/templateflow/templateflow.git to /scratch1/03201/jbwexler/work_dir/fmriprep/ds000117_sub-03/fmriprep_wf/single_subject_03_wf/func_preproc_ses_mri_task_facerecognition_run_09_wf/unwarp_wf/resample/sourcedata/templateflow 
[INFO] Completed clone attempts for Dataset(/scratch1/03201/jbwexler/work_dir/fmriprep/ds000117_sub-03/fmriprep_wf/single_subject_03_wf/func_preproc_ses_mri_task_facerecognition_run_09_wf/unwarp_wf/resample/sourcedata/templateflow) 
Traceback (most recent call last):
  File "/opt/conda/lib/python3.8/multiprocessing/forkserver.py", line 280, in main
    code = _serve_one(child_r, fds,
  File "/opt/conda/lib/python3.8/multiprocessing/forkserver.py", line 319, in _serve_one
    code = spawn._main(child_r, parent_sentinel)
  File "/opt/conda/lib/python3.8/multiprocessing/spawn.py", line 125, in _main
    prepare(preparation_data)
  File "/opt/conda/lib/python3.8/multiprocessing/spawn.py", line 236, in prepare
    _fixup_main_from_path(data['init_main_from_path'])
  File "/opt/conda/lib/python3.8/multiprocessing/spawn.py", line 287, in _fixup_main_from_path
    main_content = runpy.run_path(main_path,
  File "/opt/conda/lib/python3.8/runpy.py", line 265, in run_path
    return _run_module_code(code, init_globals, run_name,
  File "/opt/conda/lib/python3.8/runpy.py", line 97, in _run_module_code
    _run_code(code, mod_globals, init_globals,
  File "/opt/conda/lib/python3.8/runpy.py", line 87, in _run_code
    exec(code, run_globals)
  File "/opt/conda/bin/fmriprep", line 5, in <module>
    from fmriprep.cli.run import main
  File "/opt/conda/lib/python3.8/site-packages/fmriprep/cli/run.py", line 25, in <module>
    from .. import config
  File "/opt/conda/lib/python3.8/site-packages/fmriprep/config.py", line 116, in <module>
    from templateflow import __version__ as _tf_ver
  File "/opt/conda/lib/python3.8/site-packages/templateflow/__init__.py", line 19, in <module>
    from . import api
  File "/opt/conda/lib/python3.8/site-packages/templateflow/api.py", line 7, in <module>
    from .conf import TF_LAYOUT, TF_S3_ROOT, TF_USE_DATALAD, requires_layout
  File "/opt/conda/lib/python3.8/site-packages/templateflow/conf/__init__.py", line 53, in <module>
    install(path=str(TF_HOME), source=TF_GITHUB_SOURCE, recursive=True)
  File "/opt/conda/lib/python3.8/site-packages/datalad/interface/utils.py", line 484, in eval_func
    return return_func(generator_func)(*args, **kwargs)
  File "/opt/conda/lib/python3.8/site-packages/datalad/interface/utils.py", line 476, in return_func
    results = list(results)
  File "/opt/conda/lib/python3.8/site-packages/datalad/interface/utils.py", line 396, in generator_func
    for r in _process_results(
  File "/opt/conda/lib/python3.8/site-packages/datalad/interface/utils.py", line 579, in _process_results
    for res in results:
  File "/opt/conda/lib/python3.8/site-packages/datalad/distribution/install.py", line 381, in __call__
    for r in destination_dataset.get(
  File "/opt/conda/lib/python3.8/site-packages/datalad/interface/utils.py", line 396, in generator_func
    for r in _process_results(
  File "/opt/conda/lib/python3.8/site-packages/datalad/interface/utils.py", line 579, in _process_results
    for res in results:
  File "/opt/conda/lib/python3.8/site-packages/datalad/distribution/get.py", line 849, in __call__
    refds = require_dataset(
  File "/opt/conda/lib/python3.8/site-packages/datalad/distribution/dataset.py", line 567, in require_dataset
    raise ValueError(u"No installed dataset found at "
ValueError: No installed dataset found at /scratch1/03201/jbwexler/work_dir/fmriprep/ds000117_sub-03/fmriprep_wf/single_subject_03_wf/func_preproc_ses_mri_task_facerecognition_run_09_wf/unwarp_wf/resample/sourcedata/templateflow.
