[INFO] Cloning dataset to Dataset(/scratch1/03201/jbwexler/work_dir/fmriprep/ds000117_sub-10/fmriprep_wf/single_subject_10_wf/func_preproc_ses_mri_task_facerecognition_run_01_wf/unwarp_wf/resample/sourcedata/templateflow) 
[INFO] Attempting to clone from https://github.com/templateflow/templateflow.git to /scratch1/03201/jbwexler/work_dir/fmriprep/ds000117_sub-10/fmriprep_wf/single_subject_10_wf/func_preproc_ses_mri_task_facerecognition_run_01_wf/unwarp_wf/resample/sourcedata/templateflow 
[INFO] Cloning dataset to Dataset(/scratch1/03201/jbwexler/work_dir/fmriprep/ds000117_sub-10/fmriprep_wf/single_subject_10_wf/func_preproc_ses_mri_task_facerecognition_run_01_wf/unwarp_wf/resample/sourcedata/templateflow) 
[INFO] Attempting to clone from https://github.com/templateflow/templateflow.git to /scratch1/03201/jbwexler/work_dir/fmriprep/ds000117_sub-10/fmriprep_wf/single_subject_10_wf/func_preproc_ses_mri_task_facerecognition_run_01_wf/unwarp_wf/resample/sourcedata/templateflow 
Traceback (most recent call last):
  File "/opt/conda/lib/python3.8/multiprocessing/forkserver.py", line 280, in main
    code = _serve_one(child_r, fds,
  File "/opt/conda/lib/python3.8/multiprocessing/forkserver.py", line 319, in _serve_one
    code = spawn._main(child_r, parent_sentinel)
  File "/opt/conda/lib/python3.8/multiprocessing/spawn.py", line 125, in _main
    prepare(preparation_data)
  File "/opt/conda/lib/python3.8/multiprocessing/spawn.py", line 236, in prepare
    _fixup_main_from_path(data['init_main_from_path'])
  File "/opt/conda/lib/python3.8/multiprocessing/spawn.py", line 287, in _fixup_main_from_path
    main_content = runpy.run_path(main_path,
  File "/opt/conda/lib/python3.8/runpy.py", line 265, in run_path
    return _run_module_code(code, init_globals, run_name,
  File "/opt/conda/lib/python3.8/runpy.py", line 97, in _run_module_code
    Traceback (most recent call last):
_run_code(code, mod_globals, init_globals,
  File "/opt/conda/lib/python3.8/runpy.py", line 87, in _run_code
  File "/opt/conda/lib/python3.8/multiprocessing/forkserver.py", line 280, in main
    exec(code, run_globals)
  File "/opt/conda/bin/fmriprep", line 5, in <module>
    from fmriprep.cli.run import main
  File "/opt/conda/lib/python3.8/site-packages/fmriprep/cli/run.py", line 25, in <module>
    from .. import config
  File "/opt/conda/lib/python3.8/site-packages/fmriprep/config.py", line 116, in <module>
    code = _serve_one(child_r, fds,
  File "/opt/conda/lib/python3.8/multiprocessing/forkserver.py", line 319, in _serve_one
    from templateflow import __version__ as _tf_ver
  File "/opt/conda/lib/python3.8/site-packages/templateflow/__init__.py", line 19, in <module>
    code = spawn._main(child_r, parent_sentinel)
      File "/opt/conda/lib/python3.8/multiprocessing/spawn.py", line 125, in _main
from . import api
  File "/opt/conda/lib/python3.8/site-packages/templateflow/api.py", line 7, in <module>
        from .conf import TF_LAYOUT, TF_S3_ROOT, TF_USE_DATALAD, requires_layout
prepare(preparation_data)
  File "/opt/conda/lib/python3.8/site-packages/templateflow/conf/__init__.py", line 53, in <module>
  File "/opt/conda/lib/python3.8/multiprocessing/spawn.py", line 236, in prepare
    install(path=str(TF_HOME), source=TF_GITHUB_SOURCE, recursive=True)
  File "/opt/conda/lib/python3.8/site-packages/datalad/interface/utils.py", line 484, in eval_func
    _fixup_main_from_path(data['init_main_from_path'])
  File "/opt/conda/lib/python3.8/multiprocessing/spawn.py", line 287, in _fixup_main_from_path
    main_content = runpy.run_path(main_path,
  File "/opt/conda/lib/python3.8/runpy.py", line 265, in run_path
    return return_func(generator_func)(*args, **kwargs)
  File "/opt/conda/lib/python3.8/site-packages/datalad/interface/utils.py", line 476, in return_func
    return _run_module_code(code, init_globals, run_name,
  File "/opt/conda/lib/python3.8/runpy.py", line 97, in _run_module_code
    results = list(results)    
_run_code(code, mod_globals, init_globals,
  File "/opt/conda/lib/python3.8/site-packages/datalad/interface/utils.py", line 396, in generator_func
  File "/opt/conda/lib/python3.8/runpy.py", line 87, in _run_code
    exec(code, run_globals)
  File "/opt/conda/bin/fmriprep", line 5, in <module>
        from fmriprep.cli.run import mainfor r in _process_results(

  File "/opt/conda/lib/python3.8/site-packages/fmriprep/cli/run.py", line 25, in <module>
  File "/opt/conda/lib/python3.8/site-packages/datalad/interface/utils.py", line 579, in _process_results
    from .. import config
  File "/opt/conda/lib/python3.8/site-packages/fmriprep/config.py", line 116, in <module>
    for res in results:
  File "/opt/conda/lib/python3.8/site-packages/datalad/distribution/install.py", line 381, in __call__
    from templateflow import __version__ as _tf_ver
  File "/opt/conda/lib/python3.8/site-packages/templateflow/__init__.py", line 19, in <module>
    from . import api
  File "/opt/conda/lib/python3.8/site-packages/templateflow/api.py", line 7, in <module>
        for r in destination_dataset.get(
from .conf import TF_LAYOUT, TF_S3_ROOT, TF_USE_DATALAD, requires_layout
  File "/opt/conda/lib/python3.8/site-packages/datalad/interface/utils.py", line 396, in generator_func
  File "/opt/conda/lib/python3.8/site-packages/templateflow/conf/__init__.py", line 53, in <module>
    install(path=str(TF_HOME), source=TF_GITHUB_SOURCE, recursive=True)
  File "/opt/conda/lib/python3.8/site-packages/datalad/interface/utils.py", line 484, in eval_func
    for r in _process_results(
  File "/opt/conda/lib/python3.8/site-packages/datalad/interface/utils.py", line 579, in _process_results
    return return_func(generator_func)(*args, **kwargs)
  File "/opt/conda/lib/python3.8/site-packages/datalad/interface/utils.py", line 476, in return_func
    for res in results:
  File "/opt/conda/lib/python3.8/site-packages/datalad/distribution/get.py", line 849, in __call__
    results = list(results)
  File "/opt/conda/lib/python3.8/site-packages/datalad/interface/utils.py", line 396, in generator_func
        for r in _process_results(
refds = require_dataset(
  File "/opt/conda/lib/python3.8/site-packages/datalad/interface/utils.py", line 579, in _process_results
  File "/opt/conda/lib/python3.8/site-packages/datalad/distribution/dataset.py", line 567, in require_dataset
        for res in results:
raise ValueError(u"No installed dataset found at "
  File "/opt/conda/lib/python3.8/site-packages/datalad/distribution/install.py", line 381, in __call__
ValueError: No installed dataset found at /scratch1/03201/jbwexler/work_dir/fmriprep/ds000117_sub-10/fmriprep_wf/single_subject_10_wf/func_preproc_ses_mri_task_facerecognition_run_01_wf/unwarp_wf/resample/sourcedata/templateflow.
Traceback (most recent call last):
  File "/opt/conda/lib/python3.8/multiprocessing/forkserver.py", line 280, in main
    for r in destination_dataset.get(
  File "/opt/conda/lib/python3.8/site-packages/datalad/interface/utils.py", line 396, in generator_func
    for r in _process_results(
  File "/opt/conda/lib/python3.8/site-packages/datalad/interface/utils.py", line 579, in _process_results
    code = _serve_one(child_r, fds,
  File "/opt/conda/lib/python3.8/multiprocessing/forkserver.py", line 319, in _serve_one
    for res in results:
  File "/opt/conda/lib/python3.8/site-packages/datalad/distribution/get.py", line 849, in __call__
    code = spawn._main(child_r, parent_sentinel)
  File "/opt/conda/lib/python3.8/multiprocessing/spawn.py", line 125, in _main
    prepare(preparation_data)
  File "/opt/conda/lib/python3.8/multiprocessing/spawn.py", line 236, in prepare
    refds = require_dataset(    
_fixup_main_from_path(data['init_main_from_path'])  File "/opt/conda/lib/python3.8/site-packages/datalad/distribution/dataset.py", line 567, in require_dataset

  File "/opt/conda/lib/python3.8/multiprocessing/spawn.py", line 287, in _fixup_main_from_path
    main_content = runpy.run_path(main_path,
  File "/opt/conda/lib/python3.8/runpy.py", line 265, in run_path
    raise ValueError(u"No installed dataset found at "
ValueError: No installed dataset found at /scratch1/03201/jbwexler/work_dir/fmriprep/ds000117_sub-10/fmriprep_wf/single_subject_10_wf/func_preproc_ses_mri_task_facerecognition_run_01_wf/unwarp_wf/resample/sourcedata/templateflow.    
return _run_module_code(code, init_globals, run_name,
  File "/opt/conda/lib/python3.8/runpy.py", line 97, in _run_module_code
    _run_code(code, mod_globals, init_globals,
  File "/opt/conda/lib/python3.8/runpy.py", line 87, in _run_code
    exec(code, run_globals)
  File "/opt/conda/bin/fmriprep", line 5, in <module>
    from fmriprep.cli.run import main
  File "/opt/conda/lib/python3.8/site-packages/fmriprep/cli/run.py", line 25, in <module>
    from .. import config
  File "/opt/conda/lib/python3.8/site-packages/fmriprep/config.py", line 116, in <module>
    from templateflow import __version__ as _tf_ver
  File "/opt/conda/lib/python3.8/site-packages/templateflow/__init__.py", line 19, in <module>
    from . import api
  File "/opt/conda/lib/python3.8/site-packages/templateflow/api.py", line 7, in <module>
    from .conf import TF_LAYOUT, TF_S3_ROOT, TF_USE_DATALAD, requires_layout
  File "/opt/conda/lib/python3.8/site-packages/templateflow/conf/__init__.py", line 53, in <module>
    install(path=str(TF_HOME), source=TF_GITHUB_SOURCE, recursive=True)
  File "/opt/conda/lib/python3.8/site-packages/datalad/interface/utils.py", line 484, in eval_func
    return return_func(generator_func)(*args, **kwargs)
  File "/opt/conda/lib/python3.8/site-packages/datalad/interface/utils.py", line 476, in return_func
    results = list(results)
  File "/opt/conda/lib/python3.8/site-packages/datalad/interface/utils.py", line 396, in generator_func
    for r in _process_results(
  File "/opt/conda/lib/python3.8/site-packages/datalad/interface/utils.py", line 579, in _process_results
    for res in results:
  File "/opt/conda/lib/python3.8/site-packages/datalad/distribution/install.py", line 381, in __call__
    for r in destination_dataset.get(
  File "/opt/conda/lib/python3.8/site-packages/datalad/interface/utils.py", line 396, in generator_func
    for r in _process_results(
  File "/opt/conda/lib/python3.8/site-packages/datalad/interface/utils.py", line 579, in _process_results
    for res in results:
  File "/opt/conda/lib/python3.8/site-packages/datalad/distribution/get.py", line 849, in __call__
    refds = require_dataset(
  File "/opt/conda/lib/python3.8/site-packages/datalad/distribution/dataset.py", line 567, in require_dataset
    raise ValueError(u"No installed dataset found at "
ValueError: No installed dataset found at /scratch1/03201/jbwexler/work_dir/fmriprep/ds000117_sub-10/fmriprep_wf/single_subject_10_wf/func_preproc_ses_mri_task_facerecognition_run_01_wf/unwarp_wf/resample/sourcedata/templateflow.
[INFO] Cloning dataset to Dataset(/scratch1/03201/jbwexler/work_dir/fmriprep/ds000117_sub-10/fmriprep_wf/single_subject_10_wf/func_preproc_ses_mri_task_facerecognition_run_02_wf/unwarp_wf/resample/sourcedata/templateflow) 
[INFO] Attempting to clone from https://github.com/templateflow/templateflow.git to /scratch1/03201/jbwexler/work_dir/fmriprep/ds000117_sub-10/fmriprep_wf/single_subject_10_wf/func_preproc_ses_mri_task_facerecognition_run_02_wf/unwarp_wf/resample/sourcedata/templateflow 
[INFO] Cloning dataset to Dataset(/scratch1/03201/jbwexler/work_dir/fmriprep/ds000117_sub-10/fmriprep_wf/single_subject_10_wf/func_preproc_ses_mri_task_facerecognition_run_02_wf/unwarp_wf/resample/sourcedata/templateflow) 
[INFO] Attempting to clone from https://github.com/templateflow/templateflow.git to /scratch1/03201/jbwexler/work_dir/fmriprep/ds000117_sub-10/fmriprep_wf/single_subject_10_wf/func_preproc_ses_mri_task_facerecognition_run_02_wf/unwarp_wf/resample/sourcedata/templateflow 
[INFO] Cloning dataset to Dataset(/scratch1/03201/jbwexler/work_dir/fmriprep/ds000117_sub-10/fmriprep_wf/single_subject_10_wf/func_preproc_ses_mri_task_facerecognition_run_02_wf/unwarp_wf/resample/sourcedata/templateflow) 
[INFO] Attempting to clone from https://github.com/templateflow/templateflow.git to /scratch1/03201/jbwexler/work_dir/fmriprep/ds000117_sub-10/fmriprep_wf/single_subject_10_wf/func_preproc_ses_mri_task_facerecognition_run_02_wf/unwarp_wf/resample/sourcedata/templateflow 
Traceback (most recent call last):
Traceback (most recent call last):
  File "/opt/conda/lib/python3.8/multiprocessing/forkserver.py", line 280, in main
  File "/opt/conda/lib/python3.8/multiprocessing/forkserver.py", line 280, in main
        code = _serve_one(child_r, fds,code = _serve_one(child_r, fds,

  File "/opt/conda/lib/python3.8/multiprocessing/forkserver.py", line 319, in _serve_one
  File "/opt/conda/lib/python3.8/multiprocessing/forkserver.py", line 319, in _serve_one
        code = spawn._main(child_r, parent_sentinel)code = spawn._main(child_r, parent_sentinel)

  File "/opt/conda/lib/python3.8/multiprocessing/spawn.py", line 125, in _main
  File "/opt/conda/lib/python3.8/multiprocessing/spawn.py", line 125, in _main
        prepare(preparation_data)prepare(preparation_data)

  File "/opt/conda/lib/python3.8/multiprocessing/spawn.py", line 236, in prepare
  File "/opt/conda/lib/python3.8/multiprocessing/spawn.py", line 236, in prepare
        _fixup_main_from_path(data['init_main_from_path'])_fixup_main_from_path(data['init_main_from_path'])

  File "/opt/conda/lib/python3.8/multiprocessing/spawn.py", line 287, in _fixup_main_from_path
  File "/opt/conda/lib/python3.8/multiprocessing/spawn.py", line 287, in _fixup_main_from_path
        main_content = runpy.run_path(main_path,main_content = runpy.run_path(main_path,

  File "/opt/conda/lib/python3.8/runpy.py", line 265, in run_path
  File "/opt/conda/lib/python3.8/runpy.py", line 265, in run_path
        return _run_module_code(code, init_globals, run_name,return _run_module_code(code, init_globals, run_name,

  File "/opt/conda/lib/python3.8/runpy.py", line 97, in _run_module_code
  File "/opt/conda/lib/python3.8/runpy.py", line 97, in _run_module_code
        _run_code(code, mod_globals, init_globals,_run_code(code, mod_globals, init_globals,

  File "/opt/conda/lib/python3.8/runpy.py", line 87, in _run_code
  File "/opt/conda/lib/python3.8/runpy.py", line 87, in _run_code
        exec(code, run_globals)exec(code, run_globals)

  File "/opt/conda/bin/fmriprep", line 5, in <module>
  File "/opt/conda/bin/fmriprep", line 5, in <module>
        from fmriprep.cli.run import mainfrom fmriprep.cli.run import main

  File "/opt/conda/lib/python3.8/site-packages/fmriprep/cli/run.py", line 25, in <module>
  File "/opt/conda/lib/python3.8/site-packages/fmriprep/cli/run.py", line 25, in <module>
        from .. import configfrom .. import config

  File "/opt/conda/lib/python3.8/site-packages/fmriprep/config.py", line 116, in <module>
  File "/opt/conda/lib/python3.8/site-packages/fmriprep/config.py", line 116, in <module>
        from templateflow import __version__ as _tf_verfrom templateflow import __version__ as _tf_ver

  File "/opt/conda/lib/python3.8/site-packages/templateflow/__init__.py", line 19, in <module>
  File "/opt/conda/lib/python3.8/site-packages/templateflow/__init__.py", line 19, in <module>
        from . import apifrom . import api

  File "/opt/conda/lib/python3.8/site-packages/templateflow/api.py", line 7, in <module>
  File "/opt/conda/lib/python3.8/site-packages/templateflow/api.py", line 7, in <module>
        from .conf import TF_LAYOUT, TF_S3_ROOT, TF_USE_DATALAD, requires_layoutfrom .conf import TF_LAYOUT, TF_S3_ROOT, TF_USE_DATALAD, requires_layout

  File "/opt/conda/lib/python3.8/site-packages/templateflow/conf/__init__.py", line 53, in <module>
  File "/opt/conda/lib/python3.8/site-packages/templateflow/conf/__init__.py", line 53, in <module>
        install(path=str(TF_HOME), source=TF_GITHUB_SOURCE, recursive=True)install(path=str(TF_HOME), source=TF_GITHUB_SOURCE, recursive=True)

  File "/opt/conda/lib/python3.8/site-packages/datalad/interface/utils.py", line 484, in eval_func
  File "/opt/conda/lib/python3.8/site-packages/datalad/interface/utils.py", line 484, in eval_func
        return return_func(generator_func)(*args, **kwargs)
return return_func(generator_func)(*args, **kwargs)
  File "/opt/conda/lib/python3.8/site-packages/datalad/interface/utils.py", line 476, in return_func
  File "/opt/conda/lib/python3.8/site-packages/datalad/interface/utils.py", line 476, in return_func
    results = list(results)    
results = list(results)
  File "/opt/conda/lib/python3.8/site-packages/datalad/interface/utils.py", line 396, in generator_func
  File "/opt/conda/lib/python3.8/site-packages/datalad/interface/utils.py", line 396, in generator_func
    for r in _process_results(
      File "/opt/conda/lib/python3.8/site-packages/datalad/interface/utils.py", line 579, in _process_results
for r in _process_results(
  File "/opt/conda/lib/python3.8/site-packages/datalad/interface/utils.py", line 579, in _process_results
    for res in results:
      File "/opt/conda/lib/python3.8/site-packages/datalad/distribution/install.py", line 381, in __call__
for res in results:
  File "/opt/conda/lib/python3.8/site-packages/datalad/distribution/install.py", line 381, in __call__
    for r in destination_dataset.get(
      File "/opt/conda/lib/python3.8/site-packages/datalad/distribution/dataset.py", line 484, in apply_func
for r in destination_dataset.get(
  File "/opt/conda/lib/python3.8/site-packages/datalad/interface/utils.py", line 396, in generator_func
    for r in _process_results(    
return f(**kwargs)
  File "/opt/conda/lib/python3.8/site-packages/datalad/interface/utils.py", line 579, in _process_results
  File "/opt/conda/lib/python3.8/site-packages/datalad/interface/utils.py", line 375, in eval_func
    hooks = get_jsonhooks_from_config(ds.config if ds else dlcfg)
      File "/opt/conda/lib/python3.8/site-packages/datalad/distribution/dataset.py", line 325, in config
for res in results:
  File "/opt/conda/lib/python3.8/site-packages/datalad/distribution/get.py", line 855, in __call__
    repo = self.repo
  File "/opt/conda/lib/python3.8/site-packages/datalad/distribution/dataset.py", line 271, in repo
    self._repo = repo_from_path(self._path)
  File "/opt/conda/lib/python3.8/site-packages/datalad/core/local/repo.py", line 56, in repo_from_path
    for sdsres in Subdatasets.__call__(
  File "/opt/conda/lib/python3.8/site-packages/datalad/interface/utils.py", line 375, in eval_func
    hooks = get_jsonhooks_from_config(ds.config if ds else dlcfg)
  File "/opt/conda/lib/python3.8/site-packages/datalad/distribution/dataset.py", line 325, in config
    repo = self.repo
  File "/opt/conda/lib/python3.8/site-packages/datalad/distribution/dataset.py", line 259, in repo
    self._repo.is_with_annex():
  File "/opt/conda/lib/python3.8/site-packages/datalad/support/gitrepo.py", line 1120, in is_with_annex
    return any(
  File "/opt/conda/lib/python3.8/site-packages/datalad/support/gitrepo.py", line 1120, in <genexpr>
    return any(
  File "/opt/conda/lib/python3.8/site-packages/datalad/dataset/gitrepo.py", line 503, in for_each_ref_
    if not cls.is_valid_repo(path, **ckw):
  File "/opt/conda/lib/python3.8/site-packages/datalad/support/annexrepo.py", line 670, in is_valid_repo
    for line in self.call_git_items_(cmd, read_only=True):
  File "/opt/conda/lib/python3.8/site-packages/datalad/dataset/gitrepo.py", line 343, in call_git_items_
    out, _ = self._call_git(args, files, expect_stderr=expect_stderr,
  File "/opt/conda/lib/python3.8/site-packages/datalad/dataset/gitrepo.py", line 259, in _call_git
    res = runner.run(
  File "/opt/conda/lib/python3.8/site-packages/datalad/runner/runner.py", line 145, in run
    raise CommandError(
datalad.runner.exception.CommandError: CommandError: 'git -c diff.ignoreSubmodules=none for-each-ref '--format=%(refname:strip=2)' refs/heads refs/remotes' failed with exitcode 128 under /scratch1/03201/jbwexler/work_dir/fmriprep/ds000117_sub-10/fmriprep_wf/single_subject_10_wf/func_preproc_ses_mri_task_facerecognition_run_02_wf/unwarp_wf/resample/sourcedata/templateflow [err: 'fatal: not a git repository (or any parent up to mount point /)
Stopping at filesystem boundary (GIT_DISCOVERY_ACROSS_FILESYSTEM not set).']
    return initialized_annex or GitRepo(path, create=False, init=False).is_with_annex()
  File "/opt/conda/lib/python3.8/site-packages/datalad/support/gitrepo.py", line 1120, in is_with_annex
    return any(
  File "/opt/conda/lib/python3.8/site-packages/datalad/support/gitrepo.py", line 1120, in <genexpr>
    return any(
  File "/opt/conda/lib/python3.8/site-packages/datalad/dataset/gitrepo.py", line 503, in for_each_ref_
    for line in self.call_git_items_(cmd, read_only=True):
  File "/opt/conda/lib/python3.8/site-packages/datalad/dataset/gitrepo.py", line 343, in call_git_items_
    out, _ = self._call_git(args, files, expect_stderr=expect_stderr,
  File "/opt/conda/lib/python3.8/site-packages/datalad/dataset/gitrepo.py", line 259, in _call_git
    res = runner.run(
  File "/opt/conda/lib/python3.8/site-packages/datalad/runner/runner.py", line 145, in run
    raise CommandError(
datalad.runner.exception.CommandError: CommandError: 'git -c diff.ignoreSubmodules=none for-each-ref '--format=%(refname:strip=2)' refs/heads refs/remotes' failed with exitcode 128 under /scratch1/03201/jbwexler/work_dir/fmriprep/ds000117_sub-10/fmriprep_wf/single_subject_10_wf/func_preproc_ses_mri_task_facerecognition_run_02_wf/unwarp_wf/resample/sourcedata/templateflow [err: 'fatal: not a git repository (or any parent up to mount point /)
Stopping at filesystem boundary (GIT_DISCOVERY_ACROSS_FILESYSTEM not set).']
[INFO] Cloning dataset to Dataset(/scratch1/03201/jbwexler/work_dir/fmriprep/ds000117_sub-10/fmriprep_wf/single_subject_10_wf/func_preproc_ses_mri_task_facerecognition_run_03_wf/unwarp_wf/resample/sourcedata/templateflow) 
[INFO] Attempting to clone from https://github.com/templateflow/templateflow.git to /scratch1/03201/jbwexler/work_dir/fmriprep/ds000117_sub-10/fmriprep_wf/single_subject_10_wf/func_preproc_ses_mri_task_facerecognition_run_03_wf/unwarp_wf/resample/sourcedata/templateflow 
[INFO] Cloning dataset to Dataset(/scratch1/03201/jbwexler/work_dir/fmriprep/ds000117_sub-10/fmriprep_wf/single_subject_10_wf/func_preproc_ses_mri_task_facerecognition_run_03_wf/unwarp_wf/resample/sourcedata/templateflow) 
[INFO] Cloning dataset to Dataset(/scratch1/03201/jbwexler/work_dir/fmriprep/ds000117_sub-10/fmriprep_wf/single_subject_10_wf/func_preproc_ses_mri_task_facerecognition_run_03_wf/unwarp_wf/resample/sourcedata/templateflow) 
[INFO] Attempting to clone from https://github.com/templateflow/templateflow.git to /scratch1/03201/jbwexler/work_dir/fmriprep/ds000117_sub-10/fmriprep_wf/single_subject_10_wf/func_preproc_ses_mri_task_facerecognition_run_03_wf/unwarp_wf/resample/sourcedata/templateflow 
[INFO] Attempting to clone from https://github.com/templateflow/templateflow.git to /scratch1/03201/jbwexler/work_dir/fmriprep/ds000117_sub-10/fmriprep_wf/single_subject_10_wf/func_preproc_ses_mri_task_facerecognition_run_03_wf/unwarp_wf/resample/sourcedata/templateflow 
Traceback (most recent call last):
  File "/opt/conda/lib/python3.8/multiprocessing/forkserver.py", line 280, in main
    code = _serve_one(child_r, fds,
  File "/opt/conda/lib/python3.8/multiprocessing/forkserver.py", line 319, in _serve_one
    code = spawn._main(child_r, parent_sentinel)
  File "/opt/conda/lib/python3.8/multiprocessing/spawn.py", line 125, in _main
    prepare(preparation_data)
  File "/opt/conda/lib/python3.8/multiprocessing/spawn.py", line 236, in prepare
    _fixup_main_from_path(data['init_main_from_path'])
  File "/opt/conda/lib/python3.8/multiprocessing/spawn.py", line 287, in _fixup_main_from_path
    main_content = runpy.run_path(main_path,
  File "/opt/conda/lib/python3.8/runpy.py", line 265, in run_path
    return _run_module_code(code, init_globals, run_name,
  File "/opt/conda/lib/python3.8/runpy.py", line 97, in _run_module_code
    _run_code(code, mod_globals, init_globals,
  File "/opt/conda/lib/python3.8/runpy.py", line 87, in _run_code
    exec(code, run_globals)
  File "/opt/conda/bin/fmriprep", line 5, in <module>
    from fmriprep.cli.run import main
  File "/opt/conda/lib/python3.8/site-packages/fmriprep/cli/run.py", line 25, in <module>
Traceback (most recent call last):
  File "/opt/conda/lib/python3.8/multiprocessing/forkserver.py", line 280, in main
    from .. import config
  File "/opt/conda/lib/python3.8/site-packages/fmriprep/config.py", line 116, in <module>
Traceback (most recent call last):
  File "/opt/conda/lib/python3.8/multiprocessing/forkserver.py", line 280, in main
    from templateflow import __version__ as _tf_ver
  File "/opt/conda/lib/python3.8/site-packages/templateflow/__init__.py", line 19, in <module>
    code = _serve_one(child_r, fds,
  File "/opt/conda/lib/python3.8/multiprocessing/forkserver.py", line 319, in _serve_one
    from . import api
  File "/opt/conda/lib/python3.8/site-packages/templateflow/api.py", line 7, in <module>
    from .conf import TF_LAYOUT, TF_S3_ROOT, TF_USE_DATALAD, requires_layout
  File "/opt/conda/lib/python3.8/site-packages/templateflow/conf/__init__.py", line 53, in <module>
    code = spawn._main(child_r, parent_sentinel)
  File "/opt/conda/lib/python3.8/multiprocessing/spawn.py", line 125, in _main
        install(path=str(TF_HOME), source=TF_GITHUB_SOURCE, recursive=True)code = _serve_one(child_r, fds,

  File "/opt/conda/lib/python3.8/site-packages/datalad/interface/utils.py", line 484, in eval_func
  File "/opt/conda/lib/python3.8/multiprocessing/forkserver.py", line 319, in _serve_one
    prepare(preparation_data)
  File "/opt/conda/lib/python3.8/multiprocessing/spawn.py", line 236, in prepare
        _fixup_main_from_path(data['init_main_from_path'])code = spawn._main(child_r, parent_sentinel)

  File "/opt/conda/lib/python3.8/multiprocessing/spawn.py", line 287, in _fixup_main_from_path
  File "/opt/conda/lib/python3.8/multiprocessing/spawn.py", line 125, in _main
    return return_func(generator_func)(*args, **kwargs)
  File "/opt/conda/lib/python3.8/site-packages/datalad/interface/utils.py", line 476, in return_func
    prepare(preparation_data)    
main_content = runpy.run_path(main_path,
  File "/opt/conda/lib/python3.8/multiprocessing/spawn.py", line 236, in prepare
  File "/opt/conda/lib/python3.8/runpy.py", line 265, in run_path
    results = list(results)    
_fixup_main_from_path(data['init_main_from_path'])  File "/opt/conda/lib/python3.8/site-packages/datalad/interface/utils.py", line 396, in generator_func

      File "/opt/conda/lib/python3.8/multiprocessing/spawn.py", line 287, in _fixup_main_from_path
return _run_module_code(code, init_globals, run_name,Traceback (most recent call last):

  File "/opt/conda/lib/python3.8/runpy.py", line 97, in _run_module_code
  File "/opt/conda/lib/python3.8/multiprocessing/forkserver.py", line 280, in main
        _run_code(code, mod_globals, init_globals,    
main_content = runpy.run_path(main_path,for r in _process_results(
  File "/opt/conda/lib/python3.8/runpy.py", line 87, in _run_code

  File "/opt/conda/lib/python3.8/runpy.py", line 265, in run_path
  File "/opt/conda/lib/python3.8/site-packages/datalad/interface/utils.py", line 579, in _process_results
    exec(code, run_globals)
  File "/opt/conda/bin/fmriprep", line 5, in <module>
        return _run_module_code(code, init_globals, run_name,
from fmriprep.cli.run import main
  File "/opt/conda/lib/python3.8/runpy.py", line 97, in _run_module_code
  File "/opt/conda/lib/python3.8/site-packages/fmriprep/cli/run.py", line 25, in <module>
    code = _serve_one(child_r, fds,    
for res in results:
  File "/opt/conda/lib/python3.8/multiprocessing/forkserver.py", line 319, in _serve_one
  File "/opt/conda/lib/python3.8/site-packages/datalad/distribution/install.py", line 381, in __call__
    _run_code(code, mod_globals, init_globals,    
from .. import config
  File "/opt/conda/lib/python3.8/runpy.py", line 87, in _run_code
  File "/opt/conda/lib/python3.8/site-packages/fmriprep/config.py", line 116, in <module>
    exec(code, run_globals)
      File "/opt/conda/bin/fmriprep", line 5, in <module>
code = spawn._main(child_r, parent_sentinel)
      File "/opt/conda/lib/python3.8/multiprocessing/spawn.py", line 125, in _main
for r in destination_dataset.get(    
    from templateflow import __version__ as _tf_ver
from fmriprep.cli.run import main  File "/opt/conda/lib/python3.8/site-packages/datalad/interface/utils.py", line 396, in generator_func

  File "/opt/conda/lib/python3.8/site-packages/templateflow/__init__.py", line 19, in <module>
      File "/opt/conda/lib/python3.8/site-packages/fmriprep/cli/run.py", line 25, in <module>
prepare(preparation_data)
  File "/opt/conda/lib/python3.8/multiprocessing/spawn.py", line 236, in prepare
    from . import api
      File "/opt/conda/lib/python3.8/site-packages/templateflow/api.py", line 7, in <module>
from .. import config
  File "/opt/conda/lib/python3.8/site-packages/fmriprep/config.py", line 116, in <module>
            _fixup_main_from_path(data['init_main_from_path'])for r in _process_results(from .conf import TF_LAYOUT, TF_S3_ROOT, TF_USE_DATALAD, requires_layout


  File "/opt/conda/lib/python3.8/multiprocessing/spawn.py", line 287, in _fixup_main_from_path
  File "/opt/conda/lib/python3.8/site-packages/datalad/interface/utils.py", line 579, in _process_results
  File "/opt/conda/lib/python3.8/site-packages/templateflow/conf/__init__.py", line 53, in <module>
    from templateflow import __version__ as _tf_ver
      File "/opt/conda/lib/python3.8/site-packages/templateflow/__init__.py", line 19, in <module>
install(path=str(TF_HOME), source=TF_GITHUB_SOURCE, recursive=True)
      File "/opt/conda/lib/python3.8/site-packages/datalad/interface/utils.py", line 484, in eval_func
main_content = runpy.run_path(main_path,
      File "/opt/conda/lib/python3.8/runpy.py", line 265, in run_path
from . import api
  File "/opt/conda/lib/python3.8/site-packages/templateflow/api.py", line 7, in <module>
    for res in results:
      File "/opt/conda/lib/python3.8/site-packages/datalad/distribution/get.py", line 849, in __call__
from .conf import TF_LAYOUT, TF_S3_ROOT, TF_USE_DATALAD, requires_layout
  File "/opt/conda/lib/python3.8/site-packages/templateflow/conf/__init__.py", line 53, in <module>
    return _run_module_code(code, init_globals, run_name,
  File "/opt/conda/lib/python3.8/runpy.py", line 97, in _run_module_code
    return return_func(generator_func)(*args, **kwargs)    
install(path=str(TF_HOME), source=TF_GITHUB_SOURCE, recursive=True)  File "/opt/conda/lib/python3.8/site-packages/datalad/interface/utils.py", line 476, in return_func

  File "/opt/conda/lib/python3.8/site-packages/datalad/interface/utils.py", line 484, in eval_func
    _run_code(code, mod_globals, init_globals,
  File "/opt/conda/lib/python3.8/runpy.py", line 87, in _run_code
    exec(code, run_globals)
  File "/opt/conda/bin/fmriprep", line 5, in <module>
        refds = require_dataset(results = list(results)

      File "/opt/conda/lib/python3.8/site-packages/datalad/distribution/dataset.py", line 567, in require_dataset
from fmriprep.cli.run import main  File "/opt/conda/lib/python3.8/site-packages/datalad/interface/utils.py", line 396, in generator_func
    
return return_func(generator_func)(*args, **kwargs)  File "/opt/conda/lib/python3.8/site-packages/fmriprep/cli/run.py", line 25, in <module>

  File "/opt/conda/lib/python3.8/site-packages/datalad/interface/utils.py", line 476, in return_func
    from .. import config
  File "/opt/conda/lib/python3.8/site-packages/fmriprep/config.py", line 116, in <module>
    for r in _process_results(
  File "/opt/conda/lib/python3.8/site-packages/datalad/interface/utils.py", line 579, in _process_results
        raise ValueError(u"No installed dataset found at "results = list(results)

    ValueError  File "/opt/conda/lib/python3.8/site-packages/datalad/interface/utils.py", line 396, in generator_func
from templateflow import __version__ as _tf_ver: 
No installed dataset found at /scratch1/03201/jbwexler/work_dir/fmriprep/ds000117_sub-10/fmriprep_wf/single_subject_10_wf/func_preproc_ses_mri_task_facerecognition_run_03_wf/unwarp_wf/resample/sourcedata/templateflow.  File "/opt/conda/lib/python3.8/site-packages/templateflow/__init__.py", line 19, in <module>

    from . import api    
for res in results:
  File "/opt/conda/lib/python3.8/site-packages/templateflow/api.py", line 7, in <module>
  File "/opt/conda/lib/python3.8/site-packages/datalad/distribution/install.py", line 381, in __call__
        for r in _process_results(from .conf import TF_LAYOUT, TF_S3_ROOT, TF_USE_DATALAD, requires_layout

  File "/opt/conda/lib/python3.8/site-packages/datalad/interface/utils.py", line 579, in _process_results
  File "/opt/conda/lib/python3.8/site-packages/templateflow/conf/__init__.py", line 53, in <module>
    install(path=str(TF_HOME), source=TF_GITHUB_SOURCE, recursive=True)
  File "/opt/conda/lib/python3.8/site-packages/datalad/interface/utils.py", line 484, in eval_func
    for r in destination_dataset.get(
  File "/opt/conda/lib/python3.8/site-packages/datalad/interface/utils.py", line 396, in generator_func
    for res in results:
  File "/opt/conda/lib/python3.8/site-packages/datalad/distribution/install.py", line 381, in __call__
    return return_func(generator_func)(*args, **kwargs)
      File "/opt/conda/lib/python3.8/site-packages/datalad/interface/utils.py", line 476, in return_func
for r in _process_results(
  File "/opt/conda/lib/python3.8/site-packages/datalad/interface/utils.py", line 579, in _process_results
    for r in destination_dataset.get(
  File "/opt/conda/lib/python3.8/site-packages/datalad/interface/utils.py", line 396, in generator_func
    results = list(results)
  File "/opt/conda/lib/python3.8/site-packages/datalad/interface/utils.py", line 396, in generator_func
    for res in results:    
for r in _process_results(
  File "/opt/conda/lib/python3.8/site-packages/datalad/distribution/get.py", line 849, in __call__
  File "/opt/conda/lib/python3.8/site-packages/datalad/interface/utils.py", line 579, in _process_results
    for r in _process_results(
  File "/opt/conda/lib/python3.8/site-packages/datalad/interface/utils.py", line 579, in _process_results
    for res in results:
  File "/opt/conda/lib/python3.8/site-packages/datalad/distribution/get.py", line 849, in __call__
    refds = require_dataset(
      File "/opt/conda/lib/python3.8/site-packages/datalad/distribution/dataset.py", line 567, in require_dataset
for res in results:
  File "/opt/conda/lib/python3.8/site-packages/datalad/distribution/install.py", line 381, in __call__
        for r in destination_dataset.get(refds = require_dataset(    

raise ValueError(u"No installed dataset found at "  File "/opt/conda/lib/python3.8/site-packages/datalad/interface/utils.py", line 396, in generator_func

  File "/opt/conda/lib/python3.8/site-packages/datalad/distribution/dataset.py", line 567, in require_dataset
ValueError: No installed dataset found at /scratch1/03201/jbwexler/work_dir/fmriprep/ds000117_sub-10/fmriprep_wf/single_subject_10_wf/func_preproc_ses_mri_task_facerecognition_run_03_wf/unwarp_wf/resample/sourcedata/templateflow.
    for r in _process_results(
  File "/opt/conda/lib/python3.8/site-packages/datalad/interface/utils.py", line 579, in _process_results
    raise ValueError(u"No installed dataset found at "
ValueError: No installed dataset found at /scratch1/03201/jbwexler/work_dir/fmriprep/ds000117_sub-10/fmriprep_wf/single_subject_10_wf/func_preproc_ses_mri_task_facerecognition_run_03_wf/unwarp_wf/resample/sourcedata/templateflow.
    for res in results:
  File "/opt/conda/lib/python3.8/site-packages/datalad/distribution/get.py", line 849, in __call__
    refds = require_dataset(
  File "/opt/conda/lib/python3.8/site-packages/datalad/distribution/dataset.py", line 567, in require_dataset
    raise ValueError(u"No installed dataset found at "
ValueError: No installed dataset found at /scratch1/03201/jbwexler/work_dir/fmriprep/ds000117_sub-10/fmriprep_wf/single_subject_10_wf/func_preproc_ses_mri_task_facerecognition_run_03_wf/unwarp_wf/resample/sourcedata/templateflow.
[INFO] Cloning dataset to Dataset(/scratch1/03201/jbwexler/work_dir/fmriprep/ds000117_sub-10/fmriprep_wf/single_subject_10_wf/func_preproc_ses_mri_task_facerecognition_run_04_wf/unwarp_wf/resample/sourcedata/templateflow) 
[INFO] Cloning dataset to Dataset(/scratch1/03201/jbwexler/work_dir/fmriprep/ds000117_sub-10/fmriprep_wf/single_subject_10_wf/func_preproc_ses_mri_task_facerecognition_run_04_wf/unwarp_wf/resample/sourcedata/templateflow) 
[INFO] Cloning dataset to Dataset(/scratch1/03201/jbwexler/work_dir/fmriprep/ds000117_sub-10/fmriprep_wf/single_subject_10_wf/func_preproc_ses_mri_task_facerecognition_run_04_wf/unwarp_wf/resample/sourcedata/templateflow) 
[INFO] Attempting to clone from https://github.com/templateflow/templateflow.git to /scratch1/03201/jbwexler/work_dir/fmriprep/ds000117_sub-10/fmriprep_wf/single_subject_10_wf/func_preproc_ses_mri_task_facerecognition_run_04_wf/unwarp_wf/resample/sourcedata/templateflow 
[INFO] Attempting to clone from https://github.com/templateflow/templateflow.git to /scratch1/03201/jbwexler/work_dir/fmriprep/ds000117_sub-10/fmriprep_wf/single_subject_10_wf/func_preproc_ses_mri_task_facerecognition_run_04_wf/unwarp_wf/resample/sourcedata/templateflow 
[INFO] Attempting to clone from https://github.com/templateflow/templateflow.git to /scratch1/03201/jbwexler/work_dir/fmriprep/ds000117_sub-10/fmriprep_wf/single_subject_10_wf/func_preproc_ses_mri_task_facerecognition_run_04_wf/unwarp_wf/resample/sourcedata/templateflow 
[INFO] Cloning dataset to Dataset(/scratch1/03201/jbwexler/work_dir/fmriprep/ds000117_sub-10/fmriprep_wf/single_subject_10_wf/func_preproc_ses_mri_task_facerecognition_run_04_wf/unwarp_wf/resample/sourcedata/templateflow) 
[INFO] Attempting to clone from https://github.com/templateflow/templateflow.git to /scratch1/03201/jbwexler/work_dir/fmriprep/ds000117_sub-10/fmriprep_wf/single_subject_10_wf/func_preproc_ses_mri_task_facerecognition_run_04_wf/unwarp_wf/resample/sourcedata/templateflow 
[INFO] Cloning dataset to Dataset(/scratch1/03201/jbwexler/work_dir/fmriprep/ds000117_sub-10/fmriprep_wf/single_subject_10_wf/func_preproc_ses_mri_task_facerecognition_run_04_wf/unwarp_wf/resample/sourcedata/templateflow) 
[INFO] Attempting to clone from https://github.com/templateflow/templateflow.git to /scratch1/03201/jbwexler/work_dir/fmriprep/ds000117_sub-10/fmriprep_wf/single_subject_10_wf/func_preproc_ses_mri_task_facerecognition_run_04_wf/unwarp_wf/resample/sourcedata/templateflow 
Traceback (most recent call last):
  File "/opt/conda/lib/python3.8/multiprocessing/forkserver.py", line 280, in main
    code = _serve_one(child_r, fds,
  File "/opt/conda/lib/python3.8/multiprocessing/forkserver.py", line 319, in _serve_one
    code = spawn._main(child_r, parent_sentinel)
  File "/opt/conda/lib/python3.8/multiprocessing/spawn.py", line 125, in _main
    prepare(preparation_data)
  File "/opt/conda/lib/python3.8/multiprocessing/spawn.py", line 236, in prepare
    _fixup_main_from_path(data['init_main_from_path'])
  File "/opt/conda/lib/python3.8/multiprocessing/spawn.py", line 287, in _fixup_main_from_path
    main_content = runpy.run_path(main_path,
  File "/opt/conda/lib/python3.8/runpy.py", line 265, in run_path
    return _run_module_code(code, init_globals, run_name,
  File "/opt/conda/lib/python3.8/runpy.py", line 97, in _run_module_code
    _run_code(code, mod_globals, init_globals,
  File "/opt/conda/lib/python3.8/runpy.py", line 87, in _run_code
    exec(code, run_globals)
  File "/opt/conda/bin/fmriprep", line 5, in <module>
    from fmriprep.cli.run import main
  File "/opt/conda/lib/python3.8/site-packages/fmriprep/cli/run.py", line 25, in <module>
    from .. import config
  File "/opt/conda/lib/python3.8/site-packages/fmriprep/config.py", line 116, in <module>
    from templateflow import __version__ as _tf_ver
  File "/opt/conda/lib/python3.8/site-packages/templateflow/__init__.py", line 19, in <module>
    from . import api
  File "/opt/conda/lib/python3.8/site-packages/templateflow/api.py", line 7, in <module>
    from .conf import TF_LAYOUT, TF_S3_ROOT, TF_USE_DATALAD, requires_layout
  File "/opt/conda/lib/python3.8/site-packages/templateflow/conf/__init__.py", line 53, in <module>
    install(path=str(TF_HOME), source=TF_GITHUB_SOURCE, recursive=True)
  File "/opt/conda/lib/python3.8/site-packages/datalad/interface/utils.py", line 484, in eval_func
    return return_func(generator_func)(*args, **kwargs)
  File "/opt/conda/lib/python3.8/site-packages/datalad/interface/utils.py", line 476, in return_func
Traceback (most recent call last):
    results = list(results)  File "/opt/conda/lib/python3.8/multiprocessing/forkserver.py", line 280, in main

  File "/opt/conda/lib/python3.8/site-packages/datalad/interface/utils.py", line 396, in generator_func
    for r in _process_results(
  File "/opt/conda/lib/python3.8/site-packages/datalad/interface/utils.py", line 579, in _process_results
    code = _serve_one(child_r, fds,
  File "/opt/conda/lib/python3.8/multiprocessing/forkserver.py", line 319, in _serve_one
    for res in results:
  File "/opt/conda/lib/python3.8/site-packages/datalad/distribution/install.py", line 381, in __call__
    code = spawn._main(child_r, parent_sentinel)
  File "/opt/conda/lib/python3.8/multiprocessing/spawn.py", line 125, in _main
    for r in destination_dataset.get(
    prepare(preparation_data)  File "/opt/conda/lib/python3.8/site-packages/datalad/interface/utils.py", line 396, in generator_func

  File "/opt/conda/lib/python3.8/multiprocessing/spawn.py", line 236, in prepare
    _fixup_main_from_path(data['init_main_from_path'])
      File "/opt/conda/lib/python3.8/multiprocessing/spawn.py", line 287, in _fixup_main_from_path
for r in _process_results(
  File "/opt/conda/lib/python3.8/site-packages/datalad/interface/utils.py", line 579, in _process_results
    main_content = runpy.run_path(main_path,
  File "/opt/conda/lib/python3.8/runpy.py", line 265, in run_path
    for res in results:
  File "/opt/conda/lib/python3.8/site-packages/datalad/distribution/get.py", line 849, in __call__
    return _run_module_code(code, init_globals, run_name,
  File "/opt/conda/lib/python3.8/runpy.py", line 97, in _run_module_code
    _run_code(code, mod_globals, init_globals,
  File "/opt/conda/lib/python3.8/runpy.py", line 87, in _run_code
    exec(code, run_globals)
  File "/opt/conda/bin/fmriprep", line 5, in <module>
    refds = require_dataset(
    from fmriprep.cli.run import main  File "/opt/conda/lib/python3.8/site-packages/datalad/distribution/dataset.py", line 567, in require_dataset

  File "/opt/conda/lib/python3.8/site-packages/fmriprep/cli/run.py", line 25, in <module>
    from .. import config
  File "/opt/conda/lib/python3.8/site-packages/fmriprep/config.py", line 116, in <module>
    raise ValueError(u"No installed dataset found at "
ValueError:     from templateflow import __version__ as _tf_verNo installed dataset found at /scratch1/03201/jbwexler/work_dir/fmriprep/ds000117_sub-10/fmriprep_wf/single_subject_10_wf/func_preproc_ses_mri_task_facerecognition_run_04_wf/unwarp_wf/resample/sourcedata/templateflow.

  File "/opt/conda/lib/python3.8/site-packages/templateflow/__init__.py", line 19, in <module>
    from . import api
  File "/opt/conda/lib/python3.8/site-packages/templateflow/api.py", line 7, in <module>
    from .conf import TF_LAYOUT, TF_S3_ROOT, TF_USE_DATALAD, requires_layout
  File "/opt/conda/lib/python3.8/site-packages/templateflow/conf/__init__.py", line 53, in <module>
    install(path=str(TF_HOME), source=TF_GITHUB_SOURCE, recursive=True)
  File "/opt/conda/lib/python3.8/site-packages/datalad/interface/utils.py", line 484, in eval_func
    return return_func(generator_func)(*args, **kwargs)
  File "/opt/conda/lib/python3.8/site-packages/datalad/interface/utils.py", line 476, in return_func
    results = list(results)
  File "/opt/conda/lib/python3.8/site-packages/datalad/interface/utils.py", line 396, in generator_func
    for r in _process_results(
  File "/opt/conda/lib/python3.8/site-packages/datalad/interface/utils.py", line 579, in _process_results
    for res in results:
  File "/opt/conda/lib/python3.8/site-packages/datalad/distribution/install.py", line 381, in __call__
    for r in destination_dataset.get(
  File "/opt/conda/lib/python3.8/site-packages/datalad/interface/utils.py", line 396, in generator_func
    for r in _process_results(
  File "/opt/conda/lib/python3.8/site-packages/datalad/interface/utils.py", line 579, in _process_results
    for res in results:
  File "/opt/conda/lib/python3.8/site-packages/datalad/distribution/get.py", line 849, in __call__
    refds = require_dataset(
  File "/opt/conda/lib/python3.8/site-packages/datalad/distribution/dataset.py", line 567, in require_dataset
    raise ValueError(u"No installed dataset found at "
ValueError: No installed dataset found at /scratch1/03201/jbwexler/work_dir/fmriprep/ds000117_sub-10/fmriprep_wf/single_subject_10_wf/func_preproc_ses_mri_task_facerecognition_run_04_wf/unwarp_wf/resample/sourcedata/templateflow.
[INFO] Cloning dataset to Dataset(/scratch1/03201/jbwexler/work_dir/fmriprep/ds000117_sub-10/fmriprep_wf/single_subject_10_wf/func_preproc_ses_mri_task_facerecognition_run_05_wf/unwarp_wf/resample/sourcedata/templateflow) 
[INFO] Attempting to clone from https://github.com/templateflow/templateflow.git to /scratch1/03201/jbwexler/work_dir/fmriprep/ds000117_sub-10/fmriprep_wf/single_subject_10_wf/func_preproc_ses_mri_task_facerecognition_run_05_wf/unwarp_wf/resample/sourcedata/templateflow 
[INFO] Cloning dataset to Dataset(/scratch1/03201/jbwexler/work_dir/fmriprep/ds000117_sub-10/fmriprep_wf/single_subject_10_wf/func_preproc_ses_mri_task_facerecognition_run_05_wf/unwarp_wf/resample/sourcedata/templateflow) 
[INFO] Attempting to clone from https://github.com/templateflow/templateflow.git to /scratch1/03201/jbwexler/work_dir/fmriprep/ds000117_sub-10/fmriprep_wf/single_subject_10_wf/func_preproc_ses_mri_task_facerecognition_run_05_wf/unwarp_wf/resample/sourcedata/templateflow 
[INFO] Cloning dataset to Dataset(/scratch1/03201/jbwexler/work_dir/fmriprep/ds000117_sub-10/fmriprep_wf/single_subject_10_wf/func_preproc_ses_mri_task_facerecognition_run_05_wf/unwarp_wf/resample/sourcedata/templateflow) 
[INFO] Attempting to clone from https://github.com/templateflow/templateflow.git to /scratch1/03201/jbwexler/work_dir/fmriprep/ds000117_sub-10/fmriprep_wf/single_subject_10_wf/func_preproc_ses_mri_task_facerecognition_run_05_wf/unwarp_wf/resample/sourcedata/templateflow 
[INFO] Cloning dataset to Dataset(/scratch1/03201/jbwexler/work_dir/fmriprep/ds000117_sub-10/fmriprep_wf/single_subject_10_wf/func_preproc_ses_mri_task_facerecognition_run_05_wf/unwarp_wf/resample/sourcedata/templateflow) 
[INFO] Cloning dataset to Dataset(/scratch1/03201/jbwexler/work_dir/fmriprep/ds000117_sub-10/fmriprep_wf/single_subject_10_wf/func_preproc_ses_mri_task_facerecognition_run_05_wf/unwarp_wf/resample/sourcedata/templateflow) 
[INFO] Attempting to clone from https://github.com/templateflow/templateflow.git to /scratch1/03201/jbwexler/work_dir/fmriprep/ds000117_sub-10/fmriprep_wf/single_subject_10_wf/func_preproc_ses_mri_task_facerecognition_run_05_wf/unwarp_wf/resample/sourcedata/templateflow 
[INFO] Attempting to clone from https://github.com/templateflow/templateflow.git to /scratch1/03201/jbwexler/work_dir/fmriprep/ds000117_sub-10/fmriprep_wf/single_subject_10_wf/func_preproc_ses_mri_task_facerecognition_run_05_wf/unwarp_wf/resample/sourcedata/templateflow 
[INFO] Cloning dataset to Dataset(/scratch1/03201/jbwexler/work_dir/fmriprep/ds000117_sub-10/fmriprep_wf/single_subject_10_wf/func_preproc_ses_mri_task_facerecognition_run_05_wf/unwarp_wf/resample/sourcedata/templateflow) 
[INFO] Attempting to clone from https://github.com/templateflow/templateflow.git to /scratch1/03201/jbwexler/work_dir/fmriprep/ds000117_sub-10/fmriprep_wf/single_subject_10_wf/func_preproc_ses_mri_task_facerecognition_run_05_wf/unwarp_wf/resample/sourcedata/templateflow 
Traceback (most recent call last):
  File "/opt/conda/lib/python3.8/multiprocessing/forkserver.py", line 280, in main
    code = _serve_one(child_r, fds,
  File "/opt/conda/lib/python3.8/multiprocessing/forkserver.py", line 319, in _serve_one
    code = spawn._main(child_r, parent_sentinel)
  File "/opt/conda/lib/python3.8/multiprocessing/spawn.py", line 125, in _main
    prepare(preparation_data)
  File "/opt/conda/lib/python3.8/multiprocessing/spawn.py", line 236, in prepare
    _fixup_main_from_path(data['init_main_from_path'])
  File "/opt/conda/lib/python3.8/multiprocessing/spawn.py", line 287, in _fixup_main_from_path
    main_content = runpy.run_path(main_path,
  File "/opt/conda/lib/python3.8/runpy.py", line 265, in run_path
    return _run_module_code(code, init_globals, run_name,
  File "/opt/conda/lib/python3.8/runpy.py", line 97, in _run_module_code
    _run_code(code, mod_globals, init_globals,
  File "/opt/conda/lib/python3.8/runpy.py", line 87, in _run_code
    exec(code, run_globals)
  File "/opt/conda/bin/fmriprep", line 5, in <module>
    from fmriprep.cli.run import main
  File "/opt/conda/lib/python3.8/site-packages/fmriprep/cli/run.py", line 25, in <module>
    from .. import config
  File "/opt/conda/lib/python3.8/site-packages/fmriprep/config.py", line 116, in <module>
    from templateflow import __version__ as _tf_ver
  File "/opt/conda/lib/python3.8/site-packages/templateflow/__init__.py", line 19, in <module>
    from . import api
  File "/opt/conda/lib/python3.8/site-packages/templateflow/api.py", line 7, in <module>
    from .conf import TF_LAYOUT, TF_S3_ROOT, TF_USE_DATALAD, requires_layout
  File "/opt/conda/lib/python3.8/site-packages/templateflow/conf/__init__.py", line 53, in <module>
    install(path=str(TF_HOME), source=TF_GITHUB_SOURCE, recursive=True)
  File "/opt/conda/lib/python3.8/site-packages/datalad/interface/utils.py", line 484, in eval_func
    return return_func(generator_func)(*args, **kwargs)
  File "/opt/conda/lib/python3.8/site-packages/datalad/interface/utils.py", line 476, in return_func
    results = list(results)
  File "/opt/conda/lib/python3.8/site-packages/datalad/interface/utils.py", line 396, in generator_func
    for r in _process_results(
  File "/opt/conda/lib/python3.8/site-packages/datalad/interface/utils.py", line 579, in _process_results
    for res in results:
  File "/opt/conda/lib/python3.8/site-packages/datalad/distribution/install.py", line 381, in __call__
    for r in destination_dataset.get(
  File "/opt/conda/lib/python3.8/site-packages/datalad/interface/utils.py", line 396, in generator_func
    for r in _process_results(
  File "/opt/conda/lib/python3.8/site-packages/datalad/interface/utils.py", line 579, in _process_results
    for res in results:
  File "/opt/conda/lib/python3.8/site-packages/datalad/distribution/get.py", line 849, in __call__
    refds = require_dataset(
  File "/opt/conda/lib/python3.8/site-packages/datalad/distribution/dataset.py", line 567, in require_dataset
    raise ValueError(u"No installed dataset found at "
ValueError: No installed dataset found at /scratch1/03201/jbwexler/work_dir/fmriprep/ds000117_sub-10/fmriprep_wf/single_subject_10_wf/func_preproc_ses_mri_task_facerecognition_run_05_wf/unwarp_wf/resample/sourcedata/templateflow.
[INFO] Cloning dataset to Dataset(/scratch1/03201/jbwexler/work_dir/fmriprep/ds000117_sub-10/fmriprep_wf/single_subject_10_wf/func_preproc_ses_mri_task_facerecognition_run_06_wf/unwarp_wf/resample/sourcedata/templateflow) 
[INFO] Attempting to clone from https://github.com/templateflow/templateflow.git to /scratch1/03201/jbwexler/work_dir/fmriprep/ds000117_sub-10/fmriprep_wf/single_subject_10_wf/func_preproc_ses_mri_task_facerecognition_run_06_wf/unwarp_wf/resample/sourcedata/templateflow 
[INFO] Cloning dataset to Dataset(/scratch1/03201/jbwexler/work_dir/fmriprep/ds000117_sub-10/fmriprep_wf/single_subject_10_wf/func_preproc_ses_mri_task_facerecognition_run_06_wf/unwarp_wf/resample/sourcedata/templateflow) 
[INFO] Attempting to clone from https://github.com/templateflow/templateflow.git to /scratch1/03201/jbwexler/work_dir/fmriprep/ds000117_sub-10/fmriprep_wf/single_subject_10_wf/func_preproc_ses_mri_task_facerecognition_run_06_wf/unwarp_wf/resample/sourcedata/templateflow 
[INFO] Cloning dataset to Dataset(/scratch1/03201/jbwexler/work_dir/fmriprep/ds000117_sub-10/fmriprep_wf/single_subject_10_wf/func_preproc_ses_mri_task_facerecognition_run_06_wf/unwarp_wf/resample/sourcedata/templateflow) 
[INFO] Attempting to clone from https://github.com/templateflow/templateflow.git to /scratch1/03201/jbwexler/work_dir/fmriprep/ds000117_sub-10/fmriprep_wf/single_subject_10_wf/func_preproc_ses_mri_task_facerecognition_run_06_wf/unwarp_wf/resample/sourcedata/templateflow 
[INFO] Cloning dataset to Dataset(/scratch1/03201/jbwexler/work_dir/fmriprep/ds000117_sub-10/fmriprep_wf/single_subject_10_wf/func_preproc_ses_mri_task_facerecognition_run_06_wf/unwarp_wf/resample/sourcedata/templateflow) 
[INFO] Attempting to clone from https://github.com/templateflow/templateflow.git to /scratch1/03201/jbwexler/work_dir/fmriprep/ds000117_sub-10/fmriprep_wf/single_subject_10_wf/func_preproc_ses_mri_task_facerecognition_run_06_wf/unwarp_wf/resample/sourcedata/templateflow 
[INFO] Cloning dataset to Dataset(/scratch1/03201/jbwexler/work_dir/fmriprep/ds000117_sub-10/fmriprep_wf/single_subject_10_wf/func_preproc_ses_mri_task_facerecognition_run_06_wf/unwarp_wf/resample/sourcedata/templateflow) 
[INFO] Attempting to clone from https://github.com/templateflow/templateflow.git to /scratch1/03201/jbwexler/work_dir/fmriprep/ds000117_sub-10/fmriprep_wf/single_subject_10_wf/func_preproc_ses_mri_task_facerecognition_run_06_wf/unwarp_wf/resample/sourcedata/templateflow 
[INFO] Cloning dataset to Dataset(/scratch1/03201/jbwexler/work_dir/fmriprep/ds000117_sub-10/fmriprep_wf/single_subject_10_wf/func_preproc_ses_mri_task_facerecognition_run_06_wf/unwarp_wf/resample/sourcedata/templateflow) 
[INFO] Attempting to clone from https://github.com/templateflow/templateflow.git to /scratch1/03201/jbwexler/work_dir/fmriprep/ds000117_sub-10/fmriprep_wf/single_subject_10_wf/func_preproc_ses_mri_task_facerecognition_run_06_wf/unwarp_wf/resample/sourcedata/templateflow 
[INFO] Cloning dataset to Dataset(/scratch1/03201/jbwexler/work_dir/fmriprep/ds000117_sub-10/fmriprep_wf/single_subject_10_wf/func_preproc_ses_mri_task_facerecognition_run_06_wf/unwarp_wf/resample/sourcedata/templateflow) 
[INFO] Attempting to clone from https://github.com/templateflow/templateflow.git to /scratch1/03201/jbwexler/work_dir/fmriprep/ds000117_sub-10/fmriprep_wf/single_subject_10_wf/func_preproc_ses_mri_task_facerecognition_run_06_wf/unwarp_wf/resample/sourcedata/templateflow 
[INFO] Completed clone attempts for Dataset(/scratch1/03201/jbwexler/work_dir/fmriprep/ds000117_sub-10/fmriprep_wf/single_subject_10_wf/func_preproc_ses_mri_task_facerecognition_run_06_wf/unwarp_wf/resample/sourcedata/templateflow) 
[INFO] Attempting to clone from https://github.com/templateflow/templateflow.git/.git to /scratch1/03201/jbwexler/work_dir/fmriprep/ds000117_sub-10/fmriprep_wf/single_subject_10_wf/func_preproc_ses_mri_task_facerecognition_run_06_wf/unwarp_wf/resample/sourcedata/templateflow 
[INFO] Attempting to clone from https://github.com/templateflow/templateflow.git/.git to /scratch1/03201/jbwexler/work_dir/fmriprep/ds000117_sub-10/fmriprep_wf/single_subject_10_wf/func_preproc_ses_mri_task_facerecognition_run_06_wf/unwarp_wf/resample/sourcedata/templateflow 
Traceback (most recent call last):
  File "/opt/conda/lib/python3.8/multiprocessing/forkserver.py", line 280, in main
    code = _serve_one(child_r, fds,
  File "/opt/conda/lib/python3.8/multiprocessing/forkserver.py", line 319, in _serve_one
    code = spawn._main(child_r, parent_sentinel)
  File "/opt/conda/lib/python3.8/multiprocessing/spawn.py", line 125, in _main
    prepare(preparation_data)
  File "/opt/conda/lib/python3.8/multiprocessing/spawn.py", line 236, in prepare
    _fixup_main_from_path(data['init_main_from_path'])
  File "/opt/conda/lib/python3.8/multiprocessing/spawn.py", line 287, in _fixup_main_from_path
    main_content = runpy.run_path(main_path,
  File "/opt/conda/lib/python3.8/runpy.py", line 265, in run_path
    return _run_module_code(code, init_globals, run_name,
  File "/opt/conda/lib/python3.8/runpy.py", line 97, in _run_module_code
    _run_code(code, mod_globals, init_globals,
  File "/opt/conda/lib/python3.8/runpy.py", line 87, in _run_code
    exec(code, run_globals)
  File "/opt/conda/bin/fmriprep", line 5, in <module>
    from fmriprep.cli.run import main
  File "/opt/conda/lib/python3.8/site-packages/fmriprep/cli/run.py", line 25, in <module>
    from .. import config
  File "/opt/conda/lib/python3.8/site-packages/fmriprep/config.py", line 116, in <module>
    from templateflow import __version__ as _tf_ver
  File "/opt/conda/lib/python3.8/site-packages/templateflow/__init__.py", line 19, in <module>
    from . import api
  File "/opt/conda/lib/python3.8/site-packages/templateflow/api.py", line 7, in <module>
    from .conf import TF_LAYOUT, TF_S3_ROOT, TF_USE_DATALAD, requires_layout
  File "/opt/conda/lib/python3.8/site-packages/templateflow/conf/__init__.py", line 53, in <module>
    install(path=str(TF_HOME), source=TF_GITHUB_SOURCE, recursive=True)
  File "/opt/conda/lib/python3.8/site-packages/datalad/interface/utils.py", line 484, in eval_func
    return return_func(generator_func)(*args, **kwargs)
  File "/opt/conda/lib/python3.8/site-packages/datalad/interface/utils.py", line 476, in return_func
    results = list(results)
  File "/opt/conda/lib/python3.8/site-packages/datalad/interface/utils.py", line 396, in generator_func
    for r in _process_results(
  File "/opt/conda/lib/python3.8/site-packages/datalad/interface/utils.py", line 579, in _process_results
    for res in results:
  File "/opt/conda/lib/python3.8/site-packages/datalad/distribution/install.py", line 381, in __call__
    for r in destination_dataset.get(
  File "/opt/conda/lib/python3.8/site-packages/datalad/interface/utils.py", line 396, in generator_func
    for r in _process_results(
  File "/opt/conda/lib/python3.8/site-packages/datalad/interface/utils.py", line 579, in _process_results
    for res in results:
  File "/opt/conda/lib/python3.8/site-packages/datalad/distribution/get.py", line 849, in __call__
    refds = require_dataset(
  File "/opt/conda/lib/python3.8/site-packages/datalad/distribution/dataset.py", line 567, in require_dataset
    raise ValueError(u"No installed dataset found at "
ValueError: No installed dataset found at /scratch1/03201/jbwexler/work_dir/fmriprep/ds000117_sub-10/fmriprep_wf/single_subject_10_wf/func_preproc_ses_mri_task_facerecognition_run_06_wf/unwarp_wf/resample/sourcedata/templateflow.
[INFO] Cloning dataset to Dataset(/scratch1/03201/jbwexler/work_dir/fmriprep/ds000117_sub-10/fmriprep_wf/single_subject_10_wf/func_preproc_ses_mri_task_facerecognition_run_07_wf/unwarp_wf/resample/sourcedata/templateflow) 
[INFO] Cloning dataset to Dataset(/scratch1/03201/jbwexler/work_dir/fmriprep/ds000117_sub-10/fmriprep_wf/single_subject_10_wf/func_preproc_ses_mri_task_facerecognition_run_07_wf/unwarp_wf/resample/sourcedata/templateflow) 
[INFO] Attempting to clone from https://github.com/templateflow/templateflow.git to /scratch1/03201/jbwexler/work_dir/fmriprep/ds000117_sub-10/fmriprep_wf/single_subject_10_wf/func_preproc_ses_mri_task_facerecognition_run_07_wf/unwarp_wf/resample/sourcedata/templateflow 
[INFO] Attempting to clone from https://github.com/templateflow/templateflow.git to /scratch1/03201/jbwexler/work_dir/fmriprep/ds000117_sub-10/fmriprep_wf/single_subject_10_wf/func_preproc_ses_mri_task_facerecognition_run_07_wf/unwarp_wf/resample/sourcedata/templateflow 
Traceback (most recent call last):
  File "/opt/conda/lib/python3.8/multiprocessing/forkserver.py", line 280, in main
    code = _serve_one(child_r, fds,
  File "/opt/conda/lib/python3.8/multiprocessing/forkserver.py", line 319, in _serve_one
    code = spawn._main(child_r, parent_sentinel)
  File "/opt/conda/lib/python3.8/multiprocessing/spawn.py", line 125, in _main
    prepare(preparation_data)
  File "/opt/conda/lib/python3.8/multiprocessing/spawn.py", line 236, in prepare
    _fixup_main_from_path(data['init_main_from_path'])
  File "/opt/conda/lib/python3.8/multiprocessing/spawn.py", line 287, in _fixup_main_from_path
    main_content = runpy.run_path(main_path,
  File "/opt/conda/lib/python3.8/runpy.py", line 265, in run_path
    return _run_module_code(code, init_globals, run_name,
  File "/opt/conda/lib/python3.8/runpy.py", line 97, in _run_module_code
    _run_code(code, mod_globals, init_globals,
  File "/opt/conda/lib/python3.8/runpy.py", line 87, in _run_code
    exec(code, run_globals)
  File "/opt/conda/bin/fmriprep", line 5, in <module>
    from fmriprep.cli.run import main
  File "/opt/conda/lib/python3.8/site-packages/fmriprep/cli/run.py", line 25, in <module>
    from .. import config
  File "/opt/conda/lib/python3.8/site-packages/fmriprep/config.py", line 116, in <module>
    from templateflow import __version__ as _tf_ver
  File "/opt/conda/lib/python3.8/site-packages/templateflow/__init__.py", line 19, in <module>
    from . import api
  File "/opt/conda/lib/python3.8/site-packages/templateflow/api.py", line 7, in <module>
    from .conf import TF_LAYOUT, TF_S3_ROOT, TF_USE_DATALAD, requires_layout
  File "/opt/conda/lib/python3.8/site-packages/templateflow/conf/__init__.py", line 53, in <module>
    install(path=str(TF_HOME), source=TF_GITHUB_SOURCE, recursive=True)
  File "/opt/conda/lib/python3.8/site-packages/datalad/interface/utils.py", line 484, in eval_func
    return return_func(generator_func)(*args, **kwargs)
  File "/opt/conda/lib/python3.8/site-packages/datalad/interface/utils.py", line 476, in return_func
    results = list(results)
  File "/opt/conda/lib/python3.8/site-packages/datalad/interface/utils.py", line 396, in generator_func
    for r in _process_results(
  File "/opt/conda/lib/python3.8/site-packages/datalad/interface/utils.py", line 579, in _process_results
    for res in results:
  File "/opt/conda/lib/python3.8/site-packages/datalad/distribution/install.py", line 365, in __call__
    for r in res:
  File "/opt/conda/lib/python3.8/site-packages/datalad/interface/utils.py", line 396, in generator_func
    for r in _process_results(
  File "/opt/conda/lib/python3.8/site-packages/datalad/interface/utils.py", line 579, in _process_results
    for res in results:
  File "/opt/conda/lib/python3.8/site-packages/datalad/core/distributed/clone.py", line 320, in __call__
    yield from clone_dataset(
  File "/opt/conda/lib/python3.8/site-packages/datalad/core/distributed/clone.py", line 531, in clone_dataset
    track_name, track_url = _get_tracking_source(destds)
  File "/opt/conda/lib/python3.8/site-packages/datalad/core/distributed/clone.py", line 1336, in _get_tracking_source
    vcs = ds.repo
  File "/opt/conda/lib/python3.8/site-packages/datalad/distribution/dataset.py", line 259, in repo
    self._repo.is_with_annex():
  File "/opt/conda/lib/python3.8/site-packages/datalad/support/gitrepo.py", line 1120, in is_with_annex
    return any(
  File "/opt/conda/lib/python3.8/site-packages/datalad/support/gitrepo.py", line 1120, in <genexpr>
    return any(
  File "/opt/conda/lib/python3.8/site-packages/datalad/dataset/gitrepo.py", line 503, in for_each_ref_
    for line in self.call_git_items_(cmd, read_only=True):
  File "/opt/conda/lib/python3.8/site-packages/datalad/dataset/gitrepo.py", line 343, in call_git_items_
    out, _ = self._call_git(args, files, expect_stderr=expect_stderr,
  File "/opt/conda/lib/python3.8/site-packages/datalad/dataset/gitrepo.py", line 259, in _call_git
    res = runner.run(
  File "/opt/conda/lib/python3.8/site-packages/datalad/runner/runner.py", line 145, in run
    raise CommandError(
datalad.runner.exception.CommandError: CommandError: 'git -c diff.ignoreSubmodules=none for-each-ref '--format=%(refname:strip=2)' refs/heads refs/remotes' failed with exitcode 128 under /scratch1/03201/jbwexler/work_dir/fmriprep/ds000117_sub-10/fmriprep_wf/single_subject_10_wf/func_preproc_ses_mri_task_facerecognition_run_07_wf/unwarp_wf/resample/sourcedata/templateflow [err: 'fatal: not a git repository (or any parent up to mount point /)
Stopping at filesystem boundary (GIT_DISCOVERY_ACROSS_FILESYSTEM not set).']
[INFO] Cloning dataset to Dataset(/scratch1/03201/jbwexler/work_dir/fmriprep/ds000117_sub-10/fmriprep_wf/single_subject_10_wf/func_preproc_ses_mri_task_facerecognition_run_08_wf/unwarp_wf/resample/sourcedata/templateflow) 
[INFO] Attempting to clone from https://github.com/templateflow/templateflow.git to /scratch1/03201/jbwexler/work_dir/fmriprep/ds000117_sub-10/fmriprep_wf/single_subject_10_wf/func_preproc_ses_mri_task_facerecognition_run_08_wf/unwarp_wf/resample/sourcedata/templateflow 
[INFO] Cloning dataset to Dataset(/scratch1/03201/jbwexler/work_dir/fmriprep/ds000117_sub-10/fmriprep_wf/single_subject_10_wf/func_preproc_ses_mri_task_facerecognition_run_08_wf/unwarp_wf/resample/sourcedata/templateflow) 
[INFO] Attempting to clone from https://github.com/templateflow/templateflow.git to /scratch1/03201/jbwexler/work_dir/fmriprep/ds000117_sub-10/fmriprep_wf/single_subject_10_wf/func_preproc_ses_mri_task_facerecognition_run_08_wf/unwarp_wf/resample/sourcedata/templateflow 
[INFO] Attempting to clone from https://github.com/templateflow/templateflow.git/.git to /scratch1/03201/jbwexler/work_dir/fmriprep/ds000117_sub-10/fmriprep_wf/single_subject_10_wf/func_preproc_ses_mri_task_facerecognition_run_08_wf/unwarp_wf/resample/sourcedata/templateflow 
[INFO] Attempting to clone from https://github.com/templateflow/templateflow.git/.git to /scratch1/03201/jbwexler/work_dir/fmriprep/ds000117_sub-10/fmriprep_wf/single_subject_10_wf/func_preproc_ses_mri_task_facerecognition_run_08_wf/unwarp_wf/resample/sourcedata/templateflow 
[INFO] Cloning dataset to Dataset(/scratch1/03201/jbwexler/work_dir/fmriprep/ds000117_sub-10/fmriprep_wf/single_subject_10_wf/func_preproc_ses_mri_task_facerecognition_run_08_wf/unwarp_wf/resample/sourcedata/templateflow) 
[INFO] Attempting to clone from https://github.com/templateflow/templateflow.git to /scratch1/03201/jbwexler/work_dir/fmriprep/ds000117_sub-10/fmriprep_wf/single_subject_10_wf/func_preproc_ses_mri_task_facerecognition_run_08_wf/unwarp_wf/resample/sourcedata/templateflow 
Traceback (most recent call last):
  File "/opt/conda/lib/python3.8/multiprocessing/forkserver.py", line 280, in main
    code = _serve_one(child_r, fds,
  File "/opt/conda/lib/python3.8/multiprocessing/forkserver.py", line 319, in _serve_one
    code = spawn._main(child_r, parent_sentinel)
  File "/opt/conda/lib/python3.8/multiprocessing/spawn.py", line 125, in _main
    prepare(preparation_data)
  File "/opt/conda/lib/python3.8/multiprocessing/spawn.py", line 236, in prepare
    _fixup_main_from_path(data['init_main_from_path'])
  File "/opt/conda/lib/python3.8/multiprocessing/spawn.py", line 287, in _fixup_main_from_path
    main_content = runpy.run_path(main_path,
  File "/opt/conda/lib/python3.8/runpy.py", line 265, in run_path
    return _run_module_code(code, init_globals, run_name,
  File "/opt/conda/lib/python3.8/runpy.py", line 97, in _run_module_code
Traceback (most recent call last):
    _run_code(code, mod_globals, init_globals,
  File "/opt/conda/lib/python3.8/runpy.py", line 87, in _run_code
  File "/opt/conda/lib/python3.8/multiprocessing/forkserver.py", line 280, in main
    exec(code, run_globals)
  File "/opt/conda/bin/fmriprep", line 5, in <module>
    from fmriprep.cli.run import main
  File "/opt/conda/lib/python3.8/site-packages/fmriprep/cli/run.py", line 25, in <module>
    from .. import config
  File "/opt/conda/lib/python3.8/site-packages/fmriprep/config.py", line 116, in <module>
    code = _serve_one(child_r, fds,
  File "/opt/conda/lib/python3.8/multiprocessing/forkserver.py", line 319, in _serve_one
    from templateflow import __version__ as _tf_ver
  File "/opt/conda/lib/python3.8/site-packages/templateflow/__init__.py", line 19, in <module>
    code = spawn._main(child_r, parent_sentinel)
      File "/opt/conda/lib/python3.8/multiprocessing/spawn.py", line 125, in _main
Traceback (most recent call last):
from . import api
  File "/opt/conda/lib/python3.8/site-packages/templateflow/api.py", line 7, in <module>
  File "/opt/conda/lib/python3.8/multiprocessing/forkserver.py", line 280, in main
        prepare(preparation_data)from .conf import TF_LAYOUT, TF_S3_ROOT, TF_USE_DATALAD, requires_layout

  File "/opt/conda/lib/python3.8/multiprocessing/spawn.py", line 236, in prepare
  File "/opt/conda/lib/python3.8/site-packages/templateflow/conf/__init__.py", line 53, in <module>
    install(path=str(TF_HOME), source=TF_GITHUB_SOURCE, recursive=True)
      File "/opt/conda/lib/python3.8/site-packages/datalad/interface/utils.py", line 484, in eval_func
_fixup_main_from_path(data['init_main_from_path'])
  File "/opt/conda/lib/python3.8/multiprocessing/spawn.py", line 287, in _fixup_main_from_path
    code = _serve_one(child_r, fds,
  File "/opt/conda/lib/python3.8/multiprocessing/forkserver.py", line 319, in _serve_one
    return return_func(generator_func)(*args, **kwargs)
      File "/opt/conda/lib/python3.8/site-packages/datalad/interface/utils.py", line 476, in return_func
main_content = runpy.run_path(main_path,
  File "/opt/conda/lib/python3.8/runpy.py", line 265, in run_path
    code = spawn._main(child_r, parent_sentinel)
  File "/opt/conda/lib/python3.8/multiprocessing/spawn.py", line 125, in _main
        return _run_module_code(code, init_globals, run_name,results = list(results)

  File "/opt/conda/lib/python3.8/runpy.py", line 97, in _run_module_code
  File "/opt/conda/lib/python3.8/site-packages/datalad/interface/utils.py", line 396, in generator_func
    prepare(preparation_data)
  File "/opt/conda/lib/python3.8/multiprocessing/spawn.py", line 236, in prepare
    _run_code(code, mod_globals, init_globals,
  File "/opt/conda/lib/python3.8/runpy.py", line 87, in _run_code
        _fixup_main_from_path(data['init_main_from_path'])for r in _process_results(

      File "/opt/conda/lib/python3.8/multiprocessing/spawn.py", line 287, in _fixup_main_from_path
exec(code, run_globals)  File "/opt/conda/lib/python3.8/site-packages/datalad/interface/utils.py", line 579, in _process_results

  File "/opt/conda/bin/fmriprep", line 5, in <module>
    from fmriprep.cli.run import main
  File "/opt/conda/lib/python3.8/site-packages/fmriprep/cli/run.py", line 25, in <module>
    main_content = runpy.run_path(main_path,
  File "/opt/conda/lib/python3.8/runpy.py", line 265, in run_path
        from .. import configfor res in results:

  File "/opt/conda/lib/python3.8/site-packages/fmriprep/config.py", line 116, in <module>
  File "/opt/conda/lib/python3.8/site-packages/datalad/distribution/install.py", line 381, in __call__
    return _run_module_code(code, init_globals, run_name,
  File "/opt/conda/lib/python3.8/runpy.py", line 97, in _run_module_code
    from templateflow import __version__ as _tf_ver
  File "/opt/conda/lib/python3.8/site-packages/templateflow/__init__.py", line 19, in <module>
        _run_code(code, mod_globals, init_globals,for r in destination_dataset.get(

  File "/opt/conda/lib/python3.8/runpy.py", line 87, in _run_code
      File "/opt/conda/lib/python3.8/site-packages/datalad/interface/utils.py", line 396, in generator_func
from . import api
  File "/opt/conda/lib/python3.8/site-packages/templateflow/api.py", line 7, in <module>
    exec(code, run_globals)Traceback (most recent call last):

      File "/opt/conda/bin/fmriprep", line 5, in <module>
from .conf import TF_LAYOUT, TF_S3_ROOT, TF_USE_DATALAD, requires_layout
  File "/opt/conda/lib/python3.8/site-packages/templateflow/conf/__init__.py", line 53, in <module>
  File "/opt/conda/lib/python3.8/multiprocessing/forkserver.py", line 280, in main
    for r in _process_results(    
from fmriprep.cli.run import main  File "/opt/conda/lib/python3.8/site-packages/datalad/interface/utils.py", line 579, in _process_results

      File "/opt/conda/lib/python3.8/site-packages/fmriprep/cli/run.py", line 25, in <module>
install(path=str(TF_HOME), source=TF_GITHUB_SOURCE, recursive=True)
  File "/opt/conda/lib/python3.8/site-packages/datalad/interface/utils.py", line 484, in eval_func
    from .. import config
  File "/opt/conda/lib/python3.8/site-packages/fmriprep/config.py", line 116, in <module>
    for res in results:
  File "/opt/conda/lib/python3.8/site-packages/datalad/distribution/get.py", line 849, in __call__
    code = _serve_one(child_r, fds,    
return return_func(generator_func)(*args, **kwargs)    
from templateflow import __version__ as _tf_ver  File "/opt/conda/lib/python3.8/site-packages/datalad/interface/utils.py", line 476, in return_func

  File "/opt/conda/lib/python3.8/multiprocessing/forkserver.py", line 319, in _serve_one
  File "/opt/conda/lib/python3.8/site-packages/templateflow/__init__.py", line 19, in <module>
    from . import api
  File "/opt/conda/lib/python3.8/site-packages/templateflow/api.py", line 7, in <module>
            code = spawn._main(child_r, parent_sentinel)results = list(results)refds = require_dataset(


  File "/opt/conda/lib/python3.8/multiprocessing/spawn.py", line 125, in _main
  File "/opt/conda/lib/python3.8/site-packages/datalad/interface/utils.py", line 396, in generator_func
  File "/opt/conda/lib/python3.8/site-packages/datalad/distribution/dataset.py", line 567, in require_dataset
    from .conf import TF_LAYOUT, TF_S3_ROOT, TF_USE_DATALAD, requires_layout
  File "/opt/conda/lib/python3.8/site-packages/templateflow/conf/__init__.py", line 53, in <module>
    prepare(preparation_data)
      File "/opt/conda/lib/python3.8/multiprocessing/spawn.py", line 236, in prepare
install(path=str(TF_HOME), source=TF_GITHUB_SOURCE, recursive=True)
      File "/opt/conda/lib/python3.8/site-packages/datalad/interface/utils.py", line 484, in eval_func
for r in _process_results(
  File "/opt/conda/lib/python3.8/site-packages/datalad/interface/utils.py", line 579, in _process_results
    raise ValueError(u"No installed dataset found at "    
_fixup_main_from_path(data['init_main_from_path'])
ValueError:   File "/opt/conda/lib/python3.8/multiprocessing/spawn.py", line 287, in _fixup_main_from_path
No installed dataset found at /scratch1/03201/jbwexler/work_dir/fmriprep/ds000117_sub-10/fmriprep_wf/single_subject_10_wf/func_preproc_ses_mri_task_facerecognition_run_08_wf/unwarp_wf/resample/sourcedata/templateflow.
    return return_func(generator_func)(*args, **kwargs)        
for res in results:main_content = runpy.run_path(main_path,
  File "/opt/conda/lib/python3.8/site-packages/datalad/interface/utils.py", line 476, in return_func

  File "/opt/conda/lib/python3.8/site-packages/datalad/distribution/install.py", line 381, in __call__
  File "/opt/conda/lib/python3.8/runpy.py", line 265, in run_path
    return _run_module_code(code, init_globals, run_name,
          File "/opt/conda/lib/python3.8/runpy.py", line 97, in _run_module_code
for r in destination_dataset.get(results = list(results)

  File "/opt/conda/lib/python3.8/site-packages/datalad/interface/utils.py", line 396, in generator_func
  File "/opt/conda/lib/python3.8/site-packages/datalad/interface/utils.py", line 396, in generator_func
    _run_code(code, mod_globals, init_globals,
  File "/opt/conda/lib/python3.8/runpy.py", line 87, in _run_code
    exec(code, run_globals)        
for r in _process_results(for r in _process_results(
  File "/opt/conda/bin/fmriprep", line 5, in <module>

  File "/opt/conda/lib/python3.8/site-packages/datalad/interface/utils.py", line 579, in _process_results
  File "/opt/conda/lib/python3.8/site-packages/datalad/interface/utils.py", line 579, in _process_results
    from fmriprep.cli.run import main
  File "/opt/conda/lib/python3.8/site-packages/fmriprep/cli/run.py", line 25, in <module>
    from .. import config
  File "/opt/conda/lib/python3.8/site-packages/fmriprep/config.py", line 116, in <module>
    for res in results:    
for res in results:
  File "/opt/conda/lib/python3.8/site-packages/datalad/distribution/install.py", line 381, in __call__
  File "/opt/conda/lib/python3.8/site-packages/datalad/distribution/get.py", line 849, in __call__
    from templateflow import __version__ as _tf_ver
  File "/opt/conda/lib/python3.8/site-packages/templateflow/__init__.py", line 19, in <module>
        for r in destination_dataset.get(from . import api

  File "/opt/conda/lib/python3.8/site-packages/datalad/interface/utils.py", line 396, in generator_func
  File "/opt/conda/lib/python3.8/site-packages/templateflow/api.py", line 7, in <module>
    from .conf import TF_LAYOUT, TF_S3_ROOT, TF_USE_DATALAD, requires_layout
      File "/opt/conda/lib/python3.8/site-packages/templateflow/conf/__init__.py", line 53, in <module>
refds = require_dataset(
  File "/opt/conda/lib/python3.8/site-packages/datalad/distribution/dataset.py", line 567, in require_dataset
        for r in _process_results(install(path=str(TF_HOME), source=TF_GITHUB_SOURCE, recursive=True)

  File "/opt/conda/lib/python3.8/site-packages/datalad/interface/utils.py", line 579, in _process_results
  File "/opt/conda/lib/python3.8/site-packages/datalad/interface/utils.py", line 484, in eval_func
    raise ValueError(u"No installed dataset found at "
ValueError: No installed dataset found at /scratch1/03201/jbwexler/work_dir/fmriprep/ds000117_sub-10/fmriprep_wf/single_subject_10_wf/func_preproc_ses_mri_task_facerecognition_run_08_wf/unwarp_wf/resample/sourcedata/templateflow.
        return return_func(generator_func)(*args, **kwargs)for res in results:

  File "/opt/conda/lib/python3.8/site-packages/datalad/interface/utils.py", line 476, in return_func
  File "/opt/conda/lib/python3.8/site-packages/datalad/distribution/get.py", line 849, in __call__
    results = list(results)
  File "/opt/conda/lib/python3.8/site-packages/datalad/interface/utils.py", line 396, in generator_func
    refds = require_dataset(
  File "/opt/conda/lib/python3.8/site-packages/datalad/distribution/dataset.py", line 567, in require_dataset
    for r in _process_results(
  File "/opt/conda/lib/python3.8/site-packages/datalad/interface/utils.py", line 579, in _process_results
    raise ValueError(u"No installed dataset found at "
ValueError    : for res in results:
No installed dataset found at /scratch1/03201/jbwexler/work_dir/fmriprep/ds000117_sub-10/fmriprep_wf/single_subject_10_wf/func_preproc_ses_mri_task_facerecognition_run_08_wf/unwarp_wf/resample/sourcedata/templateflow.
  File "/opt/conda/lib/python3.8/site-packages/datalad/distribution/install.py", line 381, in __call__
    for r in destination_dataset.get(
  File "/opt/conda/lib/python3.8/site-packages/datalad/interface/utils.py", line 396, in generator_func
    for r in _process_results(
  File "/opt/conda/lib/python3.8/site-packages/datalad/interface/utils.py", line 579, in _process_results
    for res in results:
  File "/opt/conda/lib/python3.8/site-packages/datalad/distribution/get.py", line 849, in __call__
    refds = require_dataset(
  File "/opt/conda/lib/python3.8/site-packages/datalad/distribution/dataset.py", line 567, in require_dataset
    raise ValueError(u"No installed dataset found at "
ValueError: No installed dataset found at /scratch1/03201/jbwexler/work_dir/fmriprep/ds000117_sub-10/fmriprep_wf/single_subject_10_wf/func_preproc_ses_mri_task_facerecognition_run_08_wf/unwarp_wf/resample/sourcedata/templateflow.
[INFO] Cloning dataset to Dataset(/scratch1/03201/jbwexler/work_dir/fmriprep/ds000117_sub-10/fmriprep_wf/single_subject_10_wf/func_preproc_ses_mri_task_facerecognition_run_09_wf/unwarp_wf/resample/sourcedata/templateflow) 
[INFO] Attempting to clone from https://github.com/templateflow/templateflow.git to /scratch1/03201/jbwexler/work_dir/fmriprep/ds000117_sub-10/fmriprep_wf/single_subject_10_wf/func_preproc_ses_mri_task_facerecognition_run_09_wf/unwarp_wf/resample/sourcedata/templateflow 
[INFO] Cloning dataset to Dataset(/scratch1/03201/jbwexler/work_dir/fmriprep/ds000117_sub-10/fmriprep_wf/single_subject_10_wf/func_preproc_ses_mri_task_facerecognition_run_09_wf/unwarp_wf/resample/sourcedata/templateflow) 
[INFO] Attempting to clone from https://github.com/templateflow/templateflow.git to /scratch1/03201/jbwexler/work_dir/fmriprep/ds000117_sub-10/fmriprep_wf/single_subject_10_wf/func_preproc_ses_mri_task_facerecognition_run_09_wf/unwarp_wf/resample/sourcedata/templateflow 
[INFO] Cloning dataset to Dataset(/scratch1/03201/jbwexler/work_dir/fmriprep/ds000117_sub-10/fmriprep_wf/single_subject_10_wf/func_preproc_ses_mri_task_facerecognition_run_09_wf/unwarp_wf/resample/sourcedata/templateflow) 
[INFO] Attempting to clone from https://github.com/templateflow/templateflow.git to /scratch1/03201/jbwexler/work_dir/fmriprep/ds000117_sub-10/fmriprep_wf/single_subject_10_wf/func_preproc_ses_mri_task_facerecognition_run_09_wf/unwarp_wf/resample/sourcedata/templateflow 
Traceback (most recent call last):
Traceback (most recent call last):
  File "/opt/conda/lib/python3.8/multiprocessing/forkserver.py", line 280, in main
  File "/opt/conda/lib/python3.8/multiprocessing/forkserver.py", line 280, in main
    code = _serve_one(child_r, fds,
  File "/opt/conda/lib/python3.8/multiprocessing/forkserver.py", line 319, in _serve_one
    code = _serve_one(child_r, fds,
  File "/opt/conda/lib/python3.8/multiprocessing/forkserver.py", line 319, in _serve_one
    code = spawn._main(child_r, parent_sentinel)
  File "/opt/conda/lib/python3.8/multiprocessing/spawn.py", line 125, in _main
        prepare(preparation_data)
code = spawn._main(child_r, parent_sentinel)
  File "/opt/conda/lib/python3.8/multiprocessing/spawn.py", line 236, in prepare
  File "/opt/conda/lib/python3.8/multiprocessing/spawn.py", line 125, in _main
        _fixup_main_from_path(data['init_main_from_path'])
prepare(preparation_data)
  File "/opt/conda/lib/python3.8/multiprocessing/spawn.py", line 287, in _fixup_main_from_path
  File "/opt/conda/lib/python3.8/multiprocessing/spawn.py", line 236, in prepare
        main_content = runpy.run_path(main_path,_fixup_main_from_path(data['init_main_from_path'])

  File "/opt/conda/lib/python3.8/runpy.py", line 265, in run_path
  File "/opt/conda/lib/python3.8/multiprocessing/spawn.py", line 287, in _fixup_main_from_path
        main_content = runpy.run_path(main_path,return _run_module_code(code, init_globals, run_name,

  File "/opt/conda/lib/python3.8/runpy.py", line 265, in run_path
  File "/opt/conda/lib/python3.8/runpy.py", line 97, in _run_module_code
    _run_code(code, mod_globals, init_globals,
  File "/opt/conda/lib/python3.8/runpy.py", line 87, in _run_code
    return _run_module_code(code, init_globals, run_name,
      File "/opt/conda/lib/python3.8/runpy.py", line 97, in _run_module_code
exec(code, run_globals)
  File "/opt/conda/bin/fmriprep", line 5, in <module>
        _run_code(code, mod_globals, init_globals,from fmriprep.cli.run import main

  File "/opt/conda/lib/python3.8/runpy.py", line 87, in _run_code
  File "/opt/conda/lib/python3.8/site-packages/fmriprep/cli/run.py", line 25, in <module>
        exec(code, run_globals)from .. import config

  File "/opt/conda/bin/fmriprep", line 5, in <module>
  File "/opt/conda/lib/python3.8/site-packages/fmriprep/config.py", line 116, in <module>
    from fmriprep.cli.run import main
  File "/opt/conda/lib/python3.8/site-packages/fmriprep/cli/run.py", line 25, in <module>
    from templateflow import __version__ as _tf_ver
  File "/opt/conda/lib/python3.8/site-packages/templateflow/__init__.py", line 19, in <module>
    from .. import config
  File "/opt/conda/lib/python3.8/site-packages/fmriprep/config.py", line 116, in <module>
    from . import api
  File "/opt/conda/lib/python3.8/site-packages/templateflow/api.py", line 7, in <module>
    from .conf import TF_LAYOUT, TF_S3_ROOT, TF_USE_DATALAD, requires_layout    
from templateflow import __version__ as _tf_ver  File "/opt/conda/lib/python3.8/site-packages/templateflow/conf/__init__.py", line 53, in <module>

  File "/opt/conda/lib/python3.8/site-packages/templateflow/__init__.py", line 19, in <module>
    install(path=str(TF_HOME), source=TF_GITHUB_SOURCE, recursive=True)    
from . import api
  File "/opt/conda/lib/python3.8/site-packages/datalad/interface/utils.py", line 484, in eval_func
  File "/opt/conda/lib/python3.8/site-packages/templateflow/api.py", line 7, in <module>
    from .conf import TF_LAYOUT, TF_S3_ROOT, TF_USE_DATALAD, requires_layout
  File "/opt/conda/lib/python3.8/site-packages/templateflow/conf/__init__.py", line 53, in <module>
    install(path=str(TF_HOME), source=TF_GITHUB_SOURCE, recursive=True)    
return return_func(generator_func)(*args, **kwargs)
  File "/opt/conda/lib/python3.8/site-packages/datalad/interface/utils.py", line 484, in eval_func
  File "/opt/conda/lib/python3.8/site-packages/datalad/interface/utils.py", line 476, in return_func
    results = list(results)
      File "/opt/conda/lib/python3.8/site-packages/datalad/interface/utils.py", line 396, in generator_func
return return_func(generator_func)(*args, **kwargs)
  File "/opt/conda/lib/python3.8/site-packages/datalad/interface/utils.py", line 476, in return_func
    for r in _process_results(
  File "/opt/conda/lib/python3.8/site-packages/datalad/interface/utils.py", line 579, in _process_results
    results = list(results)
  File "/opt/conda/lib/python3.8/site-packages/datalad/interface/utils.py", line 396, in generator_func
        for res in results:for r in _process_results(

  File "/opt/conda/lib/python3.8/site-packages/datalad/distribution/install.py", line 381, in __call__
  File "/opt/conda/lib/python3.8/site-packages/datalad/interface/utils.py", line 579, in _process_results
    for r in destination_dataset.get(
  File "/opt/conda/lib/python3.8/site-packages/datalad/interface/utils.py", line 396, in generator_func
    for res in results:
  File "/opt/conda/lib/python3.8/site-packages/datalad/distribution/install.py", line 381, in __call__
    for r in _process_results(
  File "/opt/conda/lib/python3.8/site-packages/datalad/interface/utils.py", line 579, in _process_results
    for r in destination_dataset.get(
  File "/opt/conda/lib/python3.8/site-packages/datalad/interface/utils.py", line 396, in generator_func
    for res in results:
      File "/opt/conda/lib/python3.8/site-packages/datalad/distribution/get.py", line 849, in __call__
for r in _process_results(
  File "/opt/conda/lib/python3.8/site-packages/datalad/interface/utils.py", line 579, in _process_results
    for res in results:
  File "/opt/conda/lib/python3.8/site-packages/datalad/distribution/get.py", line 849, in __call__
    refds = require_dataset(
  File "/opt/conda/lib/python3.8/site-packages/datalad/distribution/dataset.py", line 567, in require_dataset
    raise ValueError(u"No installed dataset found at "
    refds = require_dataset(ValueError
:   File "/opt/conda/lib/python3.8/site-packages/datalad/distribution/dataset.py", line 567, in require_dataset
No installed dataset found at /scratch1/03201/jbwexler/work_dir/fmriprep/ds000117_sub-10/fmriprep_wf/single_subject_10_wf/func_preproc_ses_mri_task_facerecognition_run_09_wf/unwarp_wf/resample/sourcedata/templateflow.
    raise ValueError(u"No installed dataset found at "
ValueError: No installed dataset found at /scratch1/03201/jbwexler/work_dir/fmriprep/ds000117_sub-10/fmriprep_wf/single_subject_10_wf/func_preproc_ses_mri_task_facerecognition_run_09_wf/unwarp_wf/resample/sourcedata/templateflow.
Traceback (most recent call last):
  File "/opt/conda/lib/python3.8/multiprocessing/forkserver.py", line 280, in main
    code = _serve_one(child_r, fds,
  File "/opt/conda/lib/python3.8/multiprocessing/forkserver.py", line 319, in _serve_one
    code = spawn._main(child_r, parent_sentinel)
  File "/opt/conda/lib/python3.8/multiprocessing/spawn.py", line 125, in _main
    prepare(preparation_data)
  File "/opt/conda/lib/python3.8/multiprocessing/spawn.py", line 236, in prepare
Traceback (most recent call last):
    _fixup_main_from_path(data['init_main_from_path'])
  File "/opt/conda/lib/python3.8/multiprocessing/forkserver.py", line 280, in main
  File "/opt/conda/lib/python3.8/multiprocessing/spawn.py", line 287, in _fixup_main_from_path
    main_content = runpy.run_path(main_path,
  File "/opt/conda/lib/python3.8/runpy.py", line 265, in run_path
        return _run_module_code(code, init_globals, run_name,code = _serve_one(child_r, fds,

  File "/opt/conda/lib/python3.8/runpy.py", line 97, in _run_module_code
  File "/opt/conda/lib/python3.8/multiprocessing/forkserver.py", line 319, in _serve_one
    _run_code(code, mod_globals, init_globals,
  File "/opt/conda/lib/python3.8/runpy.py", line 87, in _run_code
    code = spawn._main(child_r, parent_sentinel)    
exec(code, run_globals)
  File "/opt/conda/lib/python3.8/multiprocessing/spawn.py", line 125, in _main
  File "/opt/conda/bin/fmriprep", line 5, in <module>
    from fmriprep.cli.run import main
      File "/opt/conda/lib/python3.8/site-packages/fmriprep/cli/run.py", line 25, in <module>
prepare(preparation_data)
  File "/opt/conda/lib/python3.8/multiprocessing/spawn.py", line 236, in prepare
    from .. import config
  File "/opt/conda/lib/python3.8/site-packages/fmriprep/config.py", line 116, in <module>
    _fixup_main_from_path(data['init_main_from_path'])
      File "/opt/conda/lib/python3.8/multiprocessing/spawn.py", line 287, in _fixup_main_from_path
from templateflow import __version__ as _tf_ver
  File "/opt/conda/lib/python3.8/site-packages/templateflow/__init__.py", line 19, in <module>
    from . import api
  File "/opt/conda/lib/python3.8/site-packages/templateflow/api.py", line 7, in <module>
    main_content = runpy.run_path(main_path,
  File "/opt/conda/lib/python3.8/runpy.py", line 265, in run_path
    from .conf import TF_LAYOUT, TF_S3_ROOT, TF_USE_DATALAD, requires_layout
  File "/opt/conda/lib/python3.8/site-packages/templateflow/conf/__init__.py", line 53, in <module>
    install(path=str(TF_HOME), source=TF_GITHUB_SOURCE, recursive=True)    
return _run_module_code(code, init_globals, run_name,  File "/opt/conda/lib/python3.8/site-packages/datalad/interface/utils.py", line 484, in eval_func

  File "/opt/conda/lib/python3.8/runpy.py", line 97, in _run_module_code
    _run_code(code, mod_globals, init_globals,
  File "/opt/conda/lib/python3.8/runpy.py", line 87, in _run_code
    exec(code, run_globals)    
return return_func(generator_func)(*args, **kwargs)  File "/opt/conda/bin/fmriprep", line 5, in <module>

  File "/opt/conda/lib/python3.8/site-packages/datalad/interface/utils.py", line 476, in return_func
    from fmriprep.cli.run import main
  File "/opt/conda/lib/python3.8/site-packages/fmriprep/cli/run.py", line 25, in <module>
    from .. import config
      File "/opt/conda/lib/python3.8/site-packages/fmriprep/config.py", line 116, in <module>
results = list(results)
  File "/opt/conda/lib/python3.8/site-packages/datalad/interface/utils.py", line 396, in generator_func
    from templateflow import __version__ as _tf_ver
  File "/opt/conda/lib/python3.8/site-packages/templateflow/__init__.py", line 19, in <module>
    for r in _process_results(
  File "/opt/conda/lib/python3.8/site-packages/datalad/interface/utils.py", line 579, in _process_results
    from . import api
  File "/opt/conda/lib/python3.8/site-packages/templateflow/api.py", line 7, in <module>
    from .conf import TF_LAYOUT, TF_S3_ROOT, TF_USE_DATALAD, requires_layout
  File "/opt/conda/lib/python3.8/site-packages/templateflow/conf/__init__.py", line 53, in <module>
    for res in results:    
install(path=str(TF_HOME), source=TF_GITHUB_SOURCE, recursive=True)  File "/opt/conda/lib/python3.8/site-packages/datalad/distribution/install.py", line 381, in __call__

  File "/opt/conda/lib/python3.8/site-packages/datalad/interface/utils.py", line 484, in eval_func
    for r in destination_dataset.get(
  File "/opt/conda/lib/python3.8/site-packages/datalad/interface/utils.py", line 396, in generator_func
    return return_func(generator_func)(*args, **kwargs)
  File "/opt/conda/lib/python3.8/site-packages/datalad/interface/utils.py", line 476, in return_func
    for r in _process_results(
  File "/opt/conda/lib/python3.8/site-packages/datalad/interface/utils.py", line 579, in _process_results
    results = list(results)
  File "/opt/conda/lib/python3.8/site-packages/datalad/interface/utils.py", line 396, in generator_func
    for res in results:
      File "/opt/conda/lib/python3.8/site-packages/datalad/distribution/get.py", line 849, in __call__
for r in _process_results(
  File "/opt/conda/lib/python3.8/site-packages/datalad/interface/utils.py", line 579, in _process_results
    for res in results:
  File "/opt/conda/lib/python3.8/site-packages/datalad/distribution/install.py", line 381, in __call__
    refds = require_dataset(
  File "/opt/conda/lib/python3.8/site-packages/datalad/distribution/dataset.py", line 567, in require_dataset
    for r in destination_dataset.get(
  File "/opt/conda/lib/python3.8/site-packages/datalad/interface/utils.py", line 396, in generator_func
    raise ValueError(u"No installed dataset found at "
ValueError:     No installed dataset found at /scratch1/03201/jbwexler/work_dir/fmriprep/ds000117_sub-10/fmriprep_wf/single_subject_10_wf/func_preproc_ses_mri_task_facerecognition_run_09_wf/unwarp_wf/resample/sourcedata/templateflow.for r in _process_results(

  File "/opt/conda/lib/python3.8/site-packages/datalad/interface/utils.py", line 579, in _process_results
    for res in results:
  File "/opt/conda/lib/python3.8/site-packages/datalad/distribution/get.py", line 849, in __call__
    refds = require_dataset(
  File "/opt/conda/lib/python3.8/site-packages/datalad/distribution/dataset.py", line 567, in require_dataset
    raise ValueError(u"No installed dataset found at "
ValueError: No installed dataset found at /scratch1/03201/jbwexler/work_dir/fmriprep/ds000117_sub-10/fmriprep_wf/single_subject_10_wf/func_preproc_ses_mri_task_facerecognition_run_09_wf/unwarp_wf/resample/sourcedata/templateflow.
