[INFO] Cloning dataset to Dataset(/scratch1/03201/jbwexler/work_dir/fmriprep/ds000117_sub-11/fmriprep_wf/single_subject_11_wf/func_preproc_ses_mri_task_facerecognition_run_01_wf/unwarp_wf/resample/sourcedata/templateflow) 
[INFO] Cloning dataset to Dataset(/scratch1/03201/jbwexler/work_dir/fmriprep/ds000117_sub-11/fmriprep_wf/single_subject_11_wf/func_preproc_ses_mri_task_facerecognition_run_01_wf/unwarp_wf/resample/sourcedata/templateflow) 
[INFO] Attempting to clone from https://github.com/templateflow/templateflow.git to /scratch1/03201/jbwexler/work_dir/fmriprep/ds000117_sub-11/fmriprep_wf/single_subject_11_wf/func_preproc_ses_mri_task_facerecognition_run_01_wf/unwarp_wf/resample/sourcedata/templateflow 
[INFO] Attempting to clone from https://github.com/templateflow/templateflow.git to /scratch1/03201/jbwexler/work_dir/fmriprep/ds000117_sub-11/fmriprep_wf/single_subject_11_wf/func_preproc_ses_mri_task_facerecognition_run_01_wf/unwarp_wf/resample/sourcedata/templateflow 
[INFO] Cloning dataset to Dataset(/scratch1/03201/jbwexler/work_dir/fmriprep/ds000117_sub-11/fmriprep_wf/single_subject_11_wf/func_preproc_ses_mri_task_facerecognition_run_01_wf/unwarp_wf/resample/sourcedata/templateflow) 
[INFO] Attempting to clone from https://github.com/templateflow/templateflow.git to /scratch1/03201/jbwexler/work_dir/fmriprep/ds000117_sub-11/fmriprep_wf/single_subject_11_wf/func_preproc_ses_mri_task_facerecognition_run_01_wf/unwarp_wf/resample/sourcedata/templateflow 
[INFO] Cloning dataset to Dataset(/scratch1/03201/jbwexler/work_dir/fmriprep/ds000117_sub-11/fmriprep_wf/single_subject_11_wf/func_preproc_ses_mri_task_facerecognition_run_01_wf/unwarp_wf/resample/sourcedata/templateflow) 
[INFO] Attempting to clone from https://github.com/templateflow/templateflow.git to /scratch1/03201/jbwexler/work_dir/fmriprep/ds000117_sub-11/fmriprep_wf/single_subject_11_wf/func_preproc_ses_mri_task_facerecognition_run_01_wf/unwarp_wf/resample/sourcedata/templateflow 
[INFO] Cloning dataset to Dataset(/scratch1/03201/jbwexler/work_dir/fmriprep/ds000117_sub-11/fmriprep_wf/single_subject_11_wf/func_preproc_ses_mri_task_facerecognition_run_01_wf/unwarp_wf/resample/sourcedata/templateflow) 
[INFO] Cloning dataset to Dataset(/scratch1/03201/jbwexler/work_dir/fmriprep/ds000117_sub-11/fmriprep_wf/single_subject_11_wf/func_preproc_ses_mri_task_facerecognition_run_01_wf/unwarp_wf/resample/sourcedata/templateflow) 
[INFO] Attempting to clone from https://github.com/templateflow/templateflow.git to /scratch1/03201/jbwexler/work_dir/fmriprep/ds000117_sub-11/fmriprep_wf/single_subject_11_wf/func_preproc_ses_mri_task_facerecognition_run_01_wf/unwarp_wf/resample/sourcedata/templateflow 
[INFO] Attempting to clone from https://github.com/templateflow/templateflow.git to /scratch1/03201/jbwexler/work_dir/fmriprep/ds000117_sub-11/fmriprep_wf/single_subject_11_wf/func_preproc_ses_mri_task_facerecognition_run_01_wf/unwarp_wf/resample/sourcedata/templateflow 
[INFO] Cloning dataset to Dataset(/scratch1/03201/jbwexler/work_dir/fmriprep/ds000117_sub-11/fmriprep_wf/single_subject_11_wf/func_preproc_ses_mri_task_facerecognition_run_01_wf/unwarp_wf/resample/sourcedata/templateflow) 
[INFO] Attempting to clone from https://github.com/templateflow/templateflow.git to /scratch1/03201/jbwexler/work_dir/fmriprep/ds000117_sub-11/fmriprep_wf/single_subject_11_wf/func_preproc_ses_mri_task_facerecognition_run_01_wf/unwarp_wf/resample/sourcedata/templateflow 
[INFO] Completed clone attempts for Dataset(/scratch1/03201/jbwexler/work_dir/fmriprep/ds000117_sub-11/fmriprep_wf/single_subject_11_wf/func_preproc_ses_mri_task_facerecognition_run_01_wf/unwarp_wf/resample/sourcedata/templateflow) 
Traceback (most recent call last):
  File "/opt/conda/lib/python3.8/multiprocessing/forkserver.py", line 280, in main
    code = _serve_one(child_r, fds,
  File "/opt/conda/lib/python3.8/multiprocessing/forkserver.py", line 319, in _serve_one
    code = spawn._main(child_r, parent_sentinel)
  File "/opt/conda/lib/python3.8/multiprocessing/spawn.py", line 125, in _main
    prepare(preparation_data)
  File "/opt/conda/lib/python3.8/multiprocessing/spawn.py", line 236, in prepare
    _fixup_main_from_path(data['init_main_from_path'])
  File "/opt/conda/lib/python3.8/multiprocessing/spawn.py", line 287, in _fixup_main_from_path
    main_content = runpy.run_path(main_path,
  File "/opt/conda/lib/python3.8/runpy.py", line 265, in run_path
    return _run_module_code(code, init_globals, run_name,
  File "/opt/conda/lib/python3.8/runpy.py", line 97, in _run_module_code
    _run_code(code, mod_globals, init_globals,
  File "/opt/conda/lib/python3.8/runpy.py", line 87, in _run_code
    exec(code, run_globals)
  File "/opt/conda/bin/fmriprep", line 5, in <module>
    from fmriprep.cli.run import main
  File "/opt/conda/lib/python3.8/site-packages/fmriprep/cli/run.py", line 25, in <module>
    from .. import config
  File "/opt/conda/lib/python3.8/site-packages/fmriprep/config.py", line 116, in <module>
    from templateflow import __version__ as _tf_ver
  File "/opt/conda/lib/python3.8/site-packages/templateflow/__init__.py", line 19, in <module>
    from . import api
  File "/opt/conda/lib/python3.8/site-packages/templateflow/api.py", line 7, in <module>
    from .conf import TF_LAYOUT, TF_S3_ROOT, TF_USE_DATALAD, requires_layout
  File "/opt/conda/lib/python3.8/site-packages/templateflow/conf/__init__.py", line 53, in <module>
    install(path=str(TF_HOME), source=TF_GITHUB_SOURCE, recursive=True)
  File "/opt/conda/lib/python3.8/site-packages/datalad/interface/utils.py", line 484, in eval_func
    return return_func(generator_func)(*args, **kwargs)
  File "/opt/conda/lib/python3.8/site-packages/datalad/interface/utils.py", line 476, in return_func
    results = list(results)
  File "/opt/conda/lib/python3.8/site-packages/datalad/interface/utils.py", line 396, in generator_func
    for r in _process_results(
  File "/opt/conda/lib/python3.8/site-packages/datalad/interface/utils.py", line 579, in _process_results
    for res in results:
  File "/opt/conda/lib/python3.8/site-packages/datalad/distribution/install.py", line 381, in __call__
    for r in destination_dataset.get(
  File "/opt/conda/lib/python3.8/site-packages/datalad/interface/utils.py", line 396, in generator_func
    for r in _process_results(
  File "/opt/conda/lib/python3.8/site-packages/datalad/interface/utils.py", line 579, in _process_results
    for res in results:
  File "/opt/conda/lib/python3.8/site-packages/datalad/distribution/get.py", line 849, in __call__
    refds = require_dataset(
  File "/opt/conda/lib/python3.8/site-packages/datalad/distribution/dataset.py", line 567, in require_dataset
    raise ValueError(u"No installed dataset found at "
ValueError: No installed dataset found at /scratch1/03201/jbwexler/work_dir/fmriprep/ds000117_sub-11/fmriprep_wf/single_subject_11_wf/func_preproc_ses_mri_task_facerecognition_run_01_wf/unwarp_wf/resample/sourcedata/templateflow.
[INFO] Cloning dataset to Dataset(/scratch1/03201/jbwexler/work_dir/fmriprep/ds000117_sub-11/fmriprep_wf/single_subject_11_wf/func_preproc_ses_mri_task_facerecognition_run_02_wf/unwarp_wf/resample/sourcedata/templateflow) 
[INFO] Attempting to clone from https://github.com/templateflow/templateflow.git to /scratch1/03201/jbwexler/work_dir/fmriprep/ds000117_sub-11/fmriprep_wf/single_subject_11_wf/func_preproc_ses_mri_task_facerecognition_run_02_wf/unwarp_wf/resample/sourcedata/templateflow 
Traceback (most recent call last):
Traceback (most recent call last):
Traceback (most recent call last):
Traceback (most recent call last):
Traceback (most recent call last):
  File "/opt/conda/lib/python3.8/multiprocessing/forkserver.py", line 280, in main
  File "/opt/conda/lib/python3.8/multiprocessing/forkserver.py", line 280, in main
  File "/opt/conda/lib/python3.8/multiprocessing/forkserver.py", line 280, in main
  File "/opt/conda/lib/python3.8/multiprocessing/forkserver.py", line 280, in main
  File "/opt/conda/lib/python3.8/multiprocessing/forkserver.py", line 280, in main
        code = _serve_one(child_r, fds,    code = _serve_one(child_r, fds,
code = _serve_one(child_r, fds,    
    
  File "/opt/conda/lib/python3.8/multiprocessing/forkserver.py", line 319, in _serve_one
code = _serve_one(child_r, fds,  File "/opt/conda/lib/python3.8/multiprocessing/forkserver.py", line 319, in _serve_one
code = _serve_one(child_r, fds,  File "/opt/conda/lib/python3.8/multiprocessing/forkserver.py", line 319, in _serve_one


  File "/opt/conda/lib/python3.8/multiprocessing/forkserver.py", line 319, in _serve_one
  File "/opt/conda/lib/python3.8/multiprocessing/forkserver.py", line 319, in _serve_one
    code = spawn._main(child_r, parent_sentinel)        
code = spawn._main(child_r, parent_sentinel)code = spawn._main(child_r, parent_sentinel)      File "/opt/conda/lib/python3.8/multiprocessing/spawn.py", line 125, in _main


code = spawn._main(child_r, parent_sentinel)
      File "/opt/conda/lib/python3.8/multiprocessing/spawn.py", line 125, in _main
  File "/opt/conda/lib/python3.8/multiprocessing/spawn.py", line 125, in _main
  File "/opt/conda/lib/python3.8/multiprocessing/spawn.py", line 125, in _main
code = spawn._main(child_r, parent_sentinel)
  File "/opt/conda/lib/python3.8/multiprocessing/spawn.py", line 125, in _main
    prepare(preparation_data)
      File "/opt/conda/lib/python3.8/multiprocessing/spawn.py", line 236, in prepare
        prepare(preparation_data)prepare(preparation_data)prepare(preparation_data)
    Traceback (most recent call last):


prepare(preparation_data)  File "/opt/conda/lib/python3.8/multiprocessing/spawn.py", line 236, in prepare
  File "/opt/conda/lib/python3.8/multiprocessing/spawn.py", line 236, in prepare

  File "/opt/conda/lib/python3.8/multiprocessing/spawn.py", line 236, in prepare
  File "/opt/conda/lib/python3.8/multiprocessing/spawn.py", line 236, in prepare
      File "/opt/conda/lib/python3.8/multiprocessing/forkserver.py", line 280, in main
_fixup_main_from_path(data['init_main_from_path'])
  File "/opt/conda/lib/python3.8/multiprocessing/spawn.py", line 287, in _fixup_main_from_path
            _fixup_main_from_path(data['init_main_from_path'])_fixup_main_from_path(data['init_main_from_path'])_fixup_main_from_path(data['init_main_from_path'])


      File "/opt/conda/lib/python3.8/multiprocessing/spawn.py", line 287, in _fixup_main_from_path
  File "/opt/conda/lib/python3.8/multiprocessing/spawn.py", line 287, in _fixup_main_from_path
  File "/opt/conda/lib/python3.8/multiprocessing/spawn.py", line 287, in _fixup_main_from_path
_fixup_main_from_path(data['init_main_from_path'])
  File "/opt/conda/lib/python3.8/multiprocessing/spawn.py", line 287, in _fixup_main_from_path
    main_content = runpy.run_path(main_path,
  File "/opt/conda/lib/python3.8/runpy.py", line 265, in run_path
            main_content = runpy.run_path(main_path,main_content = runpy.run_path(main_path,main_content = runpy.run_path(main_path,


      File "/opt/conda/lib/python3.8/runpy.py", line 265, in run_path
  File "/opt/conda/lib/python3.8/runpy.py", line 265, in run_path
  File "/opt/conda/lib/python3.8/runpy.py", line 265, in run_path
main_content = runpy.run_path(main_path,
  File "/opt/conda/lib/python3.8/runpy.py", line 265, in run_path
        return _run_module_code(code, init_globals, run_name,code = _serve_one(child_r, fds,

  File "/opt/conda/lib/python3.8/runpy.py", line 97, in _run_module_code
  File "/opt/conda/lib/python3.8/multiprocessing/forkserver.py", line 319, in _serve_one
            return _run_module_code(code, init_globals, run_name,return _run_module_code(code, init_globals, run_name,return _run_module_code(code, init_globals, run_name,

    
      File "/opt/conda/lib/python3.8/runpy.py", line 97, in _run_module_code
  File "/opt/conda/lib/python3.8/runpy.py", line 97, in _run_module_code
return _run_module_code(code, init_globals, run_name,  File "/opt/conda/lib/python3.8/runpy.py", line 97, in _run_module_code
_run_code(code, mod_globals, init_globals,

  File "/opt/conda/lib/python3.8/runpy.py", line 97, in _run_module_code
  File "/opt/conda/lib/python3.8/runpy.py", line 87, in _run_code
    code = spawn._main(child_r, parent_sentinel)    
        _run_code(code, mod_globals, init_globals,_run_code(code, mod_globals, init_globals,  File "/opt/conda/lib/python3.8/multiprocessing/spawn.py", line 125, in _main
_run_code(code, mod_globals, init_globals,        


exec(code, run_globals)_run_code(code, mod_globals, init_globals,  File "/opt/conda/lib/python3.8/runpy.py", line 87, in _run_code
  File "/opt/conda/lib/python3.8/runpy.py", line 87, in _run_code

  File "/opt/conda/lib/python3.8/runpy.py", line 87, in _run_code

  File "/opt/conda/bin/fmriprep", line 5, in <module>
  File "/opt/conda/lib/python3.8/runpy.py", line 87, in _run_code
    prepare(preparation_data)
      File "/opt/conda/lib/python3.8/multiprocessing/spawn.py", line 236, in prepare
            from fmriprep.cli.run import mainexec(code, run_globals)    exec(code, run_globals)exec(code, run_globals)

exec(code, run_globals)

  File "/opt/conda/lib/python3.8/site-packages/fmriprep/cli/run.py", line 25, in <module>

  File "/opt/conda/bin/fmriprep", line 5, in <module>
  File "/opt/conda/bin/fmriprep", line 5, in <module>
  File "/opt/conda/bin/fmriprep", line 5, in <module>
  File "/opt/conda/bin/fmriprep", line 5, in <module>
    _fixup_main_from_path(data['init_main_from_path'])
          File "/opt/conda/lib/python3.8/multiprocessing/spawn.py", line 287, in _fixup_main_from_path
        from fmriprep.cli.run import main    from fmriprep.cli.run import mainfrom fmriprep.cli.run import mainfrom fmriprep.cli.run import main
from .. import config



  File "/opt/conda/lib/python3.8/site-packages/fmriprep/cli/run.py", line 25, in <module>
  File "/opt/conda/lib/python3.8/site-packages/fmriprep/cli/run.py", line 25, in <module>
  File "/opt/conda/lib/python3.8/site-packages/fmriprep/cli/run.py", line 25, in <module>
  File "/opt/conda/lib/python3.8/site-packages/fmriprep/cli/run.py", line 25, in <module>
  File "/opt/conda/lib/python3.8/site-packages/fmriprep/config.py", line 116, in <module>
    main_content = runpy.run_path(main_path,        
from .. import config        from .. import config
  File "/opt/conda/lib/python3.8/runpy.py", line 265, in run_path
from .. import configfrom .. import config
  File "/opt/conda/lib/python3.8/site-packages/fmriprep/config.py", line 116, in <module>


      File "/opt/conda/lib/python3.8/site-packages/fmriprep/config.py", line 116, in <module>
  File "/opt/conda/lib/python3.8/site-packages/fmriprep/config.py", line 116, in <module>
  File "/opt/conda/lib/python3.8/site-packages/fmriprep/config.py", line 116, in <module>
from templateflow import __version__ as _tf_ver
  File "/opt/conda/lib/python3.8/site-packages/templateflow/__init__.py", line 19, in <module>
        from . import api
    return _run_module_code(code, init_globals, run_name,      File "/opt/conda/lib/python3.8/site-packages/templateflow/api.py", line 7, in <module>
from templateflow import __version__ as _tf_ver
from templateflow import __version__ as _tf_ver        

  File "/opt/conda/lib/python3.8/runpy.py", line 97, in _run_module_code
from templateflow import __version__ as _tf_verfrom templateflow import __version__ as _tf_ver  File "/opt/conda/lib/python3.8/site-packages/templateflow/__init__.py", line 19, in <module>
      File "/opt/conda/lib/python3.8/site-packages/templateflow/__init__.py", line 19, in <module>


from .conf import TF_LAYOUT, TF_S3_ROOT, TF_USE_DATALAD, requires_layout
  File "/opt/conda/lib/python3.8/site-packages/templateflow/__init__.py", line 19, in <module>
  File "/opt/conda/lib/python3.8/site-packages/templateflow/__init__.py", line 19, in <module>
  File "/opt/conda/lib/python3.8/site-packages/templateflow/conf/__init__.py", line 53, in <module>
            from . import apifrom . import api_run_code(code, mod_globals, init_globals,

        
  File "/opt/conda/lib/python3.8/site-packages/templateflow/api.py", line 7, in <module>
from . import apifrom . import api      File "/opt/conda/lib/python3.8/site-packages/templateflow/api.py", line 7, in <module>
  File "/opt/conda/lib/python3.8/runpy.py", line 87, in _run_code


install(path=str(TF_HOME), source=TF_GITHUB_SOURCE, recursive=True)  File "/opt/conda/lib/python3.8/site-packages/templateflow/api.py", line 7, in <module>
  File "/opt/conda/lib/python3.8/site-packages/templateflow/api.py", line 7, in <module>
            
from .conf import TF_LAYOUT, TF_S3_ROOT, TF_USE_DATALAD, requires_layoutfrom .conf import TF_LAYOUT, TF_S3_ROOT, TF_USE_DATALAD, requires_layoutexec(code, run_globals)

  File "/opt/conda/lib/python3.8/site-packages/datalad/interface/utils.py", line 484, in eval_func

          File "/opt/conda/lib/python3.8/site-packages/templateflow/conf/__init__.py", line 53, in <module>
  File "/opt/conda/lib/python3.8/site-packages/templateflow/conf/__init__.py", line 53, in <module>
from .conf import TF_LAYOUT, TF_S3_ROOT, TF_USE_DATALAD, requires_layout  File "/opt/conda/bin/fmriprep", line 5, in <module>
from .conf import TF_LAYOUT, TF_S3_ROOT, TF_USE_DATALAD, requires_layout

  File "/opt/conda/lib/python3.8/site-packages/templateflow/conf/__init__.py", line 53, in <module>
  File "/opt/conda/lib/python3.8/site-packages/templateflow/conf/__init__.py", line 53, in <module>
            install(path=str(TF_HOME), source=TF_GITHUB_SOURCE, recursive=True)install(path=str(TF_HOME), source=TF_GITHUB_SOURCE, recursive=True)from fmriprep.cli.run import main


          File "/opt/conda/lib/python3.8/site-packages/datalad/interface/utils.py", line 484, in eval_func
  File "/opt/conda/lib/python3.8/site-packages/datalad/interface/utils.py", line 484, in eval_func
  File "/opt/conda/lib/python3.8/site-packages/fmriprep/cli/run.py", line 25, in <module>
install(path=str(TF_HOME), source=TF_GITHUB_SOURCE, recursive=True)install(path=str(TF_HOME), source=TF_GITHUB_SOURCE, recursive=True)

  File "/opt/conda/lib/python3.8/site-packages/datalad/interface/utils.py", line 484, in eval_func
  File "/opt/conda/lib/python3.8/site-packages/datalad/interface/utils.py", line 484, in eval_func
        return return_func(generator_func)(*args, **kwargs)from .. import config

  File "/opt/conda/lib/python3.8/site-packages/datalad/interface/utils.py", line 476, in return_func
  File "/opt/conda/lib/python3.8/site-packages/fmriprep/config.py", line 116, in <module>
        return return_func(generator_func)(*args, **kwargs)return return_func(generator_func)(*args, **kwargs)

  File "/opt/conda/lib/python3.8/site-packages/datalad/interface/utils.py", line 476, in return_func
  File "/opt/conda/lib/python3.8/site-packages/datalad/interface/utils.py", line 476, in return_func
            return return_func(generator_func)(*args, **kwargs)return return_func(generator_func)(*args, **kwargs)from templateflow import __version__ as _tf_ver


  File "/opt/conda/lib/python3.8/site-packages/datalad/interface/utils.py", line 476, in return_func
  File "/opt/conda/lib/python3.8/site-packages/datalad/interface/utils.py", line 476, in return_func
  File "/opt/conda/lib/python3.8/site-packages/templateflow/__init__.py", line 19, in <module>
    results = list(results)
  File "/opt/conda/lib/python3.8/site-packages/datalad/interface/utils.py", line 396, in generator_func
    from . import api
  File "/opt/conda/lib/python3.8/site-packages/templateflow/api.py", line 7, in <module>
        results = list(results)results = list(results)

      File "/opt/conda/lib/python3.8/site-packages/datalad/interface/utils.py", line 396, in generator_func
  File "/opt/conda/lib/python3.8/site-packages/datalad/interface/utils.py", line 396, in generator_func
from .conf import TF_LAYOUT, TF_S3_ROOT, TF_USE_DATALAD, requires_layout        
results = list(results)results = list(results)      File "/opt/conda/lib/python3.8/site-packages/templateflow/conf/__init__.py", line 53, in <module>


for r in _process_results(
  File "/opt/conda/lib/python3.8/site-packages/datalad/interface/utils.py", line 396, in generator_func
  File "/opt/conda/lib/python3.8/site-packages/datalad/interface/utils.py", line 396, in generator_func
  File "/opt/conda/lib/python3.8/site-packages/datalad/interface/utils.py", line 579, in _process_results
    install(path=str(TF_HOME), source=TF_GITHUB_SOURCE, recursive=True)        
for r in _process_results(    for r in _process_results(    
  File "/opt/conda/lib/python3.8/site-packages/datalad/interface/utils.py", line 484, in eval_func
for r in _process_results(
for r in _process_results(  File "/opt/conda/lib/python3.8/site-packages/datalad/interface/utils.py", line 579, in _process_results


      File "/opt/conda/lib/python3.8/site-packages/datalad/interface/utils.py", line 579, in _process_results
  File "/opt/conda/lib/python3.8/site-packages/datalad/interface/utils.py", line 579, in _process_results
for res in results:  File "/opt/conda/lib/python3.8/site-packages/datalad/interface/utils.py", line 579, in _process_results

  File "/opt/conda/lib/python3.8/site-packages/datalad/distribution/install.py", line 381, in __call__
        for res in results:    return return_func(generator_func)(*args, **kwargs)
        for res in results:    
for res in results:  File "/opt/conda/lib/python3.8/site-packages/datalad/distribution/install.py", line 381, in __call__
for r in destination_dataset.get(
for res in results:
  File "/opt/conda/lib/python3.8/site-packages/datalad/interface/utils.py", line 476, in return_func


  File "/opt/conda/lib/python3.8/site-packages/datalad/distribution/install.py", line 381, in __call__
  File "/opt/conda/lib/python3.8/site-packages/datalad/distribution/install.py", line 381, in __call__
  File "/opt/conda/lib/python3.8/site-packages/datalad/interface/utils.py", line 396, in generator_func
  File "/opt/conda/lib/python3.8/site-packages/datalad/distribution/install.py", line 381, in __call__
    for r in destination_dataset.get(
          File "/opt/conda/lib/python3.8/site-packages/datalad/interface/utils.py", line 396, in generator_func
for r in destination_dataset.get(        for r in _process_results(    
results = list(results)for r in destination_dataset.get(for r in destination_dataset.get(


  File "/opt/conda/lib/python3.8/site-packages/datalad/interface/utils.py", line 396, in generator_func

  File "/opt/conda/lib/python3.8/site-packages/datalad/interface/utils.py", line 579, in _process_results
  File "/opt/conda/lib/python3.8/site-packages/datalad/interface/utils.py", line 396, in generator_func
  File "/opt/conda/lib/python3.8/site-packages/datalad/interface/utils.py", line 396, in generator_func
  File "/opt/conda/lib/python3.8/site-packages/datalad/interface/utils.py", line 396, in generator_func
    for r in _process_results(
  File "/opt/conda/lib/python3.8/site-packages/datalad/interface/utils.py", line 579, in _process_results
    for r in _process_results(
            for r in _process_results(  File "/opt/conda/lib/python3.8/site-packages/datalad/interface/utils.py", line 579, in _process_results
for r in _process_results(for r in _process_results(


      File "/opt/conda/lib/python3.8/site-packages/datalad/interface/utils.py", line 579, in _process_results
  File "/opt/conda/lib/python3.8/site-packages/datalad/interface/utils.py", line 579, in _process_results
for res in results:  File "/opt/conda/lib/python3.8/site-packages/datalad/interface/utils.py", line 579, in _process_results

  File "/opt/conda/lib/python3.8/site-packages/datalad/distribution/get.py", line 849, in __call__
    for res in results:
  File "/opt/conda/lib/python3.8/site-packages/datalad/distribution/get.py", line 849, in __call__
    for res in results:
      File "/opt/conda/lib/python3.8/site-packages/datalad/distribution/get.py", line 849, in __call__
        for res in results:for res in results:for res in results:


  File "/opt/conda/lib/python3.8/site-packages/datalad/distribution/install.py", line 381, in __call__
  File "/opt/conda/lib/python3.8/site-packages/datalad/distribution/get.py", line 849, in __call__
  File "/opt/conda/lib/python3.8/site-packages/datalad/distribution/get.py", line 849, in __call__
    refds = require_dataset(
  File "/opt/conda/lib/python3.8/site-packages/datalad/distribution/dataset.py", line 567, in require_dataset
        for r in destination_dataset.get(refds = require_dataset(

  File "/opt/conda/lib/python3.8/site-packages/datalad/interface/utils.py", line 396, in generator_func
  File "/opt/conda/lib/python3.8/site-packages/datalad/distribution/dataset.py", line 567, in require_dataset
    refds = require_dataset(
  File "/opt/conda/lib/python3.8/site-packages/datalad/distribution/dataset.py", line 567, in require_dataset
        refds = require_dataset(refds = require_dataset(

      File "/opt/conda/lib/python3.8/site-packages/datalad/distribution/dataset.py", line 567, in require_dataset
raise ValueError(u"No installed dataset found at "  File "/opt/conda/lib/python3.8/site-packages/datalad/distribution/dataset.py", line 567, in require_dataset

ValueError: No installed dataset found at /scratch1/03201/jbwexler/work_dir/fmriprep/ds000117_sub-11/fmriprep_wf/single_subject_11_wf/func_preproc_ses_mri_task_facerecognition_run_02_wf/unwarp_wf/resample/sourcedata/templateflow.
    for r in _process_results(
      File "/opt/conda/lib/python3.8/site-packages/datalad/interface/utils.py", line 579, in _process_results
raise ValueError(u"No installed dataset found at "
    ValueErrorraise ValueError(u"No installed dataset found at ": 
No installed dataset found at /scratch1/03201/jbwexler/work_dir/fmriprep/ds000117_sub-11/fmriprep_wf/single_subject_11_wf/func_preproc_ses_mri_task_facerecognition_run_02_wf/unwarp_wf/resample/sourcedata/templateflow.ValueError
:         raise ValueError(u"No installed dataset found at "raise ValueError(u"No installed dataset found at "No installed dataset found at /scratch1/03201/jbwexler/work_dir/fmriprep/ds000117_sub-11/fmriprep_wf/single_subject_11_wf/func_preproc_ses_mri_task_facerecognition_run_02_wf/unwarp_wf/resample/sourcedata/templateflow.


ValueErrorValueError: : No installed dataset found at /scratch1/03201/jbwexler/work_dir/fmriprep/ds000117_sub-11/fmriprep_wf/single_subject_11_wf/func_preproc_ses_mri_task_facerecognition_run_02_wf/unwarp_wf/resample/sourcedata/templateflow.No installed dataset found at /scratch1/03201/jbwexler/work_dir/fmriprep/ds000117_sub-11/fmriprep_wf/single_subject_11_wf/func_preproc_ses_mri_task_facerecognition_run_02_wf/unwarp_wf/resample/sourcedata/templateflow.

    for res in results:
  File "/opt/conda/lib/python3.8/site-packages/datalad/distribution/get.py", line 849, in __call__
    refds = require_dataset(
  File "/opt/conda/lib/python3.8/site-packages/datalad/distribution/dataset.py", line 567, in require_dataset
    raise ValueError(u"No installed dataset found at "
ValueError: No installed dataset found at /scratch1/03201/jbwexler/work_dir/fmriprep/ds000117_sub-11/fmriprep_wf/single_subject_11_wf/func_preproc_ses_mri_task_facerecognition_run_02_wf/unwarp_wf/resample/sourcedata/templateflow.
[INFO] Cloning dataset to Dataset(/scratch1/03201/jbwexler/work_dir/fmriprep/ds000117_sub-11/fmriprep_wf/single_subject_11_wf/func_preproc_ses_mri_task_facerecognition_run_03_wf/unwarp_wf/resample/sourcedata/templateflow) 
[INFO] Attempting to clone from https://github.com/templateflow/templateflow.git to /scratch1/03201/jbwexler/work_dir/fmriprep/ds000117_sub-11/fmriprep_wf/single_subject_11_wf/func_preproc_ses_mri_task_facerecognition_run_03_wf/unwarp_wf/resample/sourcedata/templateflow 
Traceback (most recent call last):
  File "/opt/conda/lib/python3.8/multiprocessing/forkserver.py", line 280, in main
    code = _serve_one(child_r, fds,
  File "/opt/conda/lib/python3.8/multiprocessing/forkserver.py", line 319, in _serve_one
    code = spawn._main(child_r, parent_sentinel)
  File "/opt/conda/lib/python3.8/multiprocessing/spawn.py", line 125, in _main
    prepare(preparation_data)
  File "/opt/conda/lib/python3.8/multiprocessing/spawn.py", line 236, in prepare
    _fixup_main_from_path(data['init_main_from_path'])
  File "/opt/conda/lib/python3.8/multiprocessing/spawn.py", line 287, in _fixup_main_from_path
    main_content = runpy.run_path(main_path,
  File "/opt/conda/lib/python3.8/runpy.py", line 265, in run_path
    return _run_module_code(code, init_globals, run_name,
  File "/opt/conda/lib/python3.8/runpy.py", line 97, in _run_module_code
    _run_code(code, mod_globals, init_globals,
  File "/opt/conda/lib/python3.8/runpy.py", line 87, in _run_code
    exec(code, run_globals)
  File "/opt/conda/bin/fmriprep", line 5, in <module>
    from fmriprep.cli.run import main
  File "/opt/conda/lib/python3.8/site-packages/fmriprep/cli/run.py", line 25, in <module>
    from .. import config
  File "/opt/conda/lib/python3.8/site-packages/fmriprep/config.py", line 116, in <module>
    from templateflow import __version__ as _tf_ver
  File "/opt/conda/lib/python3.8/site-packages/templateflow/__init__.py", line 19, in <module>
    from . import api
  File "/opt/conda/lib/python3.8/site-packages/templateflow/api.py", line 7, in <module>
    from .conf import TF_LAYOUT, TF_S3_ROOT, TF_USE_DATALAD, requires_layout
  File "/opt/conda/lib/python3.8/site-packages/templateflow/conf/__init__.py", line 53, in <module>
    install(path=str(TF_HOME), source=TF_GITHUB_SOURCE, recursive=True)
  File "/opt/conda/lib/python3.8/site-packages/datalad/interface/utils.py", line 484, in eval_func
    return return_func(generator_func)(*args, **kwargs)
  File "/opt/conda/lib/python3.8/site-packages/datalad/interface/utils.py", line 476, in return_func
    results = list(results)
  File "/opt/conda/lib/python3.8/site-packages/datalad/interface/utils.py", line 396, in generator_func
    for r in _process_results(
  File "/opt/conda/lib/python3.8/site-packages/datalad/interface/utils.py", line 579, in _process_results
    for res in results:
  File "/opt/conda/lib/python3.8/site-packages/datalad/distribution/install.py", line 381, in __call__
    for r in destination_dataset.get(
  File "/opt/conda/lib/python3.8/site-packages/datalad/interface/utils.py", line 396, in generator_func
    for r in _process_results(
  File "/opt/conda/lib/python3.8/site-packages/datalad/interface/utils.py", line 579, in _process_results
    for res in results:
  File "/opt/conda/lib/python3.8/site-packages/datalad/distribution/get.py", line 849, in __call__
    refds = require_dataset(
  File "/opt/conda/lib/python3.8/site-packages/datalad/distribution/dataset.py", line 567, in require_dataset
    raise ValueError(u"No installed dataset found at "
ValueError: No installed dataset found at /scratch1/03201/jbwexler/work_dir/fmriprep/ds000117_sub-11/fmriprep_wf/single_subject_11_wf/func_preproc_ses_mri_task_facerecognition_run_03_wf/unwarp_wf/resample/sourcedata/templateflow.
[INFO] Cloning dataset to Dataset(/scratch1/03201/jbwexler/work_dir/fmriprep/ds000117_sub-11/fmriprep_wf/single_subject_11_wf/func_preproc_ses_mri_task_facerecognition_run_04_wf/unwarp_wf/resample/sourcedata/templateflow) 
[INFO] Attempting to clone from https://github.com/templateflow/templateflow.git to /scratch1/03201/jbwexler/work_dir/fmriprep/ds000117_sub-11/fmriprep_wf/single_subject_11_wf/func_preproc_ses_mri_task_facerecognition_run_04_wf/unwarp_wf/resample/sourcedata/templateflow 
[INFO] Cloning dataset to Dataset(/scratch1/03201/jbwexler/work_dir/fmriprep/ds000117_sub-11/fmriprep_wf/single_subject_11_wf/func_preproc_ses_mri_task_facerecognition_run_04_wf/unwarp_wf/resample/sourcedata/templateflow) 
[INFO] Attempting to clone from https://github.com/templateflow/templateflow.git to /scratch1/03201/jbwexler/work_dir/fmriprep/ds000117_sub-11/fmriprep_wf/single_subject_11_wf/func_preproc_ses_mri_task_facerecognition_run_04_wf/unwarp_wf/resample/sourcedata/templateflow 
Traceback (most recent call last):
  File "/opt/conda/lib/python3.8/multiprocessing/forkserver.py", line 280, in main
    code = _serve_one(child_r, fds,
  File "/opt/conda/lib/python3.8/multiprocessing/forkserver.py", line 319, in _serve_one
    code = spawn._main(child_r, parent_sentinel)
  File "/opt/conda/lib/python3.8/multiprocessing/spawn.py", line 125, in _main
    prepare(preparation_data)
  File "/opt/conda/lib/python3.8/multiprocessing/spawn.py", line 236, in prepare
    _fixup_main_from_path(data['init_main_from_path'])
  File "/opt/conda/lib/python3.8/multiprocessing/spawn.py", line 287, in _fixup_main_from_path
    main_content = runpy.run_path(main_path,
  File "/opt/conda/lib/python3.8/runpy.py", line 265, in run_path
    return _run_module_code(code, init_globals, run_name,
  File "/opt/conda/lib/python3.8/runpy.py", line 97, in _run_module_code
    _run_code(code, mod_globals, init_globals,
  File "/opt/conda/lib/python3.8/runpy.py", line 87, in _run_code
    exec(code, run_globals)
  File "/opt/conda/bin/fmriprep", line 5, in <module>
    from fmriprep.cli.run import main
  File "/opt/conda/lib/python3.8/site-packages/fmriprep/cli/run.py", line 25, in <module>
    from .. import config
  File "/opt/conda/lib/python3.8/site-packages/fmriprep/config.py", line 116, in <module>
    from templateflow import __version__ as _tf_ver
  File "/opt/conda/lib/python3.8/site-packages/templateflow/__init__.py", line 19, in <module>
    from . import api
  File "/opt/conda/lib/python3.8/site-packages/templateflow/api.py", line 7, in <module>
    from .conf import TF_LAYOUT, TF_S3_ROOT, TF_USE_DATALAD, requires_layout
  File "/opt/conda/lib/python3.8/site-packages/templateflow/conf/__init__.py", line 53, in <module>
    install(path=str(TF_HOME), source=TF_GITHUB_SOURCE, recursive=True)
  File "/opt/conda/lib/python3.8/site-packages/datalad/interface/utils.py", line 484, in eval_func
    return return_func(generator_func)(*args, **kwargs)
  File "/opt/conda/lib/python3.8/site-packages/datalad/interface/utils.py", line 476, in return_func
    results = list(results)
  File "/opt/conda/lib/python3.8/site-packages/datalad/interface/utils.py", line 396, in generator_func
    for r in _process_results(
  File "/opt/conda/lib/python3.8/site-packages/datalad/interface/utils.py", line 579, in _process_results
    for res in results:
  File "/opt/conda/lib/python3.8/site-packages/datalad/distribution/install.py", line 365, in __call__
    for r in res:
  File "/opt/conda/lib/python3.8/site-packages/datalad/interface/utils.py", line 396, in generator_func
    for r in _process_results(
  File "/opt/conda/lib/python3.8/site-packages/datalad/interface/utils.py", line 579, in _process_results
    for res in results:
  File "/opt/conda/lib/python3.8/site-packages/datalad/core/distributed/clone.py", line 320, in __call__
    yield from clone_dataset(
  File "/opt/conda/lib/python3.8/site-packages/datalad/core/distributed/clone.py", line 589, in clone_dataset
    GitRepo.clone(
  File "/opt/conda/lib/python3.8/site-packages/datalad/support/gitrepo.py", line 949, in clone
    raise ValueError(
ValueError: destination path '/scratch1/03201/jbwexler/work_dir/fmriprep/ds000117_sub-11/fmriprep_wf/single_subject_11_wf/func_preproc_ses_mri_task_facerecognition_run_04_wf/unwarp_wf/resample/sourcedata/templateflow' already exists and is not an empty directory.
Traceback (most recent call last):
  File "/opt/conda/lib/python3.8/multiprocessing/forkserver.py", line 280, in main
    code = _serve_one(child_r, fds,
  File "/opt/conda/lib/python3.8/multiprocessing/forkserver.py", line 319, in _serve_one
    code = spawn._main(child_r, parent_sentinel)
  File "/opt/conda/lib/python3.8/multiprocessing/spawn.py", line 125, in _main
    prepare(preparation_data)
  File "/opt/conda/lib/python3.8/multiprocessing/spawn.py", line 236, in prepare
    _fixup_main_from_path(data['init_main_from_path'])
  File "/opt/conda/lib/python3.8/multiprocessing/spawn.py", line 287, in _fixup_main_from_path
    main_content = runpy.run_path(main_path,
  File "/opt/conda/lib/python3.8/runpy.py", line 265, in run_path
    return _run_module_code(code, init_globals, run_name,
  File "/opt/conda/lib/python3.8/runpy.py", line 97, in _run_module_code
    _run_code(code, mod_globals, init_globals,
  File "/opt/conda/lib/python3.8/runpy.py", line 87, in _run_code
    exec(code, run_globals)
  File "/opt/conda/bin/fmriprep", line 5, in <module>
    from fmriprep.cli.run import main
  File "/opt/conda/lib/python3.8/site-packages/fmriprep/cli/run.py", line 25, in <module>
    from .. import config
  File "/opt/conda/lib/python3.8/site-packages/fmriprep/config.py", line 116, in <module>
    from templateflow import __version__ as _tf_ver
  File "/opt/conda/lib/python3.8/site-packages/templateflow/__init__.py", line 19, in <module>
    from . import api
  File "/opt/conda/lib/python3.8/site-packages/templateflow/api.py", line 7, in <module>
    from .conf import TF_LAYOUT, TF_S3_ROOT, TF_USE_DATALAD, requires_layout
  File "/opt/conda/lib/python3.8/site-packages/templateflow/conf/__init__.py", line 53, in <module>
    install(path=str(TF_HOME), source=TF_GITHUB_SOURCE, recursive=True)
  File "/opt/conda/lib/python3.8/site-packages/datalad/interface/utils.py", line 484, in eval_func
    return return_func(generator_func)(*args, **kwargs)
  File "/opt/conda/lib/python3.8/site-packages/datalad/interface/utils.py", line 476, in return_func
    results = list(results)
  File "/opt/conda/lib/python3.8/site-packages/datalad/interface/utils.py", line 396, in generator_func
    for r in _process_results(
  File "/opt/conda/lib/python3.8/site-packages/datalad/interface/utils.py", line 579, in _process_results
    for res in results:
  File "/opt/conda/lib/python3.8/site-packages/datalad/distribution/install.py", line 381, in __call__
    for r in destination_dataset.get(
  File "/opt/conda/lib/python3.8/site-packages/datalad/interface/utils.py", line 396, in generator_func
    for r in _process_results(
  File "/opt/conda/lib/python3.8/site-packages/datalad/interface/utils.py", line 579, in _process_results
    for res in results:
  File "/opt/conda/lib/python3.8/site-packages/datalad/distribution/get.py", line 849, in __call__
    refds = require_dataset(
  File "/opt/conda/lib/python3.8/site-packages/datalad/distribution/dataset.py", line 567, in require_dataset
    raise ValueError(u"No installed dataset found at "
ValueError: No installed dataset found at /scratch1/03201/jbwexler/work_dir/fmriprep/ds000117_sub-11/fmriprep_wf/single_subject_11_wf/func_preproc_ses_mri_task_facerecognition_run_04_wf/unwarp_wf/resample/sourcedata/templateflow.
Traceback (most recent call last):
  File "/opt/conda/lib/python3.8/multiprocessing/forkserver.py", line 280, in main
    code = _serve_one(child_r, fds,Traceback (most recent call last):

  File "/opt/conda/lib/python3.8/multiprocessing/forkserver.py", line 319, in _serve_one
  File "/opt/conda/lib/python3.8/multiprocessing/forkserver.py", line 280, in main
    code = spawn._main(child_r, parent_sentinel)
  File "/opt/conda/lib/python3.8/multiprocessing/spawn.py", line 125, in _main
    prepare(preparation_data)
  File "/opt/conda/lib/python3.8/multiprocessing/spawn.py", line 236, in prepare
    code = _serve_one(child_r, fds,
  File "/opt/conda/lib/python3.8/multiprocessing/forkserver.py", line 319, in _serve_one
    _fixup_main_from_path(data['init_main_from_path'])
  File "/opt/conda/lib/python3.8/multiprocessing/spawn.py", line 287, in _fixup_main_from_path
    code = spawn._main(child_r, parent_sentinel)
  File "/opt/conda/lib/python3.8/multiprocessing/spawn.py", line 125, in _main
    main_content = runpy.run_path(main_path,
  File "/opt/conda/lib/python3.8/runpy.py", line 265, in run_path
    prepare(preparation_data)
  File "/opt/conda/lib/python3.8/multiprocessing/spawn.py", line 236, in prepare
    return _run_module_code(code, init_globals, run_name,
  File "/opt/conda/lib/python3.8/runpy.py", line 97, in _run_module_code
    _fixup_main_from_path(data['init_main_from_path'])
  File "/opt/conda/lib/python3.8/multiprocessing/spawn.py", line 287, in _fixup_main_from_path
    _run_code(code, mod_globals, init_globals,
  File "/opt/conda/lib/python3.8/runpy.py", line 87, in _run_code
        main_content = runpy.run_path(main_path,exec(code, run_globals)

  File "/opt/conda/lib/python3.8/runpy.py", line 265, in run_path
  File "/opt/conda/bin/fmriprep", line 5, in <module>
    from fmriprep.cli.run import main
  File "/opt/conda/lib/python3.8/site-packages/fmriprep/cli/run.py", line 25, in <module>
    return _run_module_code(code, init_globals, run_name,
      File "/opt/conda/lib/python3.8/runpy.py", line 97, in _run_module_code
from .. import config
  File "/opt/conda/lib/python3.8/site-packages/fmriprep/config.py", line 116, in <module>
    _run_code(code, mod_globals, init_globals,    
from templateflow import __version__ as _tf_ver
  File "/opt/conda/lib/python3.8/runpy.py", line 87, in _run_code
  File "/opt/conda/lib/python3.8/site-packages/templateflow/__init__.py", line 19, in <module>
    from . import api    
exec(code, run_globals)  File "/opt/conda/lib/python3.8/site-packages/templateflow/api.py", line 7, in <module>

  File "/opt/conda/bin/fmriprep", line 5, in <module>
    from .conf import TF_LAYOUT, TF_S3_ROOT, TF_USE_DATALAD, requires_layout    
from fmriprep.cli.run import main
  File "/opt/conda/lib/python3.8/site-packages/templateflow/conf/__init__.py", line 53, in <module>
  File "/opt/conda/lib/python3.8/site-packages/fmriprep/cli/run.py", line 25, in <module>
    install(path=str(TF_HOME), source=TF_GITHUB_SOURCE, recursive=True)
      File "/opt/conda/lib/python3.8/site-packages/datalad/interface/utils.py", line 484, in eval_func
from .. import config
  File "/opt/conda/lib/python3.8/site-packages/fmriprep/config.py", line 116, in <module>
    from templateflow import __version__ as _tf_ver
  File "/opt/conda/lib/python3.8/site-packages/templateflow/__init__.py", line 19, in <module>
    return return_func(generator_func)(*args, **kwargs)
  File "/opt/conda/lib/python3.8/site-packages/datalad/interface/utils.py", line 476, in return_func
    from . import api
  File "/opt/conda/lib/python3.8/site-packages/templateflow/api.py", line 7, in <module>
    from .conf import TF_LAYOUT, TF_S3_ROOT, TF_USE_DATALAD, requires_layout
  File "/opt/conda/lib/python3.8/site-packages/templateflow/conf/__init__.py", line 53, in <module>
    results = list(results)    
install(path=str(TF_HOME), source=TF_GITHUB_SOURCE, recursive=True)
  File "/opt/conda/lib/python3.8/site-packages/datalad/interface/utils.py", line 396, in generator_func
  File "/opt/conda/lib/python3.8/site-packages/datalad/interface/utils.py", line 484, in eval_func
    for r in _process_results(
  File "/opt/conda/lib/python3.8/site-packages/datalad/interface/utils.py", line 579, in _process_results
    return return_func(generator_func)(*args, **kwargs)
  File "/opt/conda/lib/python3.8/site-packages/datalad/interface/utils.py", line 476, in return_func
    for res in results:
  File "/opt/conda/lib/python3.8/site-packages/datalad/distribution/install.py", line 381, in __call__
    results = list(results)
  File "/opt/conda/lib/python3.8/site-packages/datalad/interface/utils.py", line 396, in generator_func
    for r in destination_dataset.get(
  File "/opt/conda/lib/python3.8/site-packages/datalad/interface/utils.py", line 396, in generator_func
    for r in _process_results(
  File "/opt/conda/lib/python3.8/site-packages/datalad/interface/utils.py", line 579, in _process_results
    for r in _process_results(
  File "/opt/conda/lib/python3.8/site-packages/datalad/interface/utils.py", line 579, in _process_results
    for res in results:
  File "/opt/conda/lib/python3.8/site-packages/datalad/distribution/install.py", line 381, in __call__
    for res in results:
  File "/opt/conda/lib/python3.8/site-packages/datalad/distribution/get.py", line 849, in __call__
    for r in destination_dataset.get(
  File "/opt/conda/lib/python3.8/site-packages/datalad/interface/utils.py", line 396, in generator_func
    for r in _process_results(
  File "/opt/conda/lib/python3.8/site-packages/datalad/interface/utils.py", line 579, in _process_results
    refds = require_dataset(
  File "/opt/conda/lib/python3.8/site-packages/datalad/distribution/dataset.py", line 567, in require_dataset
    for res in results:
  File "/opt/conda/lib/python3.8/site-packages/datalad/distribution/get.py", line 849, in __call__
    raise ValueError(u"No installed dataset found at "
ValueError: No installed dataset found at /scratch1/03201/jbwexler/work_dir/fmriprep/ds000117_sub-11/fmriprep_wf/single_subject_11_wf/func_preproc_ses_mri_task_facerecognition_run_04_wf/unwarp_wf/resample/sourcedata/templateflow.
    refds = require_dataset(
  File "/opt/conda/lib/python3.8/site-packages/datalad/distribution/dataset.py", line 567, in require_dataset
    raise ValueError(u"No installed dataset found at "
ValueError: No installed dataset found at /scratch1/03201/jbwexler/work_dir/fmriprep/ds000117_sub-11/fmriprep_wf/single_subject_11_wf/func_preproc_ses_mri_task_facerecognition_run_04_wf/unwarp_wf/resample/sourcedata/templateflow.
[INFO] Cloning dataset to Dataset(/scratch1/03201/jbwexler/work_dir/fmriprep/ds000117_sub-11/fmriprep_wf/single_subject_11_wf/func_preproc_ses_mri_task_facerecognition_run_05_wf/unwarp_wf/resample/sourcedata/templateflow) 
[INFO] Attempting to clone from https://github.com/templateflow/templateflow.git to /scratch1/03201/jbwexler/work_dir/fmriprep/ds000117_sub-11/fmriprep_wf/single_subject_11_wf/func_preproc_ses_mri_task_facerecognition_run_05_wf/unwarp_wf/resample/sourcedata/templateflow 
[INFO] Installing Dataset(/scratch1/03201/jbwexler/work_dir/fmriprep/ds000117_sub-11/fmriprep_wf/single_subject_11_wf/func_preproc_ses_mri_task_facerecognition_run_05_wf/unwarp_wf/resample/sourcedata/templateflow) to get /scratch1/03201/jbwexler/work_dir/fmriprep/ds000117_sub-11/fmriprep_wf/single_subject_11_wf/func_preproc_ses_mri_task_facerecognition_run_05_wf/unwarp_wf/resample/sourcedata/templateflow recursively 
[INFO] Installing Dataset(/scratch1/03201/jbwexler/work_dir/fmriprep/ds000117_sub-11/fmriprep_wf/single_subject_11_wf/func_preproc_ses_mri_task_facerecognition_run_05_wf/unwarp_wf/resample/sourcedata/templateflow) to get /scratch1/03201/jbwexler/work_dir/fmriprep/ds000117_sub-11/fmriprep_wf/single_subject_11_wf/func_preproc_ses_mri_task_facerecognition_run_05_wf/unwarp_wf/resample/sourcedata/templateflow recursively 
[INFO] Installing Dataset(/scratch1/03201/jbwexler/work_dir/fmriprep/ds000117_sub-11/fmriprep_wf/single_subject_11_wf/func_preproc_ses_mri_task_facerecognition_run_05_wf/unwarp_wf/resample/sourcedata/templateflow) to get /scratch1/03201/jbwexler/work_dir/fmriprep/ds000117_sub-11/fmriprep_wf/single_subject_11_wf/func_preproc_ses_mri_task_facerecognition_run_05_wf/unwarp_wf/resample/sourcedata/templateflow recursively 
[INFO] Installing Dataset(/scratch1/03201/jbwexler/work_dir/fmriprep/ds000117_sub-11/fmriprep_wf/single_subject_11_wf/func_preproc_ses_mri_task_facerecognition_run_05_wf/unwarp_wf/resample/sourcedata/templateflow) to get /scratch1/03201/jbwexler/work_dir/fmriprep/ds000117_sub-11/fmriprep_wf/single_subject_11_wf/func_preproc_ses_mri_task_facerecognition_run_05_wf/unwarp_wf/resample/sourcedata/templateflow recursively 
[INFO] Installing Dataset(/scratch1/03201/jbwexler/work_dir/fmriprep/ds000117_sub-11/fmriprep_wf/single_subject_11_wf/func_preproc_ses_mri_task_facerecognition_run_05_wf/unwarp_wf/resample/sourcedata/templateflow) to get /scratch1/03201/jbwexler/work_dir/fmriprep/ds000117_sub-11/fmriprep_wf/single_subject_11_wf/func_preproc_ses_mri_task_facerecognition_run_05_wf/unwarp_wf/resample/sourcedata/templateflow recursively 
Traceback (most recent call last):
  File "/opt/conda/lib/python3.8/multiprocessing/forkserver.py", line 280, in main
    code = _serve_one(child_r, fds,
  File "/opt/conda/lib/python3.8/multiprocessing/forkserver.py", line 319, in _serve_one
    code = spawn._main(child_r, parent_sentinel)
  File "/opt/conda/lib/python3.8/multiprocessing/spawn.py", line 125, in _main
    prepare(preparation_data)
  File "/opt/conda/lib/python3.8/multiprocessing/spawn.py", line 236, in prepare
    _fixup_main_from_path(data['init_main_from_path'])
  File "/opt/conda/lib/python3.8/multiprocessing/spawn.py", line 287, in _fixup_main_from_path
    main_content = runpy.run_path(main_path,
  File "/opt/conda/lib/python3.8/runpy.py", line 265, in run_path
    return _run_module_code(code, init_globals, run_name,
  File "/opt/conda/lib/python3.8/runpy.py", line 97, in _run_module_code
    _run_code(code, mod_globals, init_globals,
  File "/opt/conda/lib/python3.8/runpy.py", line 87, in _run_code
    exec(code, run_globals)
  File "/opt/conda/bin/fmriprep", line 5, in <module>
    from fmriprep.cli.run import main
  File "/opt/conda/lib/python3.8/site-packages/fmriprep/cli/run.py", line 25, in <module>
    from .. import config
  File "/opt/conda/lib/python3.8/site-packages/fmriprep/config.py", line 116, in <module>
    from templateflow import __version__ as _tf_ver
  File "/opt/conda/lib/python3.8/site-packages/templateflow/__init__.py", line 19, in <module>
    from . import api
  File "/opt/conda/lib/python3.8/site-packages/templateflow/api.py", line 7, in <module>
    from .conf import TF_LAYOUT, TF_S3_ROOT, TF_USE_DATALAD, requires_layout
  File "/opt/conda/lib/python3.8/site-packages/templateflow/conf/__init__.py", line 53, in <module>
    install(path=str(TF_HOME), source=TF_GITHUB_SOURCE, recursive=True)
  File "/opt/conda/lib/python3.8/site-packages/datalad/interface/utils.py", line 484, in eval_func
    return return_func(generator_func)(*args, **kwargs)
  File "/opt/conda/lib/python3.8/site-packages/datalad/interface/utils.py", line 476, in return_func
    results = list(results)
  File "/opt/conda/lib/python3.8/site-packages/datalad/interface/utils.py", line 461, in generator_func
    raise IncompleteResultsError(
datalad.support.exceptions.IncompleteResultsError: Command did not complete successfully. 1 failed:
[{'action': 'install',
  'message': 'target path already exists and not empty, refuse to clone into '
             'target path',
  'path': '/scratch1/03201/jbwexler/work_dir/fmriprep/ds000117_sub-11/fmriprep_wf/single_subject_11_wf/func_preproc_ses_mri_task_facerecognition_run_05_wf/unwarp_wf/resample/sourcedata/templateflow',
  'refds': None,
  'source_url': 'https://github.com/templateflow/templateflow.git',
  'status': 'error',
  'type': 'dataset'}]
Traceback (most recent call last):
  File "/opt/conda/lib/python3.8/multiprocessing/forkserver.py", line 280, in main
    code = _serve_one(child_r, fds,
  File "/opt/conda/lib/python3.8/multiprocessing/forkserver.py", line 319, in _serve_one
    code = spawn._main(child_r, parent_sentinel)
  File "/opt/conda/lib/python3.8/multiprocessing/spawn.py", line 125, in _main
    prepare(preparation_data)
  File "/opt/conda/lib/python3.8/multiprocessing/spawn.py", line 236, in prepare
    _fixup_main_from_path(data['init_main_from_path'])
  File "/opt/conda/lib/python3.8/multiprocessing/spawn.py", line 287, in _fixup_main_from_path
    main_content = runpy.run_path(main_path,
  File "/opt/conda/lib/python3.8/runpy.py", line 265, in run_path
    return _run_module_code(code, init_globals, run_name,
  File "/opt/conda/lib/python3.8/runpy.py", line 97, in _run_module_code
    _run_code(code, mod_globals, init_globals,
  File "/opt/conda/lib/python3.8/runpy.py", line 87, in _run_code
    exec(code, run_globals)
  File "/opt/conda/bin/fmriprep", line 5, in <module>
    from fmriprep.cli.run import main
  File "/opt/conda/lib/python3.8/site-packages/fmriprep/cli/run.py", line 25, in <module>
    from .. import config
  File "/opt/conda/lib/python3.8/site-packages/fmriprep/config.py", line 116, in <module>
    from templateflow import __version__ as _tf_ver
  File "/opt/conda/lib/python3.8/site-packages/templateflow/__init__.py", line 19, in <module>
    from . import api
  File "/opt/conda/lib/python3.8/site-packages/templateflow/api.py", line 7, in <module>
    from .conf import TF_LAYOUT, TF_S3_ROOT, TF_USE_DATALAD, requires_layout
  File "/opt/conda/lib/python3.8/site-packages/templateflow/conf/__init__.py", line 53, in <module>
    install(path=str(TF_HOME), source=TF_GITHUB_SOURCE, recursive=True)
  File "/opt/conda/lib/python3.8/site-packages/datalad/interface/utils.py", line 484, in eval_func
    return return_func(generator_func)(*args, **kwargs)
  File "/opt/conda/lib/python3.8/site-packages/datalad/interface/utils.py", line 476, in return_func
    results = list(results)
  File "/opt/conda/lib/python3.8/site-packages/datalad/interface/utils.py", line 461, in generator_func
    raise IncompleteResultsError(
datalad.support.exceptions.IncompleteResultsErrorTraceback (most recent call last):
  File "/opt/conda/lib/python3.8/multiprocessing/forkserver.py", line 280, in main
    code = _serve_one(child_r, fds,
  File "/opt/conda/lib/python3.8/multiprocessing/forkserver.py", line 319, in _serve_one
    code = spawn._main(child_r, parent_sentinel)
  File "/opt/conda/lib/python3.8/multiprocessing/spawn.py", line 125, in _main
: Command did not complete successfully. 1 failed:
[{'action': 'install',
  'message': 'target path already exists and not empty, refuse to clone into '
             'target path',
  'path': '/scratch1/03201/jbwexler/work_dir/fmriprep/ds000117_sub-11/fmriprep_wf/single_subject_11_wf/func_preproc_ses_mri_task_facerecognition_run_05_wf/unwarp_wf/resample/sourcedata/templateflow',
  'refds': None,
  'source_url': 'https://github.com/templateflow/templateflow.git',
  'status': 'error',
  'type': 'dataset'}]
    prepare(preparation_data)
  File "/opt/conda/lib/python3.8/multiprocessing/spawn.py", line 236, in prepare
    _fixup_main_from_path(data['init_main_from_path'])
  File "/opt/conda/lib/python3.8/multiprocessing/spawn.py", line 287, in _fixup_main_from_path
    main_content = runpy.run_path(main_path,
  File "/opt/conda/lib/python3.8/runpy.py", line 265, in run_path
    return _run_module_code(code, init_globals, run_name,
  File "/opt/conda/lib/python3.8/runpy.py", line 97, in _run_module_code
    _run_code(code, mod_globals, init_globals,
  File "/opt/conda/lib/python3.8/runpy.py", line 87, in _run_code
    exec(code, run_globals)
  File "/opt/conda/bin/fmriprep", line 5, in <module>
    from fmriprep.cli.run import main
  File "/opt/conda/lib/python3.8/site-packages/fmriprep/cli/run.py", line 25, in <module>
    from .. import config
  File "/opt/conda/lib/python3.8/site-packages/fmriprep/config.py", line 116, in <module>
[INFO] Cloning dataset to Dataset(/scratch1/03201/jbwexler/work_dir/fmriprep/ds000117_sub-11/fmriprep_wf/single_subject_11_wf/func_preproc_ses_mri_task_facerecognition_run_06_wf/unwarp_wf/resample/sourcedata/templateflow) 
[INFO] Attempting to clone from https://github.com/templateflow/templateflow.git to /scratch1/03201/jbwexler/work_dir/fmriprep/ds000117_sub-11/fmriprep_wf/single_subject_11_wf/func_preproc_ses_mri_task_facerecognition_run_06_wf/unwarp_wf/resample/sourcedata/templateflow 
[INFO] Installing Dataset(/scratch1/03201/jbwexler/work_dir/fmriprep/ds000117_sub-11/fmriprep_wf/single_subject_11_wf/func_preproc_ses_mri_task_facerecognition_run_06_wf/unwarp_wf/resample/sourcedata/templateflow) to get /scratch1/03201/jbwexler/work_dir/fmriprep/ds000117_sub-11/fmriprep_wf/single_subject_11_wf/func_preproc_ses_mri_task_facerecognition_run_06_wf/unwarp_wf/resample/sourcedata/templateflow recursively 
[INFO] Installing Dataset(/scratch1/03201/jbwexler/work_dir/fmriprep/ds000117_sub-11/fmriprep_wf/single_subject_11_wf/func_preproc_ses_mri_task_facerecognition_run_06_wf/unwarp_wf/resample/sourcedata/templateflow) to get /scratch1/03201/jbwexler/work_dir/fmriprep/ds000117_sub-11/fmriprep_wf/single_subject_11_wf/func_preproc_ses_mri_task_facerecognition_run_06_wf/unwarp_wf/resample/sourcedata/templateflow recursively 
[INFO] Installing Dataset(/scratch1/03201/jbwexler/work_dir/fmriprep/ds000117_sub-11/fmriprep_wf/single_subject_11_wf/func_preproc_ses_mri_task_facerecognition_run_06_wf/unwarp_wf/resample/sourcedata/templateflow) to get /scratch1/03201/jbwexler/work_dir/fmriprep/ds000117_sub-11/fmriprep_wf/single_subject_11_wf/func_preproc_ses_mri_task_facerecognition_run_06_wf/unwarp_wf/resample/sourcedata/templateflow recursively 
[INFO] Installing Dataset(/scratch1/03201/jbwexler/work_dir/fmriprep/ds000117_sub-11/fmriprep_wf/single_subject_11_wf/func_preproc_ses_mri_task_facerecognition_run_06_wf/unwarp_wf/resample/sourcedata/templateflow) to get /scratch1/03201/jbwexler/work_dir/fmriprep/ds000117_sub-11/fmriprep_wf/single_subject_11_wf/func_preproc_ses_mri_task_facerecognition_run_06_wf/unwarp_wf/resample/sourcedata/templateflow recursively 
[INFO] Installing Dataset(/scratch1/03201/jbwexler/work_dir/fmriprep/ds000117_sub-11/fmriprep_wf/single_subject_11_wf/func_preproc_ses_mri_task_facerecognition_run_06_wf/unwarp_wf/resample/sourcedata/templateflow) to get /scratch1/03201/jbwexler/work_dir/fmriprep/ds000117_sub-11/fmriprep_wf/single_subject_11_wf/func_preproc_ses_mri_task_facerecognition_run_06_wf/unwarp_wf/resample/sourcedata/templateflow recursively 
[INFO] Installing Dataset(/scratch1/03201/jbwexler/work_dir/fmriprep/ds000117_sub-11/fmriprep_wf/single_subject_11_wf/func_preproc_ses_mri_task_facerecognition_run_06_wf/unwarp_wf/resample/sourcedata/templateflow) to get /scratch1/03201/jbwexler/work_dir/fmriprep/ds000117_sub-11/fmriprep_wf/single_subject_11_wf/func_preproc_ses_mri_task_facerecognition_run_06_wf/unwarp_wf/resample/sourcedata/templateflow recursively 
Traceback (most recent call last):
  File "/opt/conda/lib/python3.8/multiprocessing/forkserver.py", line 280, in main
    code = _serve_one(child_r, fds,
  File "/opt/conda/lib/python3.8/multiprocessing/forkserver.py", line 319, in _serve_one
    code = spawn._main(child_r, parent_sentinel)
  File "/opt/conda/lib/python3.8/multiprocessing/spawn.py", line 125, in _main
    prepare(preparation_data)
  File "/opt/conda/lib/python3.8/multiprocessing/spawn.py", line 236, in prepare
    _fixup_main_from_path(data['init_main_from_path'])
  File "/opt/conda/lib/python3.8/multiprocessing/spawn.py", line 287, in _fixup_main_from_path
    main_content = runpy.run_path(main_path,
  File "/opt/conda/lib/python3.8/runpy.py", line 265, in run_path
    return _run_module_code(code, init_globals, run_name,
  File "/opt/conda/lib/python3.8/runpy.py", line 97, in _run_module_code
    _run_code(code, mod_globals, init_globals,
  File "/opt/conda/lib/python3.8/runpy.py", line 87, in _run_code
    exec(code, run_globals)
  File "/opt/conda/bin/fmriprep", line 5, in <module>
    from fmriprep.cli.run import main
  File "/opt/conda/lib/python3.8/site-packages/fmriprep/cli/run.py", line 25, in <module>
    from .. import config
  File "/opt/conda/lib/python3.8/site-packages/fmriprep/config.py", line 116, in <module>
    from templateflow import __version__ as _tf_ver
  File "/opt/conda/lib/python3.8/site-packages/templateflow/__init__.py", line 19, in <module>
    from . import api
  File "/opt/conda/lib/python3.8/site-packages/templateflow/api.py", line 7, in <module>
    from .conf import TF_LAYOUT, TF_S3_ROOT, TF_USE_DATALAD, requires_layout
  File "/opt/conda/lib/python3.8/site-packages/templateflow/conf/__init__.py", line 53, in <module>
    install(path=str(TF_HOME), source=TF_GITHUB_SOURCE, recursive=True)
  File "/opt/conda/lib/python3.8/site-packages/datalad/interface/utils.py", line 484, in eval_func
    return return_func(generator_func)(*args, **kwargs)
  File "/opt/conda/lib/python3.8/site-packages/datalad/interface/utils.py", line 476, in return_func
    results = list(results)
  File "/opt/conda/lib/python3.8/site-packages/datalad/interface/utils.py", line 461, in generator_func
    raise IncompleteResultsError(
datalad.support.exceptions.IncompleteResultsError: Command did not complete successfully. 1 failed:
[{'action': 'install',
  'message': 'target path already exists and not empty, refuse to clone into '
             'target path',
  'path': '/scratch1/03201/jbwexler/work_dir/fmriprep/ds000117_sub-11/fmriprep_wf/single_subject_11_wf/func_preproc_ses_mri_task_facerecognition_run_06_wf/unwarp_wf/resample/sourcedata/templateflow',
  'refds': None,
  'source_url': 'https://github.com/templateflow/templateflow.git',
  'status': 'error',
  'type': 'dataset'}]
Traceback (most recent call last):
  File "/opt/conda/lib/python3.8/multiprocessing/forkserver.py", line 280, in main
    code = _serve_one(child_r, fds,
  File "/opt/conda/lib/python3.8/multiprocessing/forkserver.py", line 319, in _serve_one
    code = spawn._main(child_r, parent_sentinel)
  File "/opt/conda/lib/python3.8/multiprocessing/spawn.py", line 125, in _main
    prepare(preparation_data)
  File "/opt/conda/lib/python3.8/multiprocessing/spawn.py", line 236, in prepare
    _fixup_main_from_path(data['init_main_from_path'])
  File "/opt/conda/lib/python3.8/multiprocessing/spawn.py", line 287, in _fixup_main_from_path
    main_content = runpy.run_path(main_path,
  File "/opt/conda/lib/python3.8/runpy.py", line 265, in run_path
    Traceback (most recent call last):
return _run_module_code(code, init_globals, run_name,
  File "/opt/conda/lib/python3.8/runpy.py", line 97, in _run_module_code
  File "/opt/conda/lib/python3.8/multiprocessing/forkserver.py", line 280, in main
    _run_code(code, mod_globals, init_globals,
  File "/opt/conda/lib/python3.8/runpy.py", line 87, in _run_code
    exec(code, run_globals)
  File "/opt/conda/bin/fmriprep", line 5, in <module>
    from fmriprep.cli.run import main
  File "/opt/conda/lib/python3.8/site-packages/fmriprep/cli/run.py", line 25, in <module>
    code = _serve_one(child_r, fds,
      File "/opt/conda/lib/python3.8/multiprocessing/forkserver.py", line 319, in _serve_one
from .. import config
  File "/opt/conda/lib/python3.8/site-packages/fmriprep/config.py", line 116, in <module>
    code = spawn._main(child_r, parent_sentinel)    
from templateflow import __version__ as _tf_ver
  File "/opt/conda/lib/python3.8/multiprocessing/spawn.py", line 125, in _main
  File "/opt/conda/lib/python3.8/site-packages/templateflow/__init__.py", line 19, in <module>
    from . import api
      File "/opt/conda/lib/python3.8/site-packages/templateflow/api.py", line 7, in <module>
prepare(preparation_data)
  File "/opt/conda/lib/python3.8/multiprocessing/spawn.py", line 236, in prepare
    from .conf import TF_LAYOUT, TF_S3_ROOT, TF_USE_DATALAD, requires_layout
  File "/opt/conda/lib/python3.8/site-packages/templateflow/conf/__init__.py", line 53, in <module>
    _fixup_main_from_path(data['init_main_from_path'])
      File "/opt/conda/lib/python3.8/multiprocessing/spawn.py", line 287, in _fixup_main_from_path
install(path=str(TF_HOME), source=TF_GITHUB_SOURCE, recursive=True)
  File "/opt/conda/lib/python3.8/site-packages/datalad/interface/utils.py", line 484, in eval_func
    main_content = runpy.run_path(main_path,
  File "/opt/conda/lib/python3.8/runpy.py", line 265, in run_path
    return return_func(generator_func)(*args, **kwargs)
  File "/opt/conda/lib/python3.8/site-packages/datalad/interface/utils.py", line 476, in return_func
    return _run_module_code(code, init_globals, run_name,
  File "/opt/conda/lib/python3.8/runpy.py", line 97, in _run_module_code
    _run_code(code, mod_globals, init_globals,
  File "/opt/conda/lib/python3.8/runpy.py", line 87, in _run_code
    results = list(results)
  File "/opt/conda/lib/python3.8/site-packages/datalad/interface/utils.py", line 461, in generator_func
    exec(code, run_globals)
  File "/opt/conda/bin/fmriprep", line 5, in <module>
    from fmriprep.cli.run import main
  File "/opt/conda/lib/python3.8/site-packages/fmriprep/cli/run.py", line 25, in <module>
    raise IncompleteResultsError(
datalad.support.exceptions.    IncompleteResultsErrorfrom .. import config
  File "/opt/conda/lib/python3.8/site-packages/fmriprep/config.py", line 116, in <module>
    from templateflow import __version__ as _tf_ver
  File "/opt/conda/lib/python3.8/site-packages/templateflow/__init__.py", line 19, in <module>
    from . import api
  File "/opt/conda/lib/python3.8/site-packages/templateflow/api.py", line 7, in <module>
    from .conf import TF_LAYOUT, TF_S3_ROOT, TF_USE_DATALAD, requires_layout
  File "/opt/conda/lib/python3.8/site-packages/templateflow/conf/__init__.py", line 53, in <module>
    install(path=str(TF_HOME), source=TF_GITHUB_SOURCE, recursive=True)
  File "/opt/conda/lib/python3.8/site-packages/datalad/interface/utils.py", line 484, in eval_func
    return return_func(generator_func)(*args, **kwargs)
  File "/opt/conda/lib/python3.8/site-packages/datalad/interface/utils.py", line 476, in return_func
    results = list(results): 
  File "/opt/conda/lib/python3.8/site-packages/datalad/interface/utils.py", line 461, in generator_func
Command did not complete successfully. 1 failed:
[{'action': 'install',
  'message': 'target path already exists and not empty, refuse to clone into '
             'target path',
  'path': '/scratch1/03201/jbwexler/work_dir/fmriprep/ds000117_sub-11/fmriprep_wf/single_subject_11_wf/func_preproc_ses_mri_task_facerecognition_run_06_wf/unwarp_wf/resample/sourcedata/templateflow',
  'refds': None,
  'source_url': 'https://github.com/templateflow/templateflow.git',
  'status': 'error',
  'type': 'dataset'}]
    raise IncompleteResultsError(
datalad.support.exceptions.IncompleteResultsError: Command did not complete successfully. 1 failed:
[{'action': 'install',
  'message': 'target path already exists and not empty, refuse to clone into '
             'target path',
  'path': '/scratch1/03201/jbwexler/work_dir/fmriprep/ds000117_sub-11/fmriprep_wf/single_subject_11_wf/func_preproc_ses_mri_task_facerecognition_run_06_wf/unwarp_wf/resample/sourcedata/templateflow',
  'refds': None,
  'source_url': 'https://github.com/templateflow/templateflow.git',
  'status': 'error',
  'type': 'dataset'}]
Traceback (most recent call last):
  File "/opt/conda/lib/python3.8/multiprocessing/forkserver.py", line 280, in main
    code = _serve_one(child_r, fds,
  File "/opt/conda/lib/python3.8/multiprocessing/forkserver.py", line 319, in _serve_one
    code = spawn._main(child_r, parent_sentinel)
  File "/opt/conda/lib/python3.8/multiprocessing/spawn.py", line 125, in _main
    prepare(preparation_data)
  File "/opt/conda/lib/python3.8/multiprocessing/spawn.py", line 236, in prepare
    _fixup_main_from_path(data['init_main_from_path'])
  File "/opt/conda/lib/python3.8/multiprocessing/spawn.py", line 287, in _fixup_main_from_path
    main_content = runpy.run_path(main_path,
  File "/opt/conda/lib/python3.8/runpy.py", line 265, in run_path
    return _run_module_code(code, init_globals, run_name,
  File "/opt/conda/lib/python3.8/runpy.py", line 97, in _run_module_code
    _run_code(code, mod_globals, init_globals,
  File "/opt/conda/lib/python3.8/runpy.py", line 87, in _run_code
    exec(code, run_globals)
  File "/opt/conda/bin/fmriprep", line 5, in <module>
    from fmriprep.cli.run import main
  File "/opt/conda/lib/python3.8/site-packages/fmriprep/cli/run.py", line 25, in <module>
    from .. import config
  File "/opt/conda/lib/python3.8/site-packages/fmriprep/config.py", line 116, in <module>
    from templateflow import __version__ as _tf_ver
  File "/opt/conda/lib/python3.8/site-packages/templateflow/__init__.py", line 19, in <module>
    from . import api
  File "/opt/conda/lib/python3.8/site-packages/templateflow/api.py", line 7, in <module>
    from .conf import TF_LAYOUT, TF_S3_ROOT, TF_USE_DATALAD, requires_layout
  File "/opt/conda/lib/python3.8/site-packages/templateflow/conf/__init__.py", line 53, in <module>
    install(path=str(TF_HOME), source=TF_GITHUB_SOURCE, recursive=True)
  File "/opt/conda/lib/python3.8/site-packages/datalad/interface/utils.py", line 484, in eval_func
    Traceback (most recent call last):
return return_func(generator_func)(*args, **kwargs)
  File "/opt/conda/lib/python3.8/site-packages/datalad/interface/utils.py", line 476, in return_func
  File "/opt/conda/lib/python3.8/multiprocessing/forkserver.py", line 280, in main
    results = list(results)
  File "/opt/conda/lib/python3.8/site-packages/datalad/interface/utils.py", line 461, in generator_func
    code = _serve_one(child_r, fds,
  File "/opt/conda/lib/python3.8/multiprocessing/forkserver.py", line 319, in _serve_one
    raise IncompleteResultsError(
datalad.support.exceptions.IncompleteResultsError    code = spawn._main(child_r, parent_sentinel)
  File "/opt/conda/lib/python3.8/multiprocessing/spawn.py", line 125, in _main
    prepare(preparation_data)
  File "/opt/conda/lib/python3.8/multiprocessing/spawn.py", line 236, in prepare
    _fixup_main_from_path(data['init_main_from_path'])
  File "/opt/conda/lib/python3.8/multiprocessing/spawn.py", line 287, in _fixup_main_from_path
    main_content = runpy.run_path(main_path,
  File "/opt/conda/lib/python3.8/runpy.py", line 265, in run_path
    return _run_module_code(code, init_globals, run_name,
  File "/opt/conda/lib/python3.8/runpy.py", line 97, in _run_module_code
    _run_code(code, mod_globals, init_globals,
  File "/opt/conda/lib/python3.8/runpy.py", line 87, in _run_code
    exec(code, run_globals)
  File "/opt/conda/bin/fmriprep", line 5, in <module>
: Command did not complete successfully. 1 failed:
[{'action': 'install',
  'message': 'target path already exists and not empty, refuse to clone into '
             'target path',
  'path': '/scratch1/03201/jbwexler/work_dir/fmriprep/ds000117_sub-11/fmriprep_wf/single_subject_11_wf/func_preproc_ses_mri_task_facerecognition_run_06_wf/unwarp_wf/resample/sourcedata/templateflow',
  'refds': None,
  'source_url': 'https://github.com/templateflow/templateflow.git',
  'status': 'error',
  'type': 'dataset'}]
    from fmriprep.cli.run import main
  File "/opt/conda/lib/python3.8/site-packages/fmriprep/cli/run.py", line 25, in <module>
    from .. import config
  File "/opt/conda/lib/python3.8/site-packages/fmriprep/config.py", line 116, in <module>
    from templateflow import __version__ as _tf_ver
  File "/opt/conda/lib/python3.8/site-packages/templateflow/__init__.py", line 19, in <module>
    from . import api
  File "/opt/conda/lib/python3.8/site-packages/templateflow/api.py", line 7, in <module>
    from .conf import TF_LAYOUT, TF_S3_ROOT, TF_USE_DATALAD, requires_layout
  File "/opt/conda/lib/python3.8/site-packages/templateflow/conf/__init__.py", line 53, in <module>
    install(path=str(TF_HOME), source=TF_GITHUB_SOURCE, recursive=True)
  File "/opt/conda/lib/python3.8/site-packages/datalad/interface/utils.py", line 484, in eval_func
    return return_func(generator_func)(*args, **kwargs)
  File "/opt/conda/lib/python3.8/site-packages/datalad/interface/utils.py", line 476, in return_func
    results = list(results)
  File "/opt/conda/lib/python3.8/site-packages/datalad/interface/utils.py", line 461, in generator_func
    raise IncompleteResultsError(
datalad.support.exceptions.IncompleteResultsError: Command did not complete successfully. 1 failed:
[{'action': 'install',
  'message': 'target path already exists and not empty, refuse to clone into '
             'target path',
  'path': '/scratch1/03201/jbwexler/work_dir/fmriprep/ds000117_sub-11/fmriprep_wf/single_subject_11_wf/func_preproc_ses_mri_task_facerecognition_run_06_wf/unwarp_wf/resample/sourcedata/templateflow',
  'refds': None,
  'source_url': 'https://github.com/templateflow/templateflow.git',
  'status': 'error',
  'type': 'dataset'}]
Traceback (most recent call last):
  File "/opt/conda/lib/python3.8/multiprocessing/forkserver.py", line 280, in main
    code = _serve_one(child_r, fds,
  File "/opt/conda/lib/python3.8/multiprocessing/forkserver.py", line 319, in _serve_one
    code = spawn._main(child_r, parent_sentinel)
  File "/opt/conda/lib/python3.8/multiprocessing/spawn.py", line 125, in _main
    prepare(preparation_data)
  File "/opt/conda/lib/python3.8/multiprocessing/spawn.py", line 236, in prepare
[INFO] Cloning dataset to Dataset(/scratch1/03201/jbwexler/work_dir/fmriprep/ds000117_sub-11/fmriprep_wf/single_subject_11_wf/func_preproc_ses_mri_task_facerecognition_run_07_wf/unwarp_wf/resample/sourcedata/templateflow) 
[INFO] Attempting to clone from https://github.com/templateflow/templateflow.git to /scratch1/03201/jbwexler/work_dir/fmriprep/ds000117_sub-11/fmriprep_wf/single_subject_11_wf/func_preproc_ses_mri_task_facerecognition_run_07_wf/unwarp_wf/resample/sourcedata/templateflow 
[INFO] Cloning dataset to Dataset(/scratch1/03201/jbwexler/work_dir/fmriprep/ds000117_sub-11/fmriprep_wf/single_subject_11_wf/func_preproc_ses_mri_task_facerecognition_run_07_wf/unwarp_wf/resample/sourcedata/templateflow) 
[INFO] Cloning dataset to Dataset(/scratch1/03201/jbwexler/work_dir/fmriprep/ds000117_sub-11/fmriprep_wf/single_subject_11_wf/func_preproc_ses_mri_task_facerecognition_run_07_wf/unwarp_wf/resample/sourcedata/templateflow) 
[INFO] Attempting to clone from https://github.com/templateflow/templateflow.git to /scratch1/03201/jbwexler/work_dir/fmriprep/ds000117_sub-11/fmriprep_wf/single_subject_11_wf/func_preproc_ses_mri_task_facerecognition_run_07_wf/unwarp_wf/resample/sourcedata/templateflow 
[INFO] Attempting to clone from https://github.com/templateflow/templateflow.git to /scratch1/03201/jbwexler/work_dir/fmriprep/ds000117_sub-11/fmriprep_wf/single_subject_11_wf/func_preproc_ses_mri_task_facerecognition_run_07_wf/unwarp_wf/resample/sourcedata/templateflow 
[INFO] Cloning dataset to Dataset(/scratch1/03201/jbwexler/work_dir/fmriprep/ds000117_sub-11/fmriprep_wf/single_subject_11_wf/func_preproc_ses_mri_task_facerecognition_run_07_wf/unwarp_wf/resample/sourcedata/templateflow) 
[INFO] Cloning dataset to Dataset(/scratch1/03201/jbwexler/work_dir/fmriprep/ds000117_sub-11/fmriprep_wf/single_subject_11_wf/func_preproc_ses_mri_task_facerecognition_run_07_wf/unwarp_wf/resample/sourcedata/templateflow) 
[INFO] Attempting to clone from https://github.com/templateflow/templateflow.git to /scratch1/03201/jbwexler/work_dir/fmriprep/ds000117_sub-11/fmriprep_wf/single_subject_11_wf/func_preproc_ses_mri_task_facerecognition_run_07_wf/unwarp_wf/resample/sourcedata/templateflow 
[INFO] Cloning dataset to Dataset(/scratch1/03201/jbwexler/work_dir/fmriprep/ds000117_sub-11/fmriprep_wf/single_subject_11_wf/func_preproc_ses_mri_task_facerecognition_run_07_wf/unwarp_wf/resample/sourcedata/templateflow) 
[INFO] Attempting to clone from https://github.com/templateflow/templateflow.git to /scratch1/03201/jbwexler/work_dir/fmriprep/ds000117_sub-11/fmriprep_wf/single_subject_11_wf/func_preproc_ses_mri_task_facerecognition_run_07_wf/unwarp_wf/resample/sourcedata/templateflow 
[INFO] Attempting to clone from https://github.com/templateflow/templateflow.git to /scratch1/03201/jbwexler/work_dir/fmriprep/ds000117_sub-11/fmriprep_wf/single_subject_11_wf/func_preproc_ses_mri_task_facerecognition_run_07_wf/unwarp_wf/resample/sourcedata/templateflow 
[INFO] Cloning dataset to Dataset(/scratch1/03201/jbwexler/work_dir/fmriprep/ds000117_sub-11/fmriprep_wf/single_subject_11_wf/func_preproc_ses_mri_task_facerecognition_run_07_wf/unwarp_wf/resample/sourcedata/templateflow) 
[INFO] Attempting to clone from https://github.com/templateflow/templateflow.git to /scratch1/03201/jbwexler/work_dir/fmriprep/ds000117_sub-11/fmriprep_wf/single_subject_11_wf/func_preproc_ses_mri_task_facerecognition_run_07_wf/unwarp_wf/resample/sourcedata/templateflow 
[INFO] Attempting to clone from https://github.com/templateflow/templateflow.git/.git to /scratch1/03201/jbwexler/work_dir/fmriprep/ds000117_sub-11/fmriprep_wf/single_subject_11_wf/func_preproc_ses_mri_task_facerecognition_run_07_wf/unwarp_wf/resample/sourcedata/templateflow 
[INFO] Attempting to clone from https://github.com/templateflow/templateflow.git/.git to /scratch1/03201/jbwexler/work_dir/fmriprep/ds000117_sub-11/fmriprep_wf/single_subject_11_wf/func_preproc_ses_mri_task_facerecognition_run_07_wf/unwarp_wf/resample/sourcedata/templateflow 
[INFO] Completed clone attempts for Dataset(/scratch1/03201/jbwexler/work_dir/fmriprep/ds000117_sub-11/fmriprep_wf/single_subject_11_wf/func_preproc_ses_mri_task_facerecognition_run_07_wf/unwarp_wf/resample/sourcedata/templateflow) 
Traceback (most recent call last):
  File "/opt/conda/lib/python3.8/multiprocessing/forkserver.py", line 280, in main
    code = _serve_one(child_r, fds,
  File "/opt/conda/lib/python3.8/multiprocessing/forkserver.py", line 319, in _serve_one
    code = spawn._main(child_r, parent_sentinel)
  File "/opt/conda/lib/python3.8/multiprocessing/spawn.py", line 125, in _main
    prepare(preparation_data)
  File "/opt/conda/lib/python3.8/multiprocessing/spawn.py", line 236, in prepare
    _fixup_main_from_path(data['init_main_from_path'])
  File "/opt/conda/lib/python3.8/multiprocessing/spawn.py", line 287, in _fixup_main_from_path
    main_content = runpy.run_path(main_path,
  File "/opt/conda/lib/python3.8/runpy.py", line 265, in run_path
    return _run_module_code(code, init_globals, run_name,
  File "/opt/conda/lib/python3.8/runpy.py", line 97, in _run_module_code
    _run_code(code, mod_globals, init_globals,
  File "/opt/conda/lib/python3.8/runpy.py", line 87, in _run_code
    exec(code, run_globals)
  File "/opt/conda/bin/fmriprep", line 5, in <module>
    from fmriprep.cli.run import main
  File "/opt/conda/lib/python3.8/site-packages/fmriprep/cli/run.py", line 25, in <module>
    from .. import config
  File "/opt/conda/lib/python3.8/site-packages/fmriprep/config.py", line 116, in <module>
    from templateflow import __version__ as _tf_ver
  File "/opt/conda/lib/python3.8/site-packages/templateflow/__init__.py", line 19, in <module>
    from . import api
  File "/opt/conda/lib/python3.8/site-packages/templateflow/api.py", line 7, in <module>
    from .conf import TF_LAYOUT, TF_S3_ROOT, TF_USE_DATALAD, requires_layout
  File "/opt/conda/lib/python3.8/site-packages/templateflow/conf/__init__.py", line 53, in <module>
    install(path=str(TF_HOME), source=TF_GITHUB_SOURCE, recursive=True)
  File "/opt/conda/lib/python3.8/site-packages/datalad/interface/utils.py", line 484, in eval_func
    return return_func(generator_func)(*args, **kwargs)
  File "/opt/conda/lib/python3.8/site-packages/datalad/interface/utils.py", line 476, in return_func
    results = list(results)
  File "/opt/conda/lib/python3.8/site-packages/datalad/interface/utils.py", line 396, in generator_func
    for r in _process_results(
  File "/opt/conda/lib/python3.8/site-packages/datalad/interface/utils.py", line 579, in _process_results
    for res in results:
  File "/opt/conda/lib/python3.8/site-packages/datalad/distribution/install.py", line 381, in __call__
    for r in destination_dataset.get(
  File "/opt/conda/lib/python3.8/site-packages/datalad/interface/utils.py", line 396, in generator_func
    for r in _process_results(
  File "/opt/conda/lib/python3.8/site-packages/datalad/interface/utils.py", line 579, in _process_results
    for res in results:
  File "/opt/conda/lib/python3.8/site-packages/datalad/distribution/get.py", line 849, in __call__
    refds = require_dataset(
  File "/opt/conda/lib/python3.8/site-packages/datalad/distribution/dataset.py", line 567, in require_dataset
    raise ValueError(u"No installed dataset found at "
ValueError: No installed dataset found at /scratch1/03201/jbwexler/work_dir/fmriprep/ds000117_sub-11/fmriprep_wf/single_subject_11_wf/func_preproc_ses_mri_task_facerecognition_run_07_wf/unwarp_wf/resample/sourcedata/templateflow.
[INFO] Attempting to clone from https://github.com/templateflow/templateflow.git/.git to /scratch1/03201/jbwexler/work_dir/fmriprep/ds000117_sub-11/fmriprep_wf/single_subject_11_wf/func_preproc_ses_mri_task_facerecognition_run_07_wf/unwarp_wf/resample/sourcedata/templateflow 
[INFO] Cloning dataset to Dataset(/scratch1/03201/jbwexler/work_dir/fmriprep/ds000117_sub-11/fmriprep_wf/single_subject_11_wf/func_preproc_ses_mri_task_facerecognition_run_08_wf/unwarp_wf/resample/sourcedata/templateflow) 
[INFO] Attempting to clone from https://github.com/templateflow/templateflow.git to /scratch1/03201/jbwexler/work_dir/fmriprep/ds000117_sub-11/fmriprep_wf/single_subject_11_wf/func_preproc_ses_mri_task_facerecognition_run_08_wf/unwarp_wf/resample/sourcedata/templateflow 
[INFO] Cloning dataset to Dataset(/scratch1/03201/jbwexler/work_dir/fmriprep/ds000117_sub-11/fmriprep_wf/single_subject_11_wf/func_preproc_ses_mri_task_facerecognition_run_08_wf/unwarp_wf/resample/sourcedata/templateflow) 
[INFO] Cloning dataset to Dataset(/scratch1/03201/jbwexler/work_dir/fmriprep/ds000117_sub-11/fmriprep_wf/single_subject_11_wf/func_preproc_ses_mri_task_facerecognition_run_08_wf/unwarp_wf/resample/sourcedata/templateflow) 
[INFO] Cloning dataset to Dataset(/scratch1/03201/jbwexler/work_dir/fmriprep/ds000117_sub-11/fmriprep_wf/single_subject_11_wf/func_preproc_ses_mri_task_facerecognition_run_08_wf/unwarp_wf/resample/sourcedata/templateflow) 
[INFO] Cloning dataset to Dataset(/scratch1/03201/jbwexler/work_dir/fmriprep/ds000117_sub-11/fmriprep_wf/single_subject_11_wf/func_preproc_ses_mri_task_facerecognition_run_08_wf/unwarp_wf/resample/sourcedata/templateflow) 
[INFO] Attempting to clone from https://github.com/templateflow/templateflow.git to /scratch1/03201/jbwexler/work_dir/fmriprep/ds000117_sub-11/fmriprep_wf/single_subject_11_wf/func_preproc_ses_mri_task_facerecognition_run_08_wf/unwarp_wf/resample/sourcedata/templateflow 
[INFO] Attempting to clone from https://github.com/templateflow/templateflow.git to /scratch1/03201/jbwexler/work_dir/fmriprep/ds000117_sub-11/fmriprep_wf/single_subject_11_wf/func_preproc_ses_mri_task_facerecognition_run_08_wf/unwarp_wf/resample/sourcedata/templateflow 
[INFO] Attempting to clone from https://github.com/templateflow/templateflow.git to /scratch1/03201/jbwexler/work_dir/fmriprep/ds000117_sub-11/fmriprep_wf/single_subject_11_wf/func_preproc_ses_mri_task_facerecognition_run_08_wf/unwarp_wf/resample/sourcedata/templateflow 
[INFO] Attempting to clone from https://github.com/templateflow/templateflow.git to /scratch1/03201/jbwexler/work_dir/fmriprep/ds000117_sub-11/fmriprep_wf/single_subject_11_wf/func_preproc_ses_mri_task_facerecognition_run_08_wf/unwarp_wf/resample/sourcedata/templateflow 
[INFO] Cloning dataset to Dataset(/scratch1/03201/jbwexler/work_dir/fmriprep/ds000117_sub-11/fmriprep_wf/single_subject_11_wf/func_preproc_ses_mri_task_facerecognition_run_08_wf/unwarp_wf/resample/sourcedata/templateflow) 
[INFO] Attempting to clone from https://github.com/templateflow/templateflow.git to /scratch1/03201/jbwexler/work_dir/fmriprep/ds000117_sub-11/fmriprep_wf/single_subject_11_wf/func_preproc_ses_mri_task_facerecognition_run_08_wf/unwarp_wf/resample/sourcedata/templateflow 
[INFO] Cloning dataset to Dataset(/scratch1/03201/jbwexler/work_dir/fmriprep/ds000117_sub-11/fmriprep_wf/single_subject_11_wf/func_preproc_ses_mri_task_facerecognition_run_08_wf/unwarp_wf/resample/sourcedata/templateflow) 
[INFO] Attempting to clone from https://github.com/templateflow/templateflow.git to /scratch1/03201/jbwexler/work_dir/fmriprep/ds000117_sub-11/fmriprep_wf/single_subject_11_wf/func_preproc_ses_mri_task_facerecognition_run_08_wf/unwarp_wf/resample/sourcedata/templateflow 
[INFO] Attempting to clone from https://github.com/templateflow/templateflow.git/.git to /scratch1/03201/jbwexler/work_dir/fmriprep/ds000117_sub-11/fmriprep_wf/single_subject_11_wf/func_preproc_ses_mri_task_facerecognition_run_08_wf/unwarp_wf/resample/sourcedata/templateflow 
[INFO] Attempting to clone from https://github.com/templateflow/templateflow.git/.git to /scratch1/03201/jbwexler/work_dir/fmriprep/ds000117_sub-11/fmriprep_wf/single_subject_11_wf/func_preproc_ses_mri_task_facerecognition_run_08_wf/unwarp_wf/resample/sourcedata/templateflow 
[INFO] Completed clone attempts for Dataset(/scratch1/03201/jbwexler/work_dir/fmriprep/ds000117_sub-11/fmriprep_wf/single_subject_11_wf/func_preproc_ses_mri_task_facerecognition_run_08_wf/unwarp_wf/resample/sourcedata/templateflow) 
Traceback (most recent call last):
  File "/opt/conda/lib/python3.8/multiprocessing/forkserver.py", line 280, in main
    code = _serve_one(child_r, fds,
  File "/opt/conda/lib/python3.8/multiprocessing/forkserver.py", line 319, in _serve_one
    code = spawn._main(child_r, parent_sentinel)
  File "/opt/conda/lib/python3.8/multiprocessing/spawn.py", line 125, in _main
    prepare(preparation_data)
  File "/opt/conda/lib/python3.8/multiprocessing/spawn.py", line 236, in prepare
    _fixup_main_from_path(data['init_main_from_path'])
  File "/opt/conda/lib/python3.8/multiprocessing/spawn.py", line 287, in _fixup_main_from_path
    main_content = runpy.run_path(main_path,
  File "/opt/conda/lib/python3.8/runpy.py", line 265, in run_path
    return _run_module_code(code, init_globals, run_name,
  File "/opt/conda/lib/python3.8/runpy.py", line 97, in _run_module_code
    _run_code(code, mod_globals, init_globals,
  File "/opt/conda/lib/python3.8/runpy.py", line 87, in _run_code
    exec(code, run_globals)
  File "/opt/conda/bin/fmriprep", line 5, in <module>
    from fmriprep.cli.run import main
  File "/opt/conda/lib/python3.8/site-packages/fmriprep/cli/run.py", line 25, in <module>
    from .. import config
  File "/opt/conda/lib/python3.8/site-packages/fmriprep/config.py", line 116, in <module>
    from templateflow import __version__ as _tf_ver
  File "/opt/conda/lib/python3.8/site-packages/templateflow/__init__.py", line 19, in <module>
    from . import api
  File "/opt/conda/lib/python3.8/site-packages/templateflow/api.py", line 7, in <module>
    from .conf import TF_LAYOUT, TF_S3_ROOT, TF_USE_DATALAD, requires_layout
  File "/opt/conda/lib/python3.8/site-packages/templateflow/conf/__init__.py", line 53, in <module>
    install(path=str(TF_HOME), source=TF_GITHUB_SOURCE, recursive=True)
  File "/opt/conda/lib/python3.8/site-packages/datalad/interface/utils.py", line 484, in eval_func
    return return_func(generator_func)(*args, **kwargs)
  File "/opt/conda/lib/python3.8/site-packages/datalad/interface/utils.py", line 476, in return_func
    results = list(results)
  File "/opt/conda/lib/python3.8/site-packages/datalad/interface/utils.py", line 396, in generator_func
    for r in _process_results(
  File "/opt/conda/lib/python3.8/site-packages/datalad/interface/utils.py", line 579, in _process_results
    for res in results:
  File "/opt/conda/lib/python3.8/site-packages/datalad/distribution/install.py", line 381, in __call__
    for r in destination_dataset.get(
  File "/opt/conda/lib/python3.8/site-packages/datalad/interface/utils.py", line 396, in generator_func
    for r in _process_results(
  File "/opt/conda/lib/python3.8/site-packages/datalad/interface/utils.py", line 579, in _process_results
    for res in results:
  File "/opt/conda/lib/python3.8/site-packages/datalad/distribution/get.py", line 849, in __call__
    refds = require_dataset(
  File "/opt/conda/lib/python3.8/site-packages/datalad/distribution/dataset.py", line 567, in require_dataset
    raise ValueError(u"No installed dataset found at "
ValueError: No installed dataset found at /scratch1/03201/jbwexler/work_dir/fmriprep/ds000117_sub-11/fmriprep_wf/single_subject_11_wf/func_preproc_ses_mri_task_facerecognition_run_08_wf/unwarp_wf/resample/sourcedata/templateflow.
[INFO] Cloning dataset to Dataset(/scratch1/03201/jbwexler/work_dir/fmriprep/ds000117_sub-11/fmriprep_wf/single_subject_11_wf/func_preproc_ses_mri_task_facerecognition_run_09_wf/unwarp_wf/resample/sourcedata/templateflow) 
[INFO] Cloning dataset to Dataset(/scratch1/03201/jbwexler/work_dir/fmriprep/ds000117_sub-11/fmriprep_wf/single_subject_11_wf/func_preproc_ses_mri_task_facerecognition_run_09_wf/unwarp_wf/resample/sourcedata/templateflow) 
[INFO] Cloning dataset to Dataset(/scratch1/03201/jbwexler/work_dir/fmriprep/ds000117_sub-11/fmriprep_wf/single_subject_11_wf/func_preproc_ses_mri_task_facerecognition_run_09_wf/unwarp_wf/resample/sourcedata/templateflow) 
[INFO] Attempting to clone from https://github.com/templateflow/templateflow.git to /scratch1/03201/jbwexler/work_dir/fmriprep/ds000117_sub-11/fmriprep_wf/single_subject_11_wf/func_preproc_ses_mri_task_facerecognition_run_09_wf/unwarp_wf/resample/sourcedata/templateflow 
[INFO] Attempting to clone from https://github.com/templateflow/templateflow.git to /scratch1/03201/jbwexler/work_dir/fmriprep/ds000117_sub-11/fmriprep_wf/single_subject_11_wf/func_preproc_ses_mri_task_facerecognition_run_09_wf/unwarp_wf/resample/sourcedata/templateflow 
[INFO] Attempting to clone from https://github.com/templateflow/templateflow.git to /scratch1/03201/jbwexler/work_dir/fmriprep/ds000117_sub-11/fmriprep_wf/single_subject_11_wf/func_preproc_ses_mri_task_facerecognition_run_09_wf/unwarp_wf/resample/sourcedata/templateflow 
[INFO] Cloning dataset to Dataset(/scratch1/03201/jbwexler/work_dir/fmriprep/ds000117_sub-11/fmriprep_wf/single_subject_11_wf/func_preproc_ses_mri_task_facerecognition_run_09_wf/unwarp_wf/resample/sourcedata/templateflow) 
[INFO] Attempting to clone from https://github.com/templateflow/templateflow.git to /scratch1/03201/jbwexler/work_dir/fmriprep/ds000117_sub-11/fmriprep_wf/single_subject_11_wf/func_preproc_ses_mri_task_facerecognition_run_09_wf/unwarp_wf/resample/sourcedata/templateflow 
[INFO] Cloning dataset to Dataset(/scratch1/03201/jbwexler/work_dir/fmriprep/ds000117_sub-11/fmriprep_wf/single_subject_11_wf/func_preproc_ses_mri_task_facerecognition_run_09_wf/unwarp_wf/resample/sourcedata/templateflow) 
[INFO] Cloning dataset to Dataset(/scratch1/03201/jbwexler/work_dir/fmriprep/ds000117_sub-11/fmriprep_wf/single_subject_11_wf/func_preproc_ses_mri_task_facerecognition_run_09_wf/unwarp_wf/resample/sourcedata/templateflow) 
[INFO] Attempting to clone from https://github.com/templateflow/templateflow.git to /scratch1/03201/jbwexler/work_dir/fmriprep/ds000117_sub-11/fmriprep_wf/single_subject_11_wf/func_preproc_ses_mri_task_facerecognition_run_09_wf/unwarp_wf/resample/sourcedata/templateflow 
[INFO] Attempting to clone from https://github.com/templateflow/templateflow.git to /scratch1/03201/jbwexler/work_dir/fmriprep/ds000117_sub-11/fmriprep_wf/single_subject_11_wf/func_preproc_ses_mri_task_facerecognition_run_09_wf/unwarp_wf/resample/sourcedata/templateflow 
Traceback (most recent call last):
  File "/opt/conda/lib/python3.8/multiprocessing/forkserver.py", line 280, in main
    code = _serve_one(child_r, fds,
  File "/opt/conda/lib/python3.8/multiprocessing/forkserver.py", line 319, in _serve_one
    code = spawn._main(child_r, parent_sentinel)
  File "/opt/conda/lib/python3.8/multiprocessing/spawn.py", line 125, in _main
    prepare(preparation_data)
  File "/opt/conda/lib/python3.8/multiprocessing/spawn.py", line 236, in prepare
    _fixup_main_from_path(data['init_main_from_path'])
  File "/opt/conda/lib/python3.8/multiprocessing/spawn.py", line 287, in _fixup_main_from_path
    main_content = runpy.run_path(main_path,
  File "/opt/conda/lib/python3.8/runpy.py", line 265, in run_path
    return _run_module_code(code, init_globals, run_name,
  File "/opt/conda/lib/python3.8/runpy.py", line 97, in _run_module_code
    _run_code(code, mod_globals, init_globals,
  File "/opt/conda/lib/python3.8/runpy.py", line 87, in _run_code
    exec(code, run_globals)
  File "/opt/conda/bin/fmriprep", line 5, in <module>
    from fmriprep.cli.run import main
  File "/opt/conda/lib/python3.8/site-packages/fmriprep/cli/run.py", line 25, in <module>
    from .. import config
  File "/opt/conda/lib/python3.8/site-packages/fmriprep/config.py", line 116, in <module>
    from templateflow import __version__ as _tf_ver
  File "/opt/conda/lib/python3.8/site-packages/templateflow/__init__.py", line 19, in <module>
    from . import api
  File "/opt/conda/lib/python3.8/site-packages/templateflow/api.py", line 7, in <module>
    from .conf import TF_LAYOUT, TF_S3_ROOT, TF_USE_DATALAD, requires_layout
  File "/opt/conda/lib/python3.8/site-packages/templateflow/conf/__init__.py", line 53, in <module>
    install(path=str(TF_HOME), source=TF_GITHUB_SOURCE, recursive=True)
  File "/opt/conda/lib/python3.8/site-packages/datalad/interface/utils.py", line 484, in eval_func
    return return_func(generator_func)(*args, **kwargs)
  File "/opt/conda/lib/python3.8/site-packages/datalad/interface/utils.py", line 476, in return_func
    results = list(results)
  File "/opt/conda/lib/python3.8/site-packages/datalad/interface/utils.py", line 396, in generator_func
    for r in _process_results(
  File "/opt/conda/lib/python3.8/site-packages/datalad/interface/utils.py", line 579, in _process_results
    for res in results:
  File "/opt/conda/lib/python3.8/site-packages/datalad/distribution/install.py", line 381, in __call__
    for r in destination_dataset.get(
  File "/opt/conda/lib/python3.8/site-packages/datalad/interface/utils.py", line 396, in generator_func
    for r in _process_results(
  File "/opt/conda/lib/python3.8/site-packages/datalad/interface/utils.py", line 579, in _process_results
    for res in results:
  File "/opt/conda/lib/python3.8/site-packages/datalad/distribution/get.py", line 849, in __call__
    refds = require_dataset(
  File "/opt/conda/lib/python3.8/site-packages/datalad/distribution/dataset.py", line 567, in require_dataset
    raise ValueError(u"No installed dataset found at "
ValueError: No installed dataset found at /scratch1/03201/jbwexler/work_dir/fmriprep/ds000117_sub-11/fmriprep_wf/single_subject_11_wf/func_preproc_ses_mri_task_facerecognition_run_09_wf/unwarp_wf/resample/sourcedata/templateflow.
Traceback (most recent call last):
  File "/opt/conda/lib/python3.8/site-packages/datalad/core/distributed/clone.py", line 589, in clone_dataset
    GitRepo.clone(
  File "/opt/conda/lib/python3.8/site-packages/datalad/support/gitrepo.py", line 994, in clone
    res = GitWitlessRunner().run(
  File "/opt/conda/lib/python3.8/site-packages/datalad/runner/runner.py", line 145, in run
[INFO] Attempting to clone from https://github.com/templateflow/templateflow.git/.git to /scratch1/03201/jbwexler/work_dir/fmriprep/ds000117_sub-11/fmriprep_wf/single_subject_11_wf/func_preproc_ses_mri_task_facerecognition_run_09_wf/unwarp_wf/resample/sourcedata/templateflow 
    raise CommandError(
datalad.runner.exception.CommandError: CommandError: 'git -c diff.ignoreSubmodules=none clone --progress https://github.com/templateflow/templateflow.git /scratch1/03201/jbwexler/work_dir/fmriprep/ds000117_sub-11/fmriprep_wf/single_subject_11_wf/func_preproc_ses_mri_task_facerecognition_run_09_wf/unwarp_wf/resample/sourcedata/templateflow' failed with exitcode 128 [err: 'Cloning into '/scratch1/03201/jbwexler/work_dir/fmriprep/ds000117_sub-11/fmriprep_wf/single_subject_11_wf/func_preproc_ses_mri_task_facerecognition_run_09_wf/unwarp_wf/resample/sourcedata/templateflow'...
fatal: cannot copy '/opt/conda/share/git-core/templates/description' to '/scratch1/03201/jbwexler/work_dir/fmriprep/ds000117_sub-11/fmriprep_wf/single_subject_11_wf/func_preproc_ses_mri_task_facerecognition_run_09_wf/unwarp_wf/resample/sourcedata/templateflow/.git/description': File exists']

During handling of the above exception, another exception occurred:

Traceback (most recent call last):
  File "/opt/conda/lib/python3.8/multiprocessing/forkserver.py", line 280, in main
Traceback (most recent call last):
      File "/opt/conda/lib/python3.8/site-packages/datalad/core/distributed/clone.py", line 589, in clone_dataset
code = _serve_one(child_r, fds,
  File "/opt/conda/lib/python3.8/multiprocessing/forkserver.py", line 319, in _serve_one
Traceback (most recent call last):
    code = spawn._main(child_r, parent_sentinel)
  File "/opt/conda/lib/python3.8/site-packages/datalad/core/distributed/clone.py", line 589, in clone_dataset
  File "/opt/conda/lib/python3.8/multiprocessing/spawn.py", line 125, in _main
    prepare(preparation_data)
  File "/opt/conda/lib/python3.8/multiprocessing/spawn.py", line 236, in prepare
    GitRepo.clone(Traceback (most recent call last):

  File "/opt/conda/lib/python3.8/site-packages/datalad/support/gitrepo.py", line 994, in clone
  File "/opt/conda/lib/python3.8/site-packages/datalad/core/distributed/clone.py", line 589, in clone_dataset
    _fixup_main_from_path(data['init_main_from_path'])
  File "/opt/conda/lib/python3.8/multiprocessing/spawn.py", line 287, in _fixup_main_from_path
    GitRepo.clone(
  File "/opt/conda/lib/python3.8/site-packages/datalad/support/gitrepo.py", line 994, in clone
    main_content = runpy.run_path(main_path,
  File "/opt/conda/lib/python3.8/runpy.py", line 265, in run_path
    res = GitWitlessRunner().run(    
    GitRepo.clone(  File "/opt/conda/lib/python3.8/site-packages/datalad/runner/runner.py", line 145, in run
return _run_module_code(code, init_globals, run_name,

  File "/opt/conda/lib/python3.8/runpy.py", line 97, in _run_module_code
  File "/opt/conda/lib/python3.8/site-packages/datalad/support/gitrepo.py", line 994, in clone
        raise CommandError(_run_code(code, mod_globals, init_globals,

      File "/opt/conda/lib/python3.8/runpy.py", line 87, in _run_code
datalad.runner.exceptionres = GitWitlessRunner().run(.
CommandError  File "/opt/conda/lib/python3.8/site-packages/datalad/runner/runner.py", line 145, in run
    exec(code, run_globals)
:   File "/opt/conda/bin/fmriprep", line 5, in <module>
    raise CommandError(
    CommandError: 'git -c diff.ignoreSubmodules=none clone --progress https://github.com/templateflow/templateflow.git /scratch1/03201/jbwexler/work_dir/fmriprep/ds000117_sub-11/fmriprep_wf/single_subject_11_wf/func_preproc_ses_mri_task_facerecognition_run_09_wf/unwarp_wf/resample/sourcedata/templateflow' failed with exitcode 128 [err: 'Cloning into '/scratch1/03201/jbwexler/work_dir/fmriprep/ds000117_sub-11/fmriprep_wf/single_subject_11_wf/func_preproc_ses_mri_task_facerecognition_run_09_wf/unwarp_wf/resample/sourcedata/templateflow'...
fatal: cannot copy '/opt/conda/share/git-core/templates/description' to '/scratch1/03201/jbwexler/work_dir/fmriprep/ds000117_sub-11/fmriprep_wf/single_subject_11_wf/func_preproc_ses_mri_task_facerecognition_run_09_wf/unwarp_wf/resample/sourcedata/templateflow/.git/description': File exists']from fmriprep.cli.run import maindatalad.runner.exception    

.res = GitWitlessRunner().run(CommandError
During handling of the above exception, another exception occurred:


  File "/opt/conda/lib/python3.8/site-packages/fmriprep/cli/run.py", line 25, in <module>
Traceback (most recent call last):
  File "/opt/conda/lib/python3.8/site-packages/datalad/runner/runner.py", line 145, in run
  File "/opt/conda/lib/python3.8/multiprocessing/forkserver.py", line 280, in main
:     from .. import config
      File "/opt/conda/lib/python3.8/site-packages/fmriprep/config.py", line 116, in <module>
CommandError: 'git -c diff.ignoreSubmodules=none clone --progress https://github.com/templateflow/templateflow.git /scratch1/03201/jbwexler/work_dir/fmriprep/ds000117_sub-11/fmriprep_wf/single_subject_11_wf/func_preproc_ses_mri_task_facerecognition_run_09_wf/unwarp_wf/resample/sourcedata/templateflow' failed with exitcode 128 [err: 'Cloning into '/scratch1/03201/jbwexler/work_dir/fmriprep/ds000117_sub-11/fmriprep_wf/single_subject_11_wf/func_preproc_ses_mri_task_facerecognition_run_09_wf/unwarp_wf/resample/sourcedata/templateflow'...
fatal: cannot copy '/opt/conda/share/git-core/templates/description' to '/scratch1/03201/jbwexler/work_dir/fmriprep/ds000117_sub-11/fmriprep_wf/single_subject_11_wf/func_preproc_ses_mri_task_facerecognition_run_09_wf/unwarp_wf/resample/sourcedata/templateflow/.git/description': File exists']raise CommandError(


During handling of the above exception, another exception occurred:

Traceback (most recent call last):
datalad.runner.exception.  File "/opt/conda/lib/python3.8/multiprocessing/forkserver.py", line 280, in main
    CommandErrorcode = _serve_one(child_r, fds,
  File "/opt/conda/lib/python3.8/multiprocessing/forkserver.py", line 319, in _serve_one
    : from templateflow import __version__ as _tf_ver
  File "/opt/conda/lib/python3.8/site-packages/templateflow/__init__.py", line 19, in <module>
    code = _serve_one(child_r, fds,CommandError: 'git -c diff.ignoreSubmodules=none clone --progress https://github.com/templateflow/templateflow.git /scratch1/03201/jbwexler/work_dir/fmriprep/ds000117_sub-11/fmriprep_wf/single_subject_11_wf/func_preproc_ses_mri_task_facerecognition_run_09_wf/unwarp_wf/resample/sourcedata/templateflow' failed with exitcode 128 [err: 'Cloning into '/scratch1/03201/jbwexler/work_dir/fmriprep/ds000117_sub-11/fmriprep_wf/single_subject_11_wf/func_preproc_ses_mri_task_facerecognition_run_09_wf/unwarp_wf/resample/sourcedata/templateflow'...
fatal: cannot copy '/opt/conda/share/git-core/templates/description' to '/scratch1/03201/jbwexler/work_dir/fmriprep/ds000117_sub-11/fmriprep_wf/single_subject_11_wf/func_preproc_ses_mri_task_facerecognition_run_09_wf/unwarp_wf/resample/sourcedata/templateflow/.git/description': File exists']

      File "/opt/conda/lib/python3.8/multiprocessing/forkserver.py", line 319, in _serve_one

During handling of the above exception, another exception occurred:

    code = spawn._main(child_r, parent_sentinel)Traceback (most recent call last):
from . import api

  File "/opt/conda/lib/python3.8/multiprocessing/forkserver.py", line 280, in main
  File "/opt/conda/lib/python3.8/multiprocessing/spawn.py", line 125, in _main
  File "/opt/conda/lib/python3.8/site-packages/templateflow/api.py", line 7, in <module>
    from .conf import TF_LAYOUT, TF_S3_ROOT, TF_USE_DATALAD, requires_layout
          File "/opt/conda/lib/python3.8/site-packages/templateflow/conf/__init__.py", line 53, in <module>
prepare(preparation_data)code = spawn._main(child_r, parent_sentinel)

  File "/opt/conda/lib/python3.8/multiprocessing/spawn.py", line 236, in prepare
  File "/opt/conda/lib/python3.8/multiprocessing/spawn.py", line 125, in _main
        code = _serve_one(child_r, fds,install(path=str(TF_HOME), source=TF_GITHUB_SOURCE, recursive=True)

      File "/opt/conda/lib/python3.8/multiprocessing/forkserver.py", line 319, in _serve_one
  File "/opt/conda/lib/python3.8/site-packages/datalad/interface/utils.py", line 484, in eval_func
_fixup_main_from_path(data['init_main_from_path'])
  File "/opt/conda/lib/python3.8/multiprocessing/spawn.py", line 287, in _fixup_main_from_path
    prepare(preparation_data)
  File "/opt/conda/lib/python3.8/multiprocessing/spawn.py", line 236, in prepare
    code = spawn._main(child_r, parent_sentinel)
    main_content = runpy.run_path(main_path,  File "/opt/conda/lib/python3.8/multiprocessing/spawn.py", line 125, in _main

  File "/opt/conda/lib/python3.8/runpy.py", line 265, in run_path
        _fixup_main_from_path(data['init_main_from_path'])return return_func(generator_func)(*args, **kwargs)

  File "/opt/conda/lib/python3.8/multiprocessing/spawn.py", line 287, in _fixup_main_from_path
  File "/opt/conda/lib/python3.8/site-packages/datalad/interface/utils.py", line 476, in return_func
    prepare(preparation_data)
  File "/opt/conda/lib/python3.8/multiprocessing/spawn.py", line 236, in prepare
    return _run_module_code(code, init_globals, run_name,
  File "/opt/conda/lib/python3.8/runpy.py", line 97, in _run_module_code
    main_content = runpy.run_path(main_path,
      File "/opt/conda/lib/python3.8/runpy.py", line 265, in run_path
_fixup_main_from_path(data['init_main_from_path'])
          File "/opt/conda/lib/python3.8/multiprocessing/spawn.py", line 287, in _fixup_main_from_path
results = list(results)_run_code(code, mod_globals, init_globals,

  File "/opt/conda/lib/python3.8/site-packages/datalad/interface/utils.py", line 396, in generator_func
  File "/opt/conda/lib/python3.8/runpy.py", line 87, in _run_code
        return _run_module_code(code, init_globals, run_name,exec(code, run_globals)
    
main_content = runpy.run_path(main_path,  File "/opt/conda/lib/python3.8/runpy.py", line 97, in _run_module_code
  File "/opt/conda/bin/fmriprep", line 5, in <module>

  File "/opt/conda/lib/python3.8/runpy.py", line 265, in run_path
    for r in _process_results(    
from fmriprep.cli.run import main    
  File "/opt/conda/lib/python3.8/site-packages/datalad/interface/utils.py", line 579, in _process_results
_run_code(code, mod_globals, init_globals,  File "/opt/conda/lib/python3.8/site-packages/fmriprep/cli/run.py", line 25, in <module>

  File "/opt/conda/lib/python3.8/runpy.py", line 87, in _run_code
    return _run_module_code(code, init_globals, run_name,
      File "/opt/conda/lib/python3.8/runpy.py", line 97, in _run_module_code
    from .. import configexec(code, run_globals)

  File "/opt/conda/lib/python3.8/site-packages/fmriprep/config.py", line 116, in <module>
  File "/opt/conda/bin/fmriprep", line 5, in <module>
    _run_code(code, mod_globals, init_globals,    
    from fmriprep.cli.run import mainfor res in results:  File "/opt/conda/lib/python3.8/runpy.py", line 87, in _run_code


  File "/opt/conda/lib/python3.8/site-packages/fmriprep/cli/run.py", line 25, in <module>
  File "/opt/conda/lib/python3.8/site-packages/datalad/distribution/install.py", line 365, in __call__
    from templateflow import __version__ as _tf_ver    
exec(code, run_globals)  File "/opt/conda/lib/python3.8/site-packages/templateflow/__init__.py", line 19, in <module>

    from .. import config  File "/opt/conda/bin/fmriprep", line 5, in <module>

  File "/opt/conda/lib/python3.8/site-packages/fmriprep/config.py", line 116, in <module>
    from . import api    
from fmriprep.cli.run import main    
  File "/opt/conda/lib/python3.8/site-packages/templateflow/api.py", line 7, in <module>
for r in res:
  File "/opt/conda/lib/python3.8/site-packages/fmriprep/cli/run.py", line 25, in <module>
  File "/opt/conda/lib/python3.8/site-packages/datalad/interface/utils.py", line 396, in generator_func
    from .conf import TF_LAYOUT, TF_S3_ROOT, TF_USE_DATALAD, requires_layout    
from templateflow import __version__ as _tf_ver      File "/opt/conda/lib/python3.8/site-packages/templateflow/conf/__init__.py", line 53, in <module>

from .. import config
  File "/opt/conda/lib/python3.8/site-packages/templateflow/__init__.py", line 19, in <module>
  File "/opt/conda/lib/python3.8/site-packages/fmriprep/config.py", line 116, in <module>
    for r in _process_results(
      File "/opt/conda/lib/python3.8/site-packages/datalad/interface/utils.py", line 579, in _process_results
install(path=str(TF_HOME), source=TF_GITHUB_SOURCE, recursive=True)    
from . import api
  File "/opt/conda/lib/python3.8/site-packages/datalad/interface/utils.py", line 484, in eval_func
  File "/opt/conda/lib/python3.8/site-packages/templateflow/api.py", line 7, in <module>
        from templateflow import __version__ as _tf_ver
from .conf import TF_LAYOUT, TF_S3_ROOT, TF_USE_DATALAD, requires_layout
  File "/opt/conda/lib/python3.8/site-packages/templateflow/__init__.py", line 19, in <module>
  File "/opt/conda/lib/python3.8/site-packages/templateflow/conf/__init__.py", line 53, in <module>
    from . import api    
    for res in results:
install(path=str(TF_HOME), source=TF_GITHUB_SOURCE, recursive=True)  File "/opt/conda/lib/python3.8/site-packages/templateflow/api.py", line 7, in <module>

  File "/opt/conda/lib/python3.8/site-packages/datalad/core/distributed/clone.py", line 320, in __call__
      File "/opt/conda/lib/python3.8/site-packages/datalad/interface/utils.py", line 484, in eval_func
return return_func(generator_func)(*args, **kwargs)
  File "/opt/conda/lib/python3.8/site-packages/datalad/interface/utils.py", line 476, in return_func
    from .conf import TF_LAYOUT, TF_S3_ROOT, TF_USE_DATALAD, requires_layout
  File "/opt/conda/lib/python3.8/site-packages/templateflow/conf/__init__.py", line 53, in <module>
        yield from clone_dataset(
install(path=str(TF_HOME), source=TF_GITHUB_SOURCE, recursive=True)
  File "/opt/conda/lib/python3.8/site-packages/datalad/core/distributed/clone.py", line 609, in clone_dataset
  File "/opt/conda/lib/python3.8/site-packages/datalad/interface/utils.py", line 484, in eval_func
        return return_func(generator_func)(*args, **kwargs)results = list(results)

  File "/opt/conda/lib/python3.8/site-packages/datalad/interface/utils.py", line 476, in return_func
  File "/opt/conda/lib/python3.8/site-packages/datalad/interface/utils.py", line 396, in generator_func
        rmtree(str(dest_path), children_only=dest_path_existed)
return return_func(generator_func)(*args, **kwargs)
  File "/opt/conda/lib/python3.8/site-packages/datalad/utils.py", line 471, in rmtree
  File "/opt/conda/lib/python3.8/site-packages/datalad/interface/utils.py", line 476, in return_func
    for r in _process_results(
      File "/opt/conda/lib/python3.8/site-packages/datalad/interface/utils.py", line 579, in _process_results
results = list(results)
  File "/opt/conda/lib/python3.8/site-packages/datalad/interface/utils.py", line 396, in generator_func
    rotree(path, ro=False, chmod_files=chmod_files)    
results = list(results)
  File "/opt/conda/lib/python3.8/site-packages/datalad/utils.py", line 435, in rotree
  File "/opt/conda/lib/python3.8/site-packages/datalad/interface/utils.py", line 396, in generator_func
    for r in _process_results(    
for res in results:
  File "/opt/conda/lib/python3.8/site-packages/datalad/interface/utils.py", line 579, in _process_results
  File "/opt/conda/lib/python3.8/site-packages/datalad/distribution/install.py", line 365, in __call__
        chmod(root)
for r in _process_results(
  File "/opt/conda/lib/python3.8/site-packages/datalad/utils.py", line 426, in <lambda>
  File "/opt/conda/lib/python3.8/site-packages/datalad/interface/utils.py", line 579, in _process_results
    for r in res:
  File "/opt/conda/lib/python3.8/site-packages/datalad/interface/utils.py", line 396, in generator_func
    for res in results:
  File "/opt/conda/lib/python3.8/site-packages/datalad/distribution/install.py", line 365, in __call__
    chmod = lambda f: os.chmod(f, os.stat(f).st_mode | stat.S_IWRITE | stat.S_IREAD)
FileNotFoundError        for res in results:for r in _process_results(    
: 
for r in res:[INFO] Attempting to clone from https://github.com/templateflow/templateflow.git/.git to /scratch1/03201/jbwexler/work_dir/fmriprep/ds000117_sub-11/fmriprep_wf/single_subject_11_wf/func_preproc_ses_mri_task_facerecognition_run_09_wf/unwarp_wf/resample/sourcedata/templateflow 

  File "/opt/conda/lib/python3.8/site-packages/datalad/distribution/install.py", line 365, in __call__
  File "/opt/conda/lib/python3.8/site-packages/datalad/interface/utils.py", line 579, in _process_results
[Errno 2] No such file or directory: '/scratch1/03201/jbwexler/work_dir/fmriprep/ds000117_sub-11/fmriprep_wf/single_subject_11_wf/func_preproc_ses_mri_task_facerecognition_run_09_wf/unwarp_wf/resample/sourcedata/templateflow/.git'
  File "/opt/conda/lib/python3.8/site-packages/datalad/interface/utils.py", line 396, in generator_func
    for r in res:
    for r in _process_results(  File "/opt/conda/lib/python3.8/site-packages/datalad/interface/utils.py", line 396, in generator_func

      File "/opt/conda/lib/python3.8/site-packages/datalad/interface/utils.py", line 579, in _process_results
for res in results:
  File "/opt/conda/lib/python3.8/site-packages/datalad/core/distributed/clone.py", line 320, in __call__
    for r in _process_results(
  File "/opt/conda/lib/python3.8/site-packages/datalad/interface/utils.py", line 579, in _process_results
    yield from clone_dataset(
      File "/opt/conda/lib/python3.8/site-packages/datalad/core/distributed/clone.py", line 609, in clone_dataset
for res in results:
  File "/opt/conda/lib/python3.8/site-packages/datalad/core/distributed/clone.py", line 320, in __call__
    for res in results:    
yield from clone_dataset(
  File "/opt/conda/lib/python3.8/site-packages/datalad/core/distributed/clone.py", line 320, in __call__
  File "/opt/conda/lib/python3.8/site-packages/datalad/core/distributed/clone.py", line 609, in clone_dataset
    rmtree(str(dest_path), children_only=dest_path_existed)
  File "/opt/conda/lib/python3.8/site-packages/datalad/utils.py", line 471, in rmtree
    yield from clone_dataset(
  File "/opt/conda/lib/python3.8/site-packages/datalad/core/distributed/clone.py", line 609, in clone_dataset
        rotree(path, ro=False, chmod_files=chmod_files)rmtree(str(dest_path), children_only=dest_path_existed)

  File "/opt/conda/lib/python3.8/site-packages/datalad/utils.py", line 435, in rotree
  File "/opt/conda/lib/python3.8/site-packages/datalad/utils.py", line 471, in rmtree
    rmtree(str(dest_path), children_only=dest_path_existed)
      File "/opt/conda/lib/python3.8/site-packages/datalad/utils.py", line 471, in rmtree
chmod(root)
      File "/opt/conda/lib/python3.8/site-packages/datalad/utils.py", line 426, in <lambda>
rotree(path, ro=False, chmod_files=chmod_files)
  File "/opt/conda/lib/python3.8/site-packages/datalad/utils.py", line 435, in rotree
        rotree(path, ro=False, chmod_files=chmod_files)
chmod = lambda f: os.chmod(f, os.stat(f).st_mode | stat.S_IWRITE | stat.S_IREAD)
  File "/opt/conda/lib/python3.8/site-packages/datalad/utils.py", line 435, in rotree
    FileNotFoundErrorchmod(root)
:   File "/opt/conda/lib/python3.8/site-packages/datalad/utils.py", line 426, in <lambda>
[Errno 2] No such file or directory: '/scratch1/03201/jbwexler/work_dir/fmriprep/ds000117_sub-11/fmriprep_wf/single_subject_11_wf/func_preproc_ses_mri_task_facerecognition_run_09_wf/unwarp_wf/resample/sourcedata/templateflow'
    chmod(root)
  File "/opt/conda/lib/python3.8/site-packages/datalad/utils.py", line 426, in <lambda>
    chmod = lambda f: os.chmod(f, os.stat(f).st_mode | stat.S_IWRITE | stat.S_IREAD)
FileNotFoundError: [Errno 2] No such file or directory: '/scratch1/03201/jbwexler/work_dir/fmriprep/ds000117_sub-11/fmriprep_wf/single_subject_11_wf/func_preproc_ses_mri_task_facerecognition_run_09_wf/unwarp_wf/resample/sourcedata/templateflow'
    chmod = lambda f: os.chmod(f, os.stat(f).st_mode | stat.S_IWRITE | stat.S_IREAD)
FileNotFoundError: [Errno 2] No such file or directory: '/scratch1/03201/jbwexler/work_dir/fmriprep/ds000117_sub-11/fmriprep_wf/single_subject_11_wf/func_preproc_ses_mri_task_facerecognition_run_09_wf/unwarp_wf/resample/sourcedata/templateflow'
